Workbook

Sheet Summary
A1: case_id | B1: 0.25.0 | C1: 0.25.1 | D1: 0.25.2 | E1: 0.25.3 | F1: 0.45.0 | G1: 0.45.1 | H1: 0.45.2 | I1: 0.45.3 | J1: 0.46.0 | K1: 0.46.1 | L1: 0.46.2 | M1: 0.46.3 | N1: 1.0.0 | O1: 1.0.1 | P1: 1.0.2 | Q1: 1.1.0 | R1: 1.1.1 | S1: 1.1.2 | T1: 1.2.0 | U1: 1.2.1 | V1: 1.2.2 | W1: 1.2.4 | X1: 2.0.0 | Y1: 2.2.0 | Z1: 2.3.0 | AA1: 2.4.0 | AB1: 2.5.0 | AC1: error_type_0.25.0 | AD1: error_message_0.25.0 | AE1: error_description_0.25.0 | AF1: error_type_0.25.1 | AG1: error_message_0.25.1 | AH1: error_description_0.25.1 | AI1: error_type_0.25.2 | AJ1: error_message_0.25.2 | AK1: error_description_0.25.2 | AL1: error_type_0.25.3 | AM1: error_message_0.25.3 | AN1: error_description_0.25.3 | AO1: error_type_0.45.0 | AP1: error_message_0.45.0 | AQ1: error_description_0.45.0 | AR1: error_type_0.45.1 | AS1: error_message_0.45.1 | AT1: error_description_0.45.1 | AU1: error_type_0.45.2 | AV1: error_message_0.45.2 | AW1: error_description_0.45.2 | AX1: error_type_0.45.3 | AY1: error_message_0.45.3 | AZ1: error_description_0.45.3 | BA1: error_type_0.46.0 | BB1: error_message_0.46.0 | BC1: error_description_0.46.0 | BD1: error_type_0.46.1 | BE1: error_message_0.46.1 | BF1: error_description_0.46.1 | BG1: error_type_0.46.2 | BH1: error_message_0.46.2 | BI1: error_description_0.46.2 | BJ1: error_type_0.46.3 | BK1: error_message_0.46.3 | BL1: error_description_0.46.3 | BM1: error_type_1.0.0 | BN1: error_message_1.0.0 | BO1: error_description_1.0.0 | BP1: error_type_1.0.1 | BQ1: error_message_1.0.1 | BR1: error_description_1.0.1 | BS1: error_type_1.0.2 | BT1: error_message_1.0.2 | BU1: error_description_1.0.2 | BV1: error_type_1.1.0 | BW1: error_message_1.1.0 | BX1: error_description_1.1.0 | BY1: error_type_1.1.1 | BZ1: error_message_1.1.1 | CA1: error_description_1.1.1 | CB1: error_type_1.1.2 | CC1: error_message_1.1.2 | CD1: error_description_1.1.2 | CE1: error_type_1.2.0 | CF1: error_message_1.2.0 | CG1: error_description_1.2.0 | CH1: error_type_1.2.1 | CI1: error_message_1.2.1 | CJ1: error_description_1.2.1 | CK1: error_type_1.2.2 | CL1: error_message_1.2.2 | CM1: error_description_1.2.2 | CN1: error_type_1.2.4 | CO1: error_message_1.2.4 | CP1: error_description_1.2.4 | CQ1: error_type_2.0.0 | CR1: error_message_2.0.0 | CS1: error_description_2.0.0 | CT1: error_type_2.2.0 | CU1: error_message_2.2.0 | CV1: error_description_2.2.0 | CW1: error_type_2.3.0 | CX1: error_message_2.3.0 | CY1: error_description_2.3.0 | CZ1: error_type_2.4.0 | DA1: error_message_2.4.0 | DB1: error_description_2.4.0 | DC1: error_type_2.5.0 | DD1: error_message_2.5.0 | DE1: error_description_2.5.0
A2: issue_009 | B2: NOT_TESTED | C2: NOT_TESTED | D2: NOT_TESTED | E2: NOT_TESTED | F2: Passed on test | G2: Passed on test | H2: Passed on test | I2: Passed on test | J2: Passed on test | K2: Passed on test | L2: Passed on test | M2: Passed on test | N2: NOT_TESTED | O2: NOT_TESTED | P2: NOT_TESTED | Q2: NOT_TESTED | R2: NOT_TESTED | S2: NOT_TESTED | T2: NOT_TESTED | U2: NOT_TESTED | V2: NOT_TESTED | W2: NOT_TESTED | X2: NOT_TESTED | Y2: NOT_TESTED | Z2: NOT_TESTED | AA2: NOT_TESTED | AB2: NOT_TESTED
A3: issue_018_se | B3: NOT_TESTED | C3: NOT_TESTED | D3: NOT_TESTED | E3: NOT_TESTED | F3: NOT_TESTED | G3: NOT_TESTED | H3: NOT_TESTED | I3: NOT_TESTED | J3: NOT_TESTED | K3: NOT_TESTED | L3: NOT_TESTED | M3: NOT_TESTED | N3: Failed on test | O3: Failed on test | P3: Failed on test | Q3: Failed on test | R3: Failed on test | S3: Failed on test | T3: Failed on test | U3: Failed on test | V3: Failed on test | W3: Failed on test | X3: Failed on test | Y3: Failed on test | Z3: Failed on test | AA3: Failed on test | AB3: Failed on test | BM3: AssertionError | BN3: RuntimeError: SIMULATOR_PROCESS_ERROR: exit=3221226356 (0xC0000374); AssertionError: | BO3: The LLM reversed each outcome string before reading the four bits, assuming the bug is Qiskit's little-endian bit order (the same idea as claude-sonnet-5-5). The real bug is which qubits the players measure, so the loss probabilities stay at 0.5 on six of the nine (x, y) inputs and test_exact_perfect_strategy_for_all_nine_inputs fails. The simulator check also hits the known Windows Aer native crash. Every model fails this case. | BP3: AssertionError | BQ3: RuntimeError: SIMULATOR_PROCESS_ERROR: exit=3221226356 (0xC0000374); AssertionError: | BR3: The LLM reversed each outcome string before reading the four bits, assuming the bug is Qiskit's little-endian bit order (the same idea as claude-sonnet-5-5). The real bug is which qubits the players measure, so the loss probabilities stay at 0.5 on six of the nine (x, y) inputs and test_exact_perfect_strategy_for_all_nine_inputs fails. The simulator check also hits the known Windows Aer native crash. Every model fails this case. | BS3: AssertionError | BT3: RuntimeError: SIMULATOR_PROCESS_ERROR: exit=3221226356 (0xC0000374); AssertionError: | BU3: The LLM reversed each outcome string before reading the four bits, assuming the bug is Qiskit's little-endian bit order (the same idea as claude-sonnet-5-5). The real bug is which qubits the players measure, so the loss probabilities stay at 0.5 on six of the nine (x, y) inputs and test_exact_perfect_strategy_for_all_nine_inputs fails. The simulator check also hits the known Windows Aer native crash. Every model fails this case. | BV3: AssertionError | BW3: RuntimeError: SIMULATOR_PROCESS_ERROR: exit=3221226356 (0xC0000374); AssertionError: | BX3: The LLM reversed each outcome string before reading the four bits, assuming the bug is Qiskit's little-endian bit order (the same idea as claude-sonnet-5-5). The real bug is which qubits the players measure, so the loss probabilities stay at 0.5 on six of the nine (x, y) inputs and test_exact_perfect_strategy_for_all_nine_inputs fails. The simulator check also hits the known Windows Aer native crash. Every model fails this case. | BY3: AssertionError | BZ3: RuntimeError: SIMULATOR_PROCESS_ERROR: exit=3221226356 (0xC0000374); AssertionError: | CA3: The LLM reversed each outcome string before reading the four bits, assuming the bug is Qiskit's little-endian bit order (the same idea as claude-sonnet-5-5). The real bug is which qubits the players measure, so the loss probabilities stay at 0.5 on six of the nine (x, y) inputs and test_exact_perfect_strategy_for_all_nine_inputs fails. The simulator check also hits the known Windows Aer native crash. Every model fails this case. | CB3: AssertionError | CC3: RuntimeError: SIMULATOR_PROCESS_ERROR: exit=3221226356 (0xC0000374); AssertionError: | CD3: The LLM reversed each outcome string before reading the four bits, assuming the bug is Qiskit's little-endian bit order (the same idea as claude-sonnet-5-5). The real bug is which qubits the players measure, so the loss probabilities stay at 0.5 on six of the nine (x, y) inputs and test_exact_perfect_strategy_for_all_nine_inputs fails. The simulator check also hits the known Windows Aer native crash. Every model fails this case. | CE3: AssertionError | CF3: RuntimeError: SIMULATOR_PROCESS_ERROR: exit=3221225477 (0xC0000005); AssertionError: | CG3: The LLM reversed each outcome string before reading the four bits, assuming the bug is Qiskit's little-endian bit order (the same idea as claude-sonnet-5-5). The real bug is which qubits the players measure, so the loss probabilities stay at 0.5 on six of the nine (x, y) inputs and test_exact_perfect_strategy_for_all_nine_inputs fails. The simulator check also hits the known Windows Aer native crash. Every model fails this case. | CH3: AssertionError | CI3: RuntimeError: SIMULATOR_PROCESS_ERROR: exit=3221226356 (0xC0000374); AssertionError: | CJ3: The LLM reversed each outcome string before reading the four bits, assuming the bug is Qiskit's little-endian bit order (the same idea as claude-sonnet-5-5). The real bug is which qubits the players measure, so the loss probabilities stay at 0.5 on six of the nine (x, y) inputs and test_exact_perfect_strategy_for_all_nine_inputs fails. The simulator check also hits the known Windows Aer native crash. Every model fails this case. | CK3: AssertionError | CL3: RuntimeError: SIMULATOR_PROCESS_ERROR: exit=3221226356 (0xC0000374); AssertionError: | CM3: The LLM reversed each outcome string before reading the four bits, assuming the bug is Qiskit's little-endian bit order (the same idea as claude-sonnet-5-5). The real bug is which qubits the players measure, so the loss probabilities stay at 0.5 on six of the nine (x, y) inputs and test_exact_perfect_strategy_for_all_nine_inputs fails. The simulator check also hits the known Windows Aer native crash. Every model fails this case. | CN3: AssertionError | CO3: RuntimeError: SIMULATOR_PROCESS_ERROR: exit=3221226356 (0xC0000374); AssertionError: | CP3: The LLM reversed each outcome string before reading the four bits, assuming the bug is Qiskit's little-endian bit order (the same idea as claude-sonnet-5-5). The real bug is which qubits the players measure, so the loss probabilities stay at 0.5 on six of the nine (x, y) inputs and test_exact_perfect_strategy_for_all_nine_inputs fails. The simulator check also hits the known Windows Aer native crash. Every model fails this case. | CQ3: AssertionError | CR3: RuntimeError: SIMULATOR_PROCESS_ERROR: exit=3221226356 (0xC0000374); AssertionError: | CS3: The LLM reversed each outcome string before reading the four bits, assuming the bug is Qiskit's little-endian bit order (the same idea as claude-sonnet-5-5). The real bug is which qubits the players measure, so the loss probabilities stay at 0.5 on six of the nine (x, y) inputs and test_exact_perfect_strategy_for_all_nine_inputs fails. The simulator check also hits the known Windows Aer native crash. Every model fails this case. | CT3: AssertionError | CU3: RuntimeError: SIMULATOR_PROCESS_ERROR: exit=3221226356 (0xC0000374); AssertionError: | CV3: The LLM reversed each outcome string before reading the four bits, assuming the bug is Qiskit's little-endian bit order (the same idea as claude-sonnet-5-5). The real bug is which qubits the players measure, so the loss probabilities stay at 0.5 on six of the nine (x, y) inputs and test_exact_perfect_strategy_for_all_nine_inputs fails. The simulator check also hits the known Windows Aer native crash. Every model fails this case. | CW3: AssertionError | CX3: RuntimeError: SIMULATOR_PROCESS_ERROR: exit=3221226356 (0xC0000374); AssertionError: | CY3: The LLM reversed each outcome string before reading the four bits, assuming the bug is Qiskit's little-endian bit order (the same idea as claude-sonnet-5-5). The real bug is which qubits the players measure, so the loss probabilities stay at 0.5 on six of the nine (x, y) inputs and test_exact_perfect_strategy_for_all_nine_inputs fails. The simulator check also hits the known Windows Aer native crash. Every model fails this case. | CZ3: AssertionError | DA3: RuntimeError: SIMULATOR_PROCESS_ERROR: exit=3221226356 (0xC0000374); AssertionError: | DB3: The LLM reversed each outcome string before reading the four bits, assuming the bug is Qiskit's little-endian bit order (the same idea as claude-sonnet-5-5). The real bug is which qubits the players measure, so the loss probabilities stay at 0.5 on six of the nine (x, y) inputs and test_exact_perfect_strategy_for_all_nine_inputs fails. The simulator check also hits the known Windows Aer native crash. Every model fails this case. | DC3: AssertionError | DD3: RuntimeError: SIMULATOR_PROCESS_ERROR: exit=3221226356 (0xC0000374); AssertionError: | DE3: The LLM reversed each outcome string before reading the four bits, assuming the bug is Qiskit's little-endian bit order (the same idea as claude-sonnet-5-5). The real bug is which qubits the players measure, so the loss probabilities stay at 0.5 on six of the nine (x, y) inputs and test_exact_perfect_strategy_for_all_nine_inputs fails. The simulator check also hits the known Windows Aer native crash. Every model fails this case.
A4: issue_021_se | B4: Passed on test | C4: Passed on test | D4: Passed on test | E4: Passed on test | F4: Passed on test | G4: Passed on test | H4: Passed on test | I4: Passed on test | J4: Passed on test | K4: Passed on test | L4: Passed on test | M4: Passed on test | N4: NOT_TESTED | O4: NOT_TESTED | P4: NOT_TESTED | Q4: NOT_TESTED | R4: NOT_TESTED | S4: NOT_TESTED | T4: NOT_TESTED | U4: NOT_TESTED | V4: NOT_TESTED | W4: NOT_TESTED | X4: NOT_TESTED | Y4: NOT_TESTED | Z4: NOT_TESTED | AA4: NOT_TESTED | AB4: NOT_TESTED
A5: issue_032_se | B5: Passed on test | C5: Passed on test | D5: Passed on test | E5: Passed on test | F5: NOT_TESTED | G5: NOT_TESTED | H5: NOT_TESTED | I5: NOT_TESTED | J5: NOT_TESTED | K5: NOT_TESTED | L5: NOT_TESTED | M5: NOT_TESTED | N5: NOT_TESTED | O5: NOT_TESTED | P5: NOT_TESTED | Q5: NOT_TESTED | R5: NOT_TESTED | S5: NOT_TESTED | T5: NOT_TESTED | U5: NOT_TESTED | V5: NOT_TESTED | W5: NOT_TESTED | X5: NOT_TESTED | Y5: NOT_TESTED | Z5: NOT_TESTED | AA5: NOT_TESTED | AB5: NOT_TESTED
A6: issue_034 | B6: NOT_TESTED | C6: NOT_TESTED | D6: NOT_TESTED | E6: NOT_TESTED | F6: NOT_TESTED | G6: NOT_TESTED | H6: NOT_TESTED | I6: NOT_TESTED | J6: NOT_TESTED | K6: NOT_TESTED | L6: NOT_TESTED | M6: NOT_TESTED | N6: Passed on test | O6: Passed on test | P6: Passed on test | Q6: Passed on test | R6: Passed on test | S6: Passed on test | T6: Passed on test | U6: Passed on test | V6: Passed on test | W6: Passed on test | X6: Passed on test | Y6: Passed on test | Z6: Passed on test | AA6: Passed on test | AB6: Passed on test
A7: issue_036 | B7: NOT_TESTED | C7: NOT_TESTED | D7: NOT_TESTED | E7: NOT_TESTED | F7: NOT_TESTED | G7: NOT_TESTED | H7: NOT_TESTED | I7: NOT_TESTED | J7: NOT_TESTED | K7: NOT_TESTED | L7: NOT_TESTED | M7: NOT_TESTED | N7: Passed on test | O7: Passed on test | P7: Passed on test | Q7: Passed on test | R7: Passed on test | S7: Passed on test | T7: Passed on test | U7: Passed on test | V7: Passed on test | W7: Passed on test | X7: Passed on test | Y7: Passed on test | Z7: Passed on test | AA7: Passed on test | AB7: Passed on test
A8: issue_058_se | B8: Passed on test | C8: Passed on test | D8: Passed on test | E8: Passed on test | F8: Passed on test | G8: Passed on test | H8: Passed on test | I8: Passed on test | J8: Passed on test | K8: Passed on test | L8: Passed on test | M8: Passed on test | N8: NOT_TESTED | O8: NOT_TESTED | P8: NOT_TESTED | Q8: NOT_TESTED | R8: NOT_TESTED | S8: NOT_TESTED | T8: NOT_TESTED | U8: NOT_TESTED | V8: NOT_TESTED | W8: NOT_TESTED | X8: NOT_TESTED | Y8: NOT_TESTED | Z8: NOT_TESTED | AA8: NOT_TESTED | AB8: NOT_TESTED
A9: issue_061 | B9: NOT_TESTED | C9: NOT_TESTED | D9: NOT_TESTED | E9: NOT_TESTED | F9: NOT_TESTED | G9: NOT_TESTED | H9: NOT_TESTED | I9: NOT_TESTED | J9: NOT_TESTED | K9: NOT_TESTED | L9: NOT_TESTED | M9: NOT_TESTED | N9: Passed on test | O9: Passed on test | P9: Passed on test | Q9: Passed on test | R9: Passed on test | S9: Passed on test | T9: Passed on test | U9: Passed on test | V9: Passed on test | W9: Passed on test | X9: Passed on test | Y9: Passed on test | Z9: Passed on test | AA9: Passed on test | AB9: Passed on test
A10: issue_072 | B10: Passed on test | C10: Passed on test | D10: Passed on test | E10: Passed on test | F10: NOT_TESTED | G10: NOT_TESTED | H10: NOT_TESTED | I10: NOT_TESTED | J10: NOT_TESTED | K10: NOT_TESTED | L10: NOT_TESTED | M10: NOT_TESTED | N10: NOT_TESTED | O10: NOT_TESTED | P10: NOT_TESTED | Q10: NOT_TESTED | R10: NOT_TESTED | S10: NOT_TESTED | T10: NOT_TESTED | U10: NOT_TESTED | V10: NOT_TESTED | W10: NOT_TESTED | X10: NOT_TESTED | Y10: NOT_TESTED | Z10: NOT_TESTED | AA10: NOT_TESTED | AB10: NOT_TESTED
A11: issue_096 | B11: Failed on test | C11: Failed on test | D11: Failed on test | E11: Failed on test | F11: Failed on test | G11: Failed on test | H11: Failed on test | I11: Failed on test | J11: Failed on test | K11: Failed on test | L11: Failed on test | M11: Failed on test | N11: Failed on test | O11: Failed on test | P11: Failed on test | Q11: Failed on test | R11: Failed on test | S11: Failed on test | T11: Failed on test | U11: Failed on test | V11: Failed on test | W11: Failed on test | X11: Failed on test | Y11: Failed on test | Z11: Failed on test | AA11: Failed on test | AB11: Failed on test | AC11: AssertionError | AD11: AssertionError: '' != '[default]\n'; AssertionError: False is not true : Missing ipython_kernel_config.py (even when the profile directory already exists) | AE11: The LLM creates ~/.qiskit and an empty settings.conf when they are missing, which stops the crash, but the test expects the file to contain a [default] section and the IPython profile's ipython_kernel_config.py to be created, which the fix does not do. Every model fails this case. | AF11: AssertionError | AG11: AssertionError: '' != '[default]\n'; AssertionError: False is not true : Missing ipython_kernel_config.py (even when the profile directory already exists) | AH11: The LLM creates ~/.qiskit and an empty settings.conf when they are missing, which stops the crash, but the test expects the file to contain a [default] section and the IPython profile's ipython_kernel_config.py to be created, which the fix does not do. Every model fails this case. | AI11: AssertionError | AJ11: AssertionError: '' != '[default]\n'; AssertionError: False is not true : Missing ipython_kernel_config.py (even when the profile directory already exists) | AK11: The LLM creates ~/.qiskit and an empty settings.conf when they are missing, which stops the crash, but the test expects the file to contain a [default] section and the IPython profile's ipython_kernel_config.py to be created, which the fix does not do. Every model fails this case. | AL11: AssertionError | AM11: AssertionError: '' != '[default]\n'; AssertionError: False is not true : Missing ipython_kernel_config.py (even when the profile directory already exists) | AN11: The LLM creates ~/.qiskit and an empty settings.conf when they are missing, which stops the crash, but the test expects the file to contain a [default] section and the IPython profile's ipython_kernel_config.py to be created, which the fix does not do. Every model fails this case. | AO11: AssertionError | AP11: AssertionError: '' != '[default]\n'; AssertionError: False is not true : Missing ipython_kernel_config.py (even when the profile directory already exists) | AQ11: The LLM creates ~/.qiskit and an empty settings.conf when they are missing, which stops the crash, but the test expects the file to contain a [default] section and the IPython profile's ipython_kernel_config.py to be created, which the fix does not do. Every model fails this case. | AR11: AssertionError | AS11: AssertionError: '' != '[default]\n'; AssertionError: False is not true : Missing ipython_kernel_config.py (even when the profile directory already exists) | AT11: The LLM creates ~/.qiskit and an empty settings.conf when they are missing, which stops the crash, but the test expects the file to contain a [default] section and the IPython profile's ipython_kernel_config.py to be created, which the fix does not do. Every model fails this case. | AU11: AssertionError | AV11: AssertionError: '' != '[default]\n'; AssertionError: False is not true : Missing ipython_kernel_config.py (even when the profile directory already exists) | AW11: The LLM creates ~/.qiskit and an empty settings.conf when they are missing, which stops the crash, but the test expects the file to contain a [default] section and the IPython profile's ipython_kernel_config.py to be created, which the fix does not do. Every model fails this case. | AX11: AssertionError | AY11: AssertionError: '' != '[default]\n'; AssertionError: False is not true : Missing ipython_kernel_config.py (even when the profile directory already exists) | AZ11: The LLM creates ~/.qiskit and an empty settings.conf when they are missing, which stops the crash, but the test expects the file to contain a [default] section and the IPython profile's ipython_kernel_config.py to be created, which the fix does not do. Every model fails this case. | BA11: AssertionError | BB11: AssertionError: '' != '[default]\n'; AssertionError: False is not true : Missing ipython_kernel_config.py (even when the profile directory already exists) | BC11: The LLM creates ~/.qiskit and an empty settings.conf when they are missing, which stops the crash, but the test expects the file to contain a [default] section and the IPython profile's ipython_kernel_config.py to be created, which the fix does not do. Every model fails this case. | BD11: AssertionError | BE11: AssertionError: '' != '[default]\n'; AssertionError: False is not true : Missing ipython_kernel_config.py (even when the profile directory already exists) | BF11: The LLM creates ~/.qiskit and an empty settings.conf when they are missing, which stops the crash, but the test expects the file to contain a [default] section and the IPython profile's ipython_kernel_config.py to be created, which the fix does not do. Every model fails this case. | BG11: AssertionError | BH11: AssertionError: '' != '[default]\n'; AssertionError: False is not true : Missing ipython_kernel_config.py (even when the profile directory already exists) | BI11: The LLM creates ~/.qiskit and an empty settings.conf when they are missing, which stops the crash, but the test expects the file to contain a [default] section and the IPython profile's ipython_kernel_config.py to be created, which the fix does not do. Every model fails this case. | BJ11: AssertionError | BK11: AssertionError: '' != '[default]\n'; AssertionError: False is not true : Missing ipython_kernel_config.py (even when the profile directory already exists) | BL11: The LLM creates ~/.qiskit and an empty settings.conf when they are missing, which stops the crash, but the test expects the file to contain a [default] section and the IPython profile's ipython_kernel_config.py to be created, which the fix does not do. Every model fails this case. | BM11: AssertionError | BN11: AssertionError: '' != '[default]\n'; AssertionError: False is not true : Missing ipython_kernel_config.py (even when the profile directory already exists) | BO11: The LLM creates ~/.qiskit and an empty settings.conf when they are missing, which stops the crash, but the test expects the file to contain a [default] section and the IPython profile's ipython_kernel_config.py to be created, which the fix does not do. Every model fails this case. | BP11: AssertionError | BQ11: AssertionError: '' != '[default]\n'; AssertionError: False is not true : Missing ipython_kernel_config.py (even when the profile directory already exists) | BR11: The LLM creates ~/.qiskit and an empty settings.conf when they are missing, which stops the crash, but the test expects the file to contain a [default] section and the IPython profile's ipython_kernel_config.py to be created, which the fix does not do. Every model fails this case. | BS11: AssertionError | BT11: AssertionError: '' != '[default]\n'; AssertionError: False is not true : Missing ipython_kernel_config.py (even when the profile directory already exists) | BU11: The LLM creates ~/.qiskit and an empty settings.conf when they are missing, which stops the crash, but the test expects the file to contain a [default] section and the IPython profile's ipython_kernel_config.py to be created, which the fix does not do. Every model fails this case. | BV11: AssertionError | BW11: AssertionError: '' != '[default]\n'; AssertionError: False is not true : Missing ipython_kernel_config.py (even when the profile directory already exists) | BX11: The LLM creates ~/.qiskit and an empty settings.conf when they are missing, which stops the crash, but the test expects the file to contain a [default] section and the IPython profile's ipython_kernel_config.py to be created, which the fix does not do. Every model fails this case. | BY11: AssertionError | BZ11: AssertionError: '' != '[default]\n'; AssertionError: False is not true : Missing ipython_kernel_config.py (even when the profile directory already exists) | CA11: The LLM creates ~/.qiskit and an empty settings.conf when they are missing, which stops the crash, but the test expects the file to contain a [default] section and the IPython profile's ipython_kernel_config.py to be created, which the fix does not do. Every model fails this case. | CB11: AssertionError | CC11: AssertionError: '' != '[default]\n'; AssertionError: False is not true : Missing ipython_kernel_config.py (even when the profile directory already exists) | CD11: The LLM creates ~/.qiskit and an empty settings.conf when they are missing, which stops the crash, but the test expects the file to contain a [default] section and the IPython profile's ipython_kernel_config.py to be created, which the fix does not do. Every model fails this case. | CE11: AssertionError | CF11: AssertionError: '' != '[default]\n'; AssertionError: False is not true : Missing ipython_kernel_config.py (even when the profile directory already exists) | CG11: The LLM creates ~/.qiskit and an empty settings.conf when they are missing, which stops the crash, but the test expects the file to contain a [default] section and the IPython profile's ipython_kernel_config.py to be created, which the fix does not do. Every model fails this case. | CH11: AssertionError | CI11: AssertionError: '' != '[default]\n'; AssertionError: False is not true : Missing ipython_kernel_config.py (even when the profile directory already exists) | CJ11: The LLM creates ~/.qiskit and an empty settings.conf when they are missing, which stops the crash, but the test expects the file to contain a [default] section and the IPython profile's ipython_kernel_config.py to be created, which the fix does not do. Every model fails this case. | CK11: AssertionError | CL11: AssertionError: '' != '[default]\n'; AssertionError: False is not true : Missing ipython_kernel_config.py (even when the profile directory already exists) | CM11: The LLM creates ~/.qiskit and an empty settings.conf when they are missing, which stops the crash, but the test expects the file to contain a [default] section and the IPython profile's ipython_kernel_config.py to be created, which the fix does not do. Every model fails this case. | CN11: AssertionError | CO11: AssertionError: '' != '[default]\n'; AssertionError: False is not true : Missing ipython_kernel_config.py (even when the profile directory already exists) | CP11: The LLM creates ~/.qiskit and an empty settings.conf when they are missing, which stops the crash, but the test expects the file to contain a [default] section and the IPython profile's ipython_kernel_config.py to be created, which the fix does not do. Every model fails this case. | CQ11: AssertionError | CR11: AssertionError: '' != '[default]\n'; AssertionError: False is not true : Missing ipython_kernel_config.py (even when the profile directory already exists) | CS11: The LLM creates ~/.qiskit and an empty settings.conf when they are missing, which stops the crash, but the test expects the file to contain a [default] section and the IPython profile's ipython_kernel_config.py to be created, which the fix does not do. Every model fails this case. | CT11: AssertionError | CU11: AssertionError: '' != '[default]\n'; AssertionError: False is not true : Missing ipython_kernel_config.py (even when the profile directory already exists) | CV11: The LLM creates ~/.qiskit and an empty settings.conf when they are missing, which stops the crash, but the test expects the file to contain a [default] section and the IPython profile's ipython_kernel_config.py to be created, which the fix does not do. Every model fails this case. | CW11: AssertionError | CX11: AssertionError: '' != '[default]\n'; AssertionError: False is not true : Missing ipython_kernel_config.py (even when the profile directory already exists) | CY11: The LLM creates ~/.qiskit and an empty settings.conf when they are missing, which stops the crash, but the test expects the file to contain a [default] section and the IPython profile's ipython_kernel_config.py to be created, which the fix does not do. Every model fails this case. | CZ11: AssertionError | DA11: AssertionError: '' != '[default]\n'; AssertionError: False is not true : Missing ipython_kernel_config.py (even when the profile directory already exists) | DB11: The LLM creates ~/.qiskit and an empty settings.conf when they are missing, which stops the crash, but the test expects the file to contain a [default] section and the IPython profile's ipython_kernel_config.py to be created, which the fix does not do. Every model fails this case. | DC11: AssertionError | DD11: AssertionError: '' != '[default]\n'; AssertionError: False is not true : Missing ipython_kernel_config.py (even when the profile directory already exists) | DE11: The LLM creates ~/.qiskit and an empty settings.conf when they are missing, which stops the crash, but the test expects the file to contain a [default] section and the IPython profile's ipython_kernel_config.py to be created, which the fix does not do. Every model fails this case.
A12: issue_155 | B12: Passed on test | C12: Passed on test | D12: Passed on test | E12: Passed on test | F12: Passed on test | G12: Passed on test | H12: Passed on test | I12: Passed on test | J12: Passed on test | K12: Passed on test | L12: Passed on test | M12: Passed on test | N12: NOT_TESTED | O12: NOT_TESTED | P12: NOT_TESTED | Q12: NOT_TESTED | R12: NOT_TESTED | S12: NOT_TESTED | T12: NOT_TESTED | U12: NOT_TESTED | V12: NOT_TESTED | W12: NOT_TESTED | X12: NOT_TESTED | Y12: NOT_TESTED | Z12: NOT_TESTED | AA12: NOT_TESTED | AB12: NOT_TESTED
A13: issue_157 | B13: Runtime error | C13: Runtime error | D13: Runtime error | E13: Runtime error | F13: Passed on test | G13: Passed on test | H13: Passed on test | I13: Passed on test | J13: Passed on test | K13: Passed on test | L13: Passed on test | M13: Passed on test | N13: NOT_TESTED | O13: NOT_TESTED | P13: NOT_TESTED | Q13: NOT_TESTED | R13: NOT_TESTED | S13: NOT_TESTED | T13: NOT_TESTED | U13: NOT_TESTED | V13: NOT_TESTED | W13: NOT_TESTED | X13: NOT_TESTED | Y13: NOT_TESTED | Z13: NOT_TESTED | AA13: NOT_TESTED | AB13: NOT_TESTED | AC13: ImportError | AD13: ImportError: cannot import name 'StatePreparation' from 'qiskit.circuit.library' (C:\qiskit_envs\q0250\lib\site-packages\qiskit\circuit\library\__init__.py) | AE13: Error on 0.25.x, passed on 0.45.x / 0.46.x: the LLM replaced initialize() (which contains a non-unitary reset and can't be controlled) with a StatePreparation gate, which is correct, but StatePreparation doesn't exist yet in Qiskit 0.25 (ImportError). Same code as claude-sonnet-5-5; every model loses 0.25.x on this case. | AF13: ImportError | AG13: ImportError: cannot import name 'StatePreparation' from 'qiskit.circuit.library' (C:\qiskit_envs\q0251\lib\site-packages\qiskit\circuit\library\__init__.py) | AH13: Error on 0.25.x, passed on 0.45.x / 0.46.x: the LLM replaced initialize() (which contains a non-unitary reset and can't be controlled) with a StatePreparation gate, which is correct, but StatePreparation doesn't exist yet in Qiskit 0.25 (ImportError). Same code as claude-sonnet-5-5; every model loses 0.25.x on this case. | AI13: ImportError | AJ13: ImportError: cannot import name 'StatePreparation' from 'qiskit.circuit.library' (C:\qiskit_envs\q0252\lib\site-packages\qiskit\circuit\library\__init__.py) | AK13: Error on 0.25.x, passed on 0.45.x / 0.46.x: the LLM replaced initialize() (which contains a non-unitary reset and can't be controlled) with a StatePreparation gate, which is correct, but StatePreparation doesn't exist yet in Qiskit 0.25 (ImportError). Same code as claude-sonnet-5-5; every model loses 0.25.x on this case. | AL13: ImportError | AM13: ImportError: cannot import name 'StatePreparation' from 'qiskit.circuit.library' (C:\qiskit_envs\q0253\lib\site-packages\qiskit\circuit\library\__init__.py) | AN13: Error on 0.25.x, passed on 0.45.x / 0.46.x: the LLM replaced initialize() (which contains a non-unitary reset and can't be controlled) with a StatePreparation gate, which is correct, but StatePreparation doesn't exist yet in Qiskit 0.25 (ImportError). Same code as claude-sonnet-5-5; every model loses 0.25.x on this case.
A14: issue_174 | B14: Passed on test | C14: Passed on test | D14: Passed on test | E14: Passed on test | F14: Passed on test | G14: Passed on test | H14: Passed on test | I14: Passed on test | J14: Passed on test | K14: Passed on test | L14: Passed on test | M14: Passed on test | N14: NOT_TESTED | O14: NOT_TESTED | P14: NOT_TESTED | Q14: NOT_TESTED | R14: NOT_TESTED | S14: NOT_TESTED | T14: NOT_TESTED | U14: NOT_TESTED | V14: NOT_TESTED | W14: NOT_TESTED | X14: NOT_TESTED | Y14: NOT_TESTED | Z14: NOT_TESTED | AA14: NOT_TESTED | AB14: NOT_TESTED
A15: issue_189 | B15: NOT_TESTED | C15: NOT_TESTED | D15: NOT_TESTED | E15: NOT_TESTED | F15: Passed on test | G15: Passed on test | H15: Passed on test | I15: Passed on test | J15: Passed on test | K15: Passed on test | L15: Passed on test | M15: Passed on test | N15: Passed on test | O15: Passed on test | P15: Passed on test | Q15: Passed on test | R15: Passed on test | S15: Passed on test | T15: Passed on test | U15: Passed on test | V15: Passed on test | W15: Passed on test | X15: Passed on test | Y15: Passed on test | Z15: Passed on test | AA15: Passed on test | AB15: Passed on test
A16: issue_225 | B16: NOT_TESTED | C16: NOT_TESTED | D16: NOT_TESTED | E16: NOT_TESTED | F16: Passed on test | G16: Passed on test | H16: Passed on test | I16: Passed on test | J16: Passed on test | K16: Passed on test | L16: Passed on test | M16: Passed on test | N16: NOT_TESTED | O16: NOT_TESTED | P16: NOT_TESTED | Q16: NOT_TESTED | R16: NOT_TESTED | S16: NOT_TESTED | T16: NOT_TESTED | U16: NOT_TESTED | V16: NOT_TESTED | W16: NOT_TESTED | X16: NOT_TESTED | Y16: NOT_TESTED | Z16: NOT_TESTED | AA16: NOT_TESTED | AB16: NOT_TESTED
A17: issue_233 | B17: Runtime error | C17: Runtime error | D17: Runtime error | E17: Runtime error | F17: Runtime error | G17: Runtime error | H17: Runtime error | I17: Runtime error | J17: Runtime error | K17: Runtime error | L17: Runtime error | M17: Runtime error | N17: Runtime error | O17: Runtime error | P17: Runtime error | Q17: Runtime error | R17: Runtime error | S17: Runtime error | T17: Runtime error | U17: Runtime error | V17: Runtime error | W17: Runtime error | X17: Runtime error | Y17: Runtime error | Z17: Runtime error | AA17: Runtime error | AB17: Runtime error | AC17: TypeError | AD17: TypeError: 'int' object is not callable | AE17: The LLM decided the bug was composing into a TwoLocal blueprint circuit and replaced the in-place compose with rot = rot.compose(var), but it kept the rot.num_parameters_settable() calls, and num_parameters_settable is an int property, so calling it raises TypeError on every version. claude-sonnet-5-5 and both luna models crashed the same way; claude-opus-5-5, gpt-6.1-sol and gpt-6-astra replaced both calls with num_parameters and passed. | AF17: TypeError | AG17: TypeError: 'int' object is not callable | AH17: The LLM decided the bug was composing into a TwoLocal blueprint circuit and replaced the in-place compose with rot = rot.compose(var), but it kept the rot.num_parameters_settable() calls, and num_parameters_settable is an int property, so calling it raises TypeError on every version. claude-sonnet-5-5 and both luna models crashed the same way; claude-opus-5-5, gpt-6.1-sol and gpt-6-astra replaced both calls with num_parameters and passed. | AI17: TypeError | AJ17: TypeError: 'int' object is not callable | AK17: The LLM decided the bug was composing into a TwoLocal blueprint circuit and replaced the in-place compose with rot = rot.compose(var), but it kept the rot.num_parameters_settable() calls, and num_parameters_settable is an int property, so calling it raises TypeError on every version. claude-sonnet-5-5 and both luna models crashed the same way; claude-opus-5-5, gpt-6.1-sol and gpt-6-astra replaced both calls with num_parameters and passed. | AL17: TypeError | AM17: TypeError: 'int' object is not callable | AN17: The LLM decided the bug was composing into a TwoLocal blueprint circuit and replaced the in-place compose with rot = rot.compose(var), but it kept the rot.num_parameters_settable() calls, and num_parameters_settable is an int property, so calling it raises TypeError on every version. claude-sonnet-5-5 and both luna models crashed the same way; claude-opus-5-5, gpt-6.1-sol and gpt-6-astra replaced both calls with num_parameters and passed. | AO17: TypeError | AP17: TypeError: 'int' object is not callable | AQ17: The LLM decided the bug was composing into a TwoLocal blueprint circuit and replaced the in-place compose with rot = rot.compose(var), but it kept the rot.num_parameters_settable() calls, and num_parameters_settable is an int property, so calling it raises TypeError on every version. claude-sonnet-5-5 and both luna models crashed the same way; claude-opus-5-5, gpt-6.1-sol and gpt-6-astra replaced both calls with num_parameters and passed. | AR17: TypeError | AS17: TypeError: 'int' object is not callable | AT17: The LLM decided the bug was composing into a TwoLocal blueprint circuit and replaced the in-place compose with rot = rot.compose(var), but it kept the rot.num_parameters_settable() calls, and num_parameters_settable is an int property, so calling it raises TypeError on every version. claude-sonnet-5-5 and both luna models crashed the same way; claude-opus-5-5, gpt-6.1-sol and gpt-6-astra replaced both calls with num_parameters and passed. | AU17: TypeError | AV17: TypeError: 'int' object is not callable | AW17: The LLM decided the bug was composing into a TwoLocal blueprint circuit and replaced the in-place compose with rot = rot.compose(var), but it kept the rot.num_parameters_settable() calls, and num_parameters_settable is an int property, so calling it raises TypeError on every version. claude-sonnet-5-5 and both luna models crashed the same way; claude-opus-5-5, gpt-6.1-sol and gpt-6-astra replaced both calls with num_parameters and passed. | AX17: TypeError | AY17: TypeError: 'int' object is not callable | AZ17: The LLM decided the bug was composing into a TwoLocal blueprint circuit and replaced the in-place compose with rot = rot.compose(var), but it kept the rot.num_parameters_settable() calls, and num_parameters_settable is an int property, so calling it raises TypeError on every version. claude-sonnet-5-5 and both luna models crashed the same way; claude-opus-5-5, gpt-6.1-sol and gpt-6-astra replaced both calls with num_parameters and passed. | BA17: TypeError | BB17: TypeError: 'int' object is not callable | BC17: The LLM decided the bug was composing into a TwoLocal blueprint circuit and replaced the in-place compose with rot = rot.compose(var), but it kept the rot.num_parameters_settable() calls, and num_parameters_settable is an int property, so calling it raises TypeError on every version. claude-sonnet-5-5 and both luna models crashed the same way; claude-opus-5-5, gpt-6.1-sol and gpt-6-astra replaced both calls with num_parameters and passed. | BD17: TypeError | BE17: TypeError: 'int' object is not callable | BF17: The LLM decided the bug was composing into a TwoLocal blueprint circuit and replaced the in-place compose with rot = rot.compose(var), but it kept the rot.num_parameters_settable() calls, and num_parameters_settable is an int property, so calling it raises TypeError on every version. claude-sonnet-5-5 and both luna models crashed the same way; claude-opus-5-5, gpt-6.1-sol and gpt-6-astra replaced both calls with num_parameters and passed. | BG17: TypeError | BH17: TypeError: 'int' object is not callable | BI17: The LLM decided the bug was composing into a TwoLocal blueprint circuit and replaced the in-place compose with rot = rot.compose(var), but it kept the rot.num_parameters_settable() calls, and num_parameters_settable is an int property, so calling it raises TypeError on every version. claude-sonnet-5-5 and both luna models crashed the same way; claude-opus-5-5, gpt-6.1-sol and gpt-6-astra replaced both calls with num_parameters and passed. | BJ17: TypeError | BK17: TypeError: 'int' object is not callable | BL17: The LLM decided the bug was composing into a TwoLocal blueprint circuit and replaced the in-place compose with rot = rot.compose(var), but it kept the rot.num_parameters_settable() calls, and num_parameters_settable is an int property, so calling it raises TypeError on every version. claude-sonnet-5-5 and both luna models crashed the same way; claude-opus-5-5, gpt-6.1-sol and gpt-6-astra replaced both calls with num_parameters and passed. | BM17: TypeError | BN17: TypeError: 'int' object is not callable | BO17: The LLM decided the bug was composing into a TwoLocal blueprint circuit and replaced the in-place compose with rot = rot.compose(var), but it kept the rot.num_parameters_settable() calls, and num_parameters_settable is an int property, so calling it raises TypeError on every version. claude-sonnet-5-5 and both luna models crashed the same way; claude-opus-5-5, gpt-6.1-sol and gpt-6-astra replaced both calls with num_parameters and passed. | BP17: TypeError | BQ17: TypeError: 'int' object is not callable | BR17: The LLM decided the bug was composing into a TwoLocal blueprint circuit and replaced the in-place compose with rot = rot.compose(var), but it kept the rot.num_parameters_settable() calls, and num_parameters_settable is an int property, so calling it raises TypeError on every version. claude-sonnet-5-5 and both luna models crashed the same way; claude-opus-5-5, gpt-6.1-sol and gpt-6-astra replaced both calls with num_parameters and passed. | BS17: TypeError | BT17: TypeError: 'int' object is not callable | BU17: The LLM decided the bug was composing into a TwoLocal blueprint circuit and replaced the in-place compose with rot = rot.compose(var), but it kept the rot.num_parameters_settable() calls, and num_parameters_settable is an int property, so calling it raises TypeError on every version. claude-sonnet-5-5 and both luna models crashed the same way; claude-opus-5-5, gpt-6.1-sol and gpt-6-astra replaced both calls with num_parameters and passed. | BV17: TypeError | BW17: TypeError: 'int' object is not callable | BX17: The LLM decided the bug was composing into a TwoLocal blueprint circuit and replaced the in-place compose with rot = rot.compose(var), but it kept the rot.num_parameters_settable() calls, and num_parameters_settable is an int property, so calling it raises TypeError on every version. claude-sonnet-5-5 and both luna models crashed the same way; claude-opus-5-5, gpt-6.1-sol and gpt-6-astra replaced both calls with num_parameters and passed. | BY17: TypeError | BZ17: TypeError: 'int' object is not callable | CA17: The LLM decided the bug was composing into a TwoLocal blueprint circuit and replaced the in-place compose with rot = rot.compose(var), but it kept the rot.num_parameters_settable() calls, and num_parameters_settable is an int property, so calling it raises TypeError on every version. claude-sonnet-5-5 and both luna models crashed the same way; claude-opus-5-5, gpt-6.1-sol and gpt-6-astra replaced both calls with num_parameters and passed. | CB17: TypeError | CC17: TypeError: 'int' object is not callable | CD17: The LLM decided the bug was composing into a TwoLocal blueprint circuit and replaced the in-place compose with rot = rot.compose(var), but it kept the rot.num_parameters_settable() calls, and num_parameters_settable is an int property, so calling it raises TypeError on every version. claude-sonnet-5-5 and both luna models crashed the same way; claude-opus-5-5, gpt-6.1-sol and gpt-6-astra replaced both calls with num_parameters and passed. | CE17: TypeError | CF17: TypeError: 'int' object is not callable | CG17: The LLM decided the bug was composing into a TwoLocal blueprint circuit and replaced the in-place compose with rot = rot.compose(var), but it kept the rot.num_parameters_settable() calls, and num_parameters_settable is an int property, so calling it raises TypeError on every version. claude-sonnet-5-5 and both luna models crashed the same way; claude-opus-5-5, gpt-6.1-sol and gpt-6-astra replaced both calls with num_parameters and passed. | CH17: TypeError | CI17: TypeError: 'int' object is not callable | CJ17: The LLM decided the bug was composing into a TwoLocal blueprint circuit and replaced the in-place compose with rot = rot.compose(var), but it kept the rot.num_parameters_settable() calls, and num_parameters_settable is an int property, so calling it raises TypeError on every version. claude-sonnet-5-5 and both luna models crashed the same way; claude-opus-5-5, gpt-6.1-sol and gpt-6-astra replaced both calls with num_parameters and passed. | CK17: TypeError | CL17: TypeError: 'int' object is not callable | CM17: The LLM decided the bug was composing into a TwoLocal blueprint circuit and replaced the in-place compose with rot = rot.compose(var), but it kept the rot.num_parameters_settable() calls, and num_parameters_settable is an int property, so calling it raises TypeError on every version. claude-sonnet-5-5 and both luna models crashed the same way; claude-opus-5-5, gpt-6.1-sol and gpt-6-astra replaced both calls with num_parameters and passed. | CN17: TypeError | CO17: TypeError: 'int' object is not callable | CP17: The LLM decided the bug was composing into a TwoLocal blueprint circuit and replaced the in-place compose with rot = rot.compose(var), but it kept the rot.num_parameters_settable() calls, and num_parameters_settable is an int property, so calling it raises TypeError on every version. claude-sonnet-5-5 and both luna models crashed the same way; claude-opus-5-5, gpt-6.1-sol and gpt-6-astra replaced both calls with num_parameters and passed. | CQ17: TypeError | CR17: TypeError: 'int' object is not callable | CS17: The LLM decided the bug was composing into a TwoLocal blueprint circuit and replaced the in-place compose with rot = rot.compose(var), but it kept the rot.num_parameters_settable() calls, and num_parameters_settable is an int property, so calling it raises TypeError on every version. claude-sonnet-5-5 and both luna models crashed the same way; claude-opus-5-5, gpt-6.1-sol and gpt-6-astra replaced both calls with num_parameters and passed. | CT17: TypeError | CU17: TypeError: 'int' object is not callable | CV17: The LLM decided the bug was composing into a TwoLocal blueprint circuit and replaced the in-place compose with rot = rot.compose(var), but it kept the rot.num_parameters_settable() calls, and num_parameters_settable is an int property, so calling it raises TypeError on every version. claude-sonnet-5-5 and both luna models crashed the same way; claude-opus-5-5, gpt-6.1-sol and gpt-6-astra replaced both calls with num_parameters and passed. | CW17: TypeError | CX17: TypeError: 'int' object is not callable | CY17: The LLM decided the bug was composing into a TwoLocal blueprint circuit and replaced the in-place compose with rot = rot.compose(var), but it kept the rot.num_parameters_settable() calls, and num_parameters_settable is an int property, so calling it raises TypeError on every version. claude-sonnet-5-5 and both luna models crashed the same way; claude-opus-5-5, gpt-6.1-sol and gpt-6-astra replaced both calls with num_parameters and passed. | CZ17: TypeError | DA17: TypeError: 'int' object is not callable | DB17: The LLM decided the bug was composing into a TwoLocal blueprint circuit and replaced the in-place compose with rot = rot.compose(var), but it kept the rot.num_parameters_settable() calls, and num_parameters_settable is an int property, so calling it raises TypeError on every version. claude-sonnet-5-5 and both luna models crashed the same way; claude-opus-5-5, gpt-6.1-sol and gpt-6-astra replaced both calls with num_parameters and passed. | DC17: TypeError | DD17: TypeError: 'int' object is not callable | DE17: The LLM decided the bug was composing into a TwoLocal blueprint circuit and replaced the in-place compose with rot = rot.compose(var), but it kept the rot.num_parameters_settable() calls, and num_parameters_settable is an int property, so calling it raises TypeError on every version. claude-sonnet-5-5 and both luna models crashed the same way; claude-opus-5-5, gpt-6.1-sol and gpt-6-astra replaced both calls with num_parameters and passed.
A18: issue_261 | B18: Passed on test | C18: Passed on test | D18: Passed on test | E18: Passed on test | F18: Passed on test | G18: Passed on test | H18: Passed on test | I18: Passed on test | J18: Passed on test | K18: Passed on test | L18: Passed on test | M18: Passed on test | N18: NOT_TESTED | O18: NOT_TESTED | P18: NOT_TESTED | Q18: NOT_TESTED | R18: NOT_TESTED | S18: NOT_TESTED | T18: NOT_TESTED | U18: NOT_TESTED | V18: NOT_TESTED | W18: NOT_TESTED | X18: NOT_TESTED | Y18: NOT_TESTED | Z18: NOT_TESTED | AA18: NOT_TESTED | AB18: NOT_TESTED
A19: issue_280 | B19: Passed on test | C19: Passed on test | D19: Passed on test | E19: Passed on test | F19: Passed on test | G19: Passed on test | H19: Passed on test | I19: Passed on test | J19: Passed on test | K19: Passed on test | L19: Passed on test | M19: Passed on test | N19: NOT_TESTED | O19: NOT_TESTED | P19: NOT_TESTED | Q19: NOT_TESTED | R19: NOT_TESTED | S19: NOT_TESTED | T19: NOT_TESTED | U19: NOT_TESTED | V19: NOT_TESTED | W19: NOT_TESTED | X19: NOT_TESTED | Y19: NOT_TESTED | Z19: NOT_TESTED | AA19: NOT_TESTED | AB19: NOT_TESTED
A20: issue_295 | B20: NOT_TESTED | C20: NOT_TESTED | D20: NOT_TESTED | E20: NOT_TESTED | F20: Runtime error | G20: Runtime error | H20: Runtime error | I20: Runtime error | J20: Runtime error | K20: Runtime error | L20: Runtime error | M20: Runtime error | N20: NOT_TESTED | O20: NOT_TESTED | P20: NOT_TESTED | Q20: NOT_TESTED | R20: NOT_TESTED | S20: NOT_TESTED | T20: NOT_TESTED | U20: NOT_TESTED | V20: NOT_TESTED | W20: NOT_TESTED | X20: NOT_TESTED | Y20: NOT_TESTED | Z20: NOT_TESTED | AA20: NOT_TESTED | AB20: NOT_TESTED | AO20: TypeError | AP20: TypeError: unsupported operand type(s) for +=: 'QuantumCircuit' and 'QuantumCircuit' | AQ20: The LLM answered NO BUG, saying circuit += oracle validly appends the oracle, and returned the code unchanged, but QuantumCircuit no longer supports += in these versions (TypeError: unsupported operand type(s) for +=). claude-sonnet-5-5 also kept +=; every other model replaced it with compose() and passed. | AR20: TypeError | AS20: TypeError: unsupported operand type(s) for +=: 'QuantumCircuit' and 'QuantumCircuit' | AT20: The LLM answered NO BUG, saying circuit += oracle validly appends the oracle, and returned the code unchanged, but QuantumCircuit no longer supports += in these versions (TypeError: unsupported operand type(s) for +=). claude-sonnet-5-5 also kept +=; every other model replaced it with compose() and passed. | AU20: TypeError | AV20: TypeError: unsupported operand type(s) for +=: 'QuantumCircuit' and 'QuantumCircuit' | AW20: The LLM answered NO BUG, saying circuit += oracle validly appends the oracle, and returned the code unchanged, but QuantumCircuit no longer supports += in these versions (TypeError: unsupported operand type(s) for +=). claude-sonnet-5-5 also kept +=; every other model replaced it with compose() and passed. | AX20: TypeError | AY20: TypeError: unsupported operand type(s) for +=: 'QuantumCircuit' and 'QuantumCircuit' | AZ20: The LLM answered NO BUG, saying circuit += oracle validly appends the oracle, and returned the code unchanged, but QuantumCircuit no longer supports += in these versions (TypeError: unsupported operand type(s) for +=). claude-sonnet-5-5 also kept +=; every other model replaced it with compose() and passed. | BA20: TypeError | BB20: TypeError: unsupported operand type(s) for +=: 'QuantumCircuit' and 'QuantumCircuit' | BC20: The LLM answered NO BUG, saying circuit += oracle validly appends the oracle, and returned the code unchanged, but QuantumCircuit no longer supports += in these versions (TypeError: unsupported operand type(s) for +=). claude-sonnet-5-5 also kept +=; every other model replaced it with compose() and passed. | BD20: TypeError | BE20: TypeError: unsupported operand type(s) for +=: 'QuantumCircuit' and 'QuantumCircuit' | BF20: The LLM answered NO BUG, saying circuit += oracle validly appends the oracle, and returned the code unchanged, but QuantumCircuit no longer supports += in these versions (TypeError: unsupported operand type(s) for +=). claude-sonnet-5-5 also kept +=; every other model replaced it with compose() and passed. | BG20: TypeError | BH20: TypeError: unsupported operand type(s) for +=: 'QuantumCircuit' and 'QuantumCircuit' | BI20: The LLM answered NO BUG, saying circuit += oracle validly appends the oracle, and returned the code unchanged, but QuantumCircuit no longer supports += in these versions (TypeError: unsupported operand type(s) for +=). claude-sonnet-5-5 also kept +=; every other model replaced it with compose() and passed. | BJ20: TypeError | BK20: TypeError: unsupported operand type(s) for +=: 'QuantumCircuit' and 'QuantumCircuit' | BL20: The LLM answered NO BUG, saying circuit += oracle validly appends the oracle, and returned the code unchanged, but QuantumCircuit no longer supports += in these versions (TypeError: unsupported operand type(s) for +=). claude-sonnet-5-5 also kept +=; every other model replaced it with compose() and passed.
