Workbook

Sheet Metrics
A1: LLM bug-repair results: all seven models, pass / fail / runtime error (72 cases, 1000 case × version pairs)
A2: Counts are formulas over each model's status sheet. A case is Passed on test only when every tested version passed, Runtime error when any version crashed or timed out, and Failed on test otherwise.
A4: 1. Case × version pairs
A5: Result | B5: gpt-5.6-luna | C5: % | D5: gpt-6-luna | E5: % | F5: gpt-6-astra | G5: % | H5: gpt-6.1-sol | I5: % | J5: claude-opus-5-5 | K5: % | L5: claude-sonnet-5-5 | M5: % | N5: claude-haiku-5-5 | O5: %
A6: Passed on test | B6: =COUNTIF('gpt-5.6-luna'!$B$2:$AB$73,"Passed on test") | C6: =IF(B$9=0,0,B6/B$9) | D6: =COUNTIF('gpt-6-luna'!$B$2:$AB$73,"Passed on test") | E6: =IF(D$9=0,0,D6/D$9) | F6: =COUNTIF('gpt-6-astra'!$B$2:$AB$73,"Passed on test") | G6: =IF(F$9=0,0,F6/F$9) | H6: =COUNTIF('gpt-6.1-sol'!$B$2:$AB$73,"Passed on test") | I6: =IF(H$9=0,0,H6/H$9) | J6: =COUNTIF('claude-opus-5-5'!$B$2:$AB$73,"PASS") | K6: =IF(J$9=0,0,J6/J$9) | L6: =COUNTIF('claude-sonnet-5-5'!$B$2:$AB$73,"PASS") | M6: =IF(L$9=0,0,L6/L$9) | N6: =COUNTIF('claude-haiku-5-5'!$B$2:$AB$73,"PASS") | O6: =IF(N$9=0,0,N6/N$9)
A7: Failed on test | B7: =COUNTIF('gpt-5.6-luna'!$B$2:$AB$73,"Failed on test") | C7: =IF(B$9=0,0,B7/B$9) | D7: =COUNTIF('gpt-6-luna'!$B$2:$AB$73,"Failed on test") | E7: =IF(D$9=0,0,D7/D$9) | F7: =COUNTIF('gpt-6-astra'!$B$2:$AB$73,"Failed on test") | G7: =IF(F$9=0,0,F7/F$9) | H7: =COUNTIF('gpt-6.1-sol'!$B$2:$AB$73,"Failed on test") | I7: =IF(H$9=0,0,H7/H$9) | J7: =COUNTIF('claude-opus-5-5'!$B$2:$AB$73,"FAIL") | K7: =IF(J$9=0,0,J7/J$9) | L7: =COUNTIF('claude-sonnet-5-5'!$B$2:$AB$73,"FAIL") | M7: =IF(L$9=0,0,L7/L$9) | N7: =COUNTIF('claude-haiku-5-5'!$B$2:$AB$73,"FAIL") | O7: =IF(N$9=0,0,N7/N$9)
A8: Runtime error | B8: =COUNTIF('gpt-5.6-luna'!$B$2:$AB$73,"Runtime error") | C8: =IF(B$9=0,0,B8/B$9) | D8: =COUNTIF('gpt-6-luna'!$B$2:$AB$73,"Runtime error") | E8: =IF(D$9=0,0,D8/D$9) | F8: =COUNTIF('gpt-6-astra'!$B$2:$AB$73,"Runtime error") | G8: =IF(F$9=0,0,F8/F$9) | H8: =COUNTIF('gpt-6.1-sol'!$B$2:$AB$73,"Runtime error") | I8: =IF(H$9=0,0,H8/H$9) | J8: =COUNTIF('claude-opus-5-5'!$B$2:$AB$73,"ERROR") | K8: =IF(J$9=0,0,J8/J$9) | L8: =COUNTIF('claude-sonnet-5-5'!$B$2:$AB$73,"ERROR") | M8: =IF(L$9=0,0,L8/L$9) | N8: =COUNTIF('claude-haiku-5-5'!$B$2:$AB$73,"ERROR") | O8: =IF(N$9=0,0,N8/N$9)
A9: Total | B9: =SUM(B6:B8) | C9: =SUM(C6:C8) | D9: =SUM(D6:D8) | E9: =SUM(E6:E8) | F9: =SUM(F6:F8) | G9: =SUM(G6:G8) | H9: =SUM(H6:H8) | I9: =SUM(I6:I8) | ... O9: =SUM(O6:O8)
A10: Not tested means that Qiskit version is not assigned to the case. It is not a pass, fail, or error.
A12: 2. Cases by outcome
A13: Result | B13: gpt-5.6-luna | C13: % | D13: gpt-6-luna | E13: % | F13: gpt-6-astra | G13: % | H13: gpt-6.1-sol | I13: % | J13: claude-opus-5-5 | K13: % | L13: claude-sonnet-5-5 | M13: % | N13: claude-haiku-5-5 | O13: %
A14: Passed on test | B14: =COUNTIF(Overview!$E$2:$E$73,"Passed on test") | C14: =IF(B$17=0,0,B14/B$17) | D14: =COUNTIF(Overview!$I$2:$I$73,"Passed on test") | E14: =IF(D$17=0,0,D14/D$17) | F14: =COUNTIF(Overview!$M$2:$M$73,"Passed on test") | G14: =IF(F$17=0,0,F14/F$17) | H14: =COUNTIF(Overview!$Q$2:$Q$73,"Passed on test") | I14: =IF(H$17=0,0,H14/H$17) | J14: =COUNTIF(Overview!$U$2:$U$73,"Passed on test") | K14: =IF(J$17=0,0,J14/J$17) | L14: =COUNTIF(Overview!$Y$2:$Y$73,"Passed on test") | M14: =IF(L$17=0,0,L14/L$17) | N14: =COUNTIF(Overview!$AC$2:$AC$73,"Passed on test") | O14: =IF(N$17=0,0,N14/N$17)
A15: Failed on test | B15: =COUNTIF(Overview!$E$2:$E$73,"Failed on test") | C15: =IF(B$17=0,0,B15/B$17) | D15: =COUNTIF(Overview!$I$2:$I$73,"Failed on test") | E15: =IF(D$17=0,0,D15/D$17) | F15: =COUNTIF(Overview!$M$2:$M$73,"Failed on test") | G15: =IF(F$17=0,0,F15/F$17) | H15: =COUNTIF(Overview!$Q$2:$Q$73,"Failed on test") | I15: =IF(H$17=0,0,H15/H$17) | J15: =COUNTIF(Overview!$U$2:$U$73,"Failed on test") | K15: =IF(J$17=0,0,J15/J$17) | L15: =COUNTIF(Overview!$Y$2:$Y$73,"Failed on test") | M15: =IF(L$17=0,0,L15/L$17) | N15: =COUNTIF(Overview!$AC$2:$AC$73,"Failed on test") | O15: =IF(N$17=0,0,N15/N$17)
A16: Runtime error | B16: =COUNTIF(Overview!$E$2:$E$73,"Runtime error") | C16: =IF(B$17=0,0,B16/B$17) | D16: =COUNTIF(Overview!$I$2:$I$73,"Runtime error") | E16: =IF(D$17=0,0,D16/D$17) | F16: =COUNTIF(Overview!$M$2:$M$73,"Runtime error") | G16: =IF(F$17=0,0,F16/F$17) | H16: =COUNTIF(Overview!$Q$2:$Q$73,"Runtime error") | I16: =IF(H$17=0,0,H16/H$17) | J16: =COUNTIF(Overview!$U$2:$U$73,"Runtime error") | K16: =IF(J$17=0,0,J16/J$17) | L16: =COUNTIF(Overview!$Y$2:$Y$73,"Runtime error") | M16: =IF(L$17=0,0,L16/L$17) | N16: =COUNTIF(Overview!$AC$2:$AC$73,"Runtime error") | O16: =IF(N$17=0,0,N16/N$17)
A17: Total | B17: =SUM(B14:B16) | C17: =SUM(C14:C16) | D17: =SUM(D14:D16) | E17: =SUM(E14:E16) | F17: =SUM(F14:F16) | G17: =SUM(G14:G16) | H17: =SUM(H14:H16) | I17: =SUM(I14:I16) | ... O17: =SUM(O14:O16)
A19: 3. Cases that passed on at least one version
A20: Result | B20: gpt-5.6-luna | C20: % | D20: gpt-6-luna | E20: % | F20: gpt-6-astra | G20: % | H20: gpt-6.1-sol | I20: % | J20: claude-opus-5-5 | K20: % | L20: claude-sonnet-5-5 | M20: % | N20: claude-haiku-5-5 | O20: %
A21: Passed on at least one version | B21: =COUNTIF(Overview!$F$2:$F$73,">0") | C21: =IF(COUNTA(Overview!$B$2:$B$73)=0,0,B21/COUNTA(Overview!$B$2:$B$73)) | D21: =COUNTIF(Overview!$J$2:$J$73,">0") | E21: =IF(COUNTA(Overview!$B$2:$B$73)=0,0,D21/COUNTA(Overview!$B$2:$B$73)) | F21: =COUNTIF(Overview!$N$2:$N$73,">0") | G21: =IF(COUNTA(Overview!$B$2:$B$73)=0,0,F21/COUNTA(Overview!$B$2:$B$73)) | H21: =COUNTIF(Overview!$R$2:$R$73,">0") | I21: =IF(COUNTA(Overview!$B$2:$B$73)=0,0,H21/COUNTA(Overview!$B$2:$B$73)) | J21: =COUNTIF(Overview!$V$2:$V$73,">0") | K21: =IF(COUNTA(Overview!$B$2:$B$73)=0,0,J21/COUNTA(Overview!$B$2:$B$73)) | L21: =COUNTIF(Overview!$Z$2:$Z$73,">0") | M21: =IF(COUNTA(Overview!$B$2:$B$73)=0,0,L21/COUNTA(Overview!$B$2:$B$73)) | N21: =COUNTIF(Overview!$AD$2:$AD$73,">0") | O21: =IF(COUNTA(Overview!$B$2:$B$73)=0,0,N21/COUNTA(Overview!$B$2:$B$73))
A22: Passed on every version | B22: =B14 | C22: =IF(COUNTA(Overview!$B$2:$B$73)=0,0,B22/COUNTA(Overview!$B$2:$B$73)) | D22: =D14 | E22: =IF(COUNTA(Overview!$B$2:$B$73)=0,0,D22/COUNTA(Overview!$B$2:$B$73)) | F22: =F14 | G22: =IF(COUNTA(Overview!$B$2:$B$73)=0,0,F22/COUNTA(Overview!$B$2:$B$73)) | H22: =H14 | I22: =IF(COUNTA(Overview!$B$2:$B$73)=0,0,H22/COUNTA(Overview!$B$2:$B$73)) | J22: =J14 | K22: =IF(COUNTA(Overview!$B$2:$B$73)=0,0,J22/COUNTA(Overview!$B$2:$B$73)) | L22: =L14 | M22: =IF(COUNTA(Overview!$B$2:$B$73)=0,0,L22/COUNTA(Overview!$B$2:$B$73)) | N22: =N14 | O22: =IF(COUNTA(Overview!$B$2:$B$73)=0,0,N22/COUNTA(Overview!$B$2:$B$73))
A23: Passed on some but not all versions | B23: =B21-B22 | C23: =IF(COUNTA(Overview!$B$2:$B$73)=0,0,B23/COUNTA(Overview!$B$2:$B$73)) | D23: =D21-D22 | E23: =IF(COUNTA(Overview!$B$2:$B$73)=0,0,D23/COUNTA(Overview!$B$2:$B$73)) | F23: =F21-F22 | G23: =IF(COUNTA(Overview!$B$2:$B$73)=0,0,F23/COUNTA(Overview!$B$2:$B$73)) | H23: =H21-H22 | I23: =IF(COUNTA(Overview!$B$2:$B$73)=0,0,H23/COUNTA(Overview!$B$2:$B$73)) | J23: =J21-J22 | K23: =IF(COUNTA(Overview!$B$2:$B$73)=0,0,J23/COUNTA(Overview!$B$2:$B$73)) | L23: =L21-L22 | M23: =IF(COUNTA(Overview!$B$2:$B$73)=0,0,L23/COUNTA(Overview!$B$2:$B$73)) | N23: =N21-N22 | O23: =IF(COUNTA(Overview!$B$2:$B$73)=0,0,N23/COUNTA(Overview!$B$2:$B$73))
A24: Passed on no version | B24: =COUNTIF(Overview!$F$2:$F$73,0) | C24: =IF(COUNTA(Overview!$B$2:$B$73)=0,0,B24/COUNTA(Overview!$B$2:$B$73)) | D24: =COUNTIF(Overview!$J$2:$J$73,0) | E24: =IF(COUNTA(Overview!$B$2:$B$73)=0,0,D24/COUNTA(Overview!$B$2:$B$73)) | F24: =COUNTIF(Overview!$N$2:$N$73,0) | G24: =IF(COUNTA(Overview!$B$2:$B$73)=0,0,F24/COUNTA(Overview!$B$2:$B$73)) | H24: =COUNTIF(Overview!$R$2:$R$73,0) | I24: =IF(COUNTA(Overview!$B$2:$B$73)=0,0,H24/COUNTA(Overview!$B$2:$B$73)) | J24: =COUNTIF(Overview!$V$2:$V$73,0) | K24: =IF(COUNTA(Overview!$B$2:$B$73)=0,0,J24/COUNTA(Overview!$B$2:$B$73)) | L24: =COUNTIF(Overview!$Z$2:$Z$73,0) | M24: =IF(COUNTA(Overview!$B$2:$B$73)=0,0,L24/COUNTA(Overview!$B$2:$B$73)) | N24: =COUNTIF(Overview!$AD$2:$AD$73,0) | O24: =IF(COUNTA(Overview!$B$2:$B$73)=0,0,N24/COUNTA(Overview!$B$2:$B$73))
A26: 4. By batch: pair pass, fail, and runtime error
A27: Batch | B27: Cases | C27: Pairs | D27: gpt-5.6-luna | H27: gpt-6-luna | L27: gpt-6-astra | P27: gpt-6.1-sol | T27: claude-opus-5-5 | X27: claude-sonnet-5-5 | AB27: claude-haiku-5-5
D28: Passed | E28: Failed | F28: Runtime error | G28: % passed | H28: Passed | I28: Failed | J28: Runtime error | K28: % passed | L28: Passed | M28: Failed | N28: Runtime error | O28: % passed | P28: Passed | Q28: Failed | R28: Runtime error | S28: % passed | T28: Passed | U28: Failed | V28: Runtime error | W28: % passed | X28: Passed | Y28: Failed | Z28: Runtime error | AA28: % passed | AB28: Passed | AC28: Failed | AD28: Runtime error | AE28: % passed
A29: 1 | B29: =COUNTIF(Overview!$A$2:$A$73,1) | C29: =SUMIF(Overview!$A$2:$A$73,1,Overview!$D$2:$D$73) | D29: =SUMIF(Overview!$A$2:$A$73,1,Overview!$F$2:$F$73) | E29: =SUMIF(Overview!$A$2:$A$73,1,Overview!$G$2:$G$73) | F29: =SUMIF(Overview!$A$2:$A$73,1,Overview!$H$2:$H$73) | G29: =IF($C29=0,0,D29/$C29) | H29: =SUMIF(Overview!$A$2:$A$73,1,Overview!$J$2:$J$73) | I29: =SUMIF(Overview!$A$2:$A$73,1,Overview!$K$2:$K$73) | J29: =SUMIF(Overview!$A$2:$A$73,1,Overview!$L$2:$L$73) | K29: =IF($C29=0,0,H29/$C29) | L29: =SUMIF(Overview!$A$2:$A$73,1,Overview!$N$2:$N$73) | M29: =SUMIF(Overview!$A$2:$A$73,1,Overview!$O$2:$O$73) | N29: =SUMIF(Overview!$A$2:$A$73,1,Overview!$P$2:$P$73) | O29: =IF($C29=0,0,L29/$C29) | P29: =SUMIF(Overview!$A$2:$A$73,1,Overview!$R$2:$R$73) | Q29: =SUMIF(Overview!$A$2:$A$73,1,Overview!$S$2:$S$73) | R29: =SUMIF(Overview!$A$2:$A$73,1,Overview!$T$2:$T$73) | S29: =IF($C29=0,0,P29/$C29) | T29: =SUMIF(Overview!$A$2:$A$73,1,Overview!$V$2:$V$73) | U29: =SUMIF(Overview!$A$2:$A$73,1,Overview!$W$2:$W$73) | V29: =SUMIF(Overview!$A$2:$A$73,1,Overview!$X$2:$X$73) | W29: =IF($C29=0,0,T29/$C29) | X29: =SUMIF(Overview!$A$2:$A$73,1,Overview!$Z$2:$Z$73) | Y29: =SUMIF(Overview!$A$2:$A$73,1,Overview!$AA$2:$AA$73) | Z29: =SUMIF(Overview!$A$2:$A$73,1,Overview!$AB$2:$AB$73) | AA29: =IF($C29=0,0,X29/$C29) | AB29: =SUMIF(Overview!$A$2:$A$73,1,Overview!$AD$2:$AD$73) | AC29: =SUMIF(Overview!$A$2:$A$73,1,Overview!$AE$2:$AE$73) | AD29: =SUMIF(Overview!$A$2:$A$73,1,Overview!$AF$2:$AF$73) | AE29: =IF($C29=0,0,AB29/$C29)
A30: 2 | B30: =COUNTIF(Overview!$A$2:$A$73,2) | C30: =SUMIF(Overview!$A$2:$A$73,2,Overview!$D$2:$D$73) | D30: =SUMIF(Overview!$A$2:$A$73,2,Overview!$F$2:$F$73) | E30: =SUMIF(Overview!$A$2:$A$73,2,Overview!$G$2:$G$73) | F30: =SUMIF(Overview!$A$2:$A$73,2,Overview!$H$2:$H$73) | G30: =IF($C30=0,0,D30/$C30) | H30: =SUMIF(Overview!$A$2:$A$73,2,Overview!$J$2:$J$73) | I30: =SUMIF(Overview!$A$2:$A$73,2,Overview!$K$2:$K$73) | J30: =SUMIF(Overview!$A$2:$A$73,2,Overview!$L$2:$L$73) | K30: =IF($C30=0,0,H30/$C30) | L30: =SUMIF(Overview!$A$2:$A$73,2,Overview!$N$2:$N$73) | M30: =SUMIF(Overview!$A$2:$A$73,2,Overview!$O$2:$O$73) | N30: =SUMIF(Overview!$A$2:$A$73,2,Overview!$P$2:$P$73) | O30: =IF($C30=0,0,L30/$C30) | P30: =SUMIF(Overview!$A$2:$A$73,2,Overview!$R$2:$R$73) | Q30: =SUMIF(Overview!$A$2:$A$73,2,Overview!$S$2:$S$73) | R30: =SUMIF(Overview!$A$2:$A$73,2,Overview!$T$2:$T$73) | S30: =IF($C30=0,0,P30/$C30) | T30: =SUMIF(Overview!$A$2:$A$73,2,Overview!$V$2:$V$73) | U30: =SUMIF(Overview!$A$2:$A$73,2,Overview!$W$2:$W$73) | V30: =SUMIF(Overview!$A$2:$A$73,2,Overview!$X$2:$X$73) | W30: =IF($C30=0,0,T30/$C30) | X30: =SUMIF(Overview!$A$2:$A$73,2,Overview!$Z$2:$Z$73) | Y30: =SUMIF(Overview!$A$2:$A$73,2,Overview!$AA$2:$AA$73) | Z30: =SUMIF(Overview!$A$2:$A$73,2,Overview!$AB$2:$AB$73) | AA30: =IF($C30=0,0,X30/$C30) | AB30: =SUMIF(Overview!$A$2:$A$73,2,Overview!$AD$2:$AD$73) | AC30: =SUMIF(Overview!$A$2:$A$73,2,Overview!$AE$2:$AE$73) | AD30: =SUMIF(Overview!$A$2:$A$73,2,Overview!$AF$2:$AF$73) | AE30: =IF($C30=0,0,AB30/$C30)
A31: 3 | B31: =COUNTIF(Overview!$A$2:$A$73,3) | C31: =SUMIF(Overview!$A$2:$A$73,3,Overview!$D$2:$D$73) | D31: =SUMIF(Overview!$A$2:$A$73,3,Overview!$F$2:$F$73) | E31: =SUMIF(Overview!$A$2:$A$73,3,Overview!$G$2:$G$73) | F31: =SUMIF(Overview!$A$2:$A$73,3,Overview!$H$2:$H$73) | G31: =IF($C31=0,0,D31/$C31) | H31: =SUMIF(Overview!$A$2:$A$73,3,Overview!$J$2:$J$73) | I31: =SUMIF(Overview!$A$2:$A$73,3,Overview!$K$2:$K$73) | J31: =SUMIF(Overview!$A$2:$A$73,3,Overview!$L$2:$L$73) | K31: =IF($C31=0,0,H31/$C31) | L31: =SUMIF(Overview!$A$2:$A$73,3,Overview!$N$2:$N$73) | M31: =SUMIF(Overview!$A$2:$A$73,3,Overview!$O$2:$O$73) | N31: =SUMIF(Overview!$A$2:$A$73,3,Overview!$P$2:$P$73) | O31: =IF($C31=0,0,L31/$C31) | P31: =SUMIF(Overview!$A$2:$A$73,3,Overview!$R$2:$R$73) | Q31: =SUMIF(Overview!$A$2:$A$73,3,Overview!$S$2:$S$73) | R31: =SUMIF(Overview!$A$2:$A$73,3,Overview!$T$2:$T$73) | S31: =IF($C31=0,0,P31/$C31) | T31: =SUMIF(Overview!$A$2:$A$73,3,Overview!$V$2:$V$73) | U31: =SUMIF(Overview!$A$2:$A$73,3,Overview!$W$2:$W$73) | V31: =SUMIF(Overview!$A$2:$A$73,3,Overview!$X$2:$X$73) | W31: =IF($C31=0,0,T31/$C31) | X31: =SUMIF(Overview!$A$2:$A$73,3,Overview!$Z$2:$Z$73) | Y31: =SUMIF(Overview!$A$2:$A$73,3,Overview!$AA$2:$AA$73) | Z31: =SUMIF(Overview!$A$2:$A$73,3,Overview!$AB$2:$AB$73) | AA31: =IF($C31=0,0,X31/$C31) | AB31: =SUMIF(Overview!$A$2:$A$73,3,Overview!$AD$2:$AD$73) | AC31: =SUMIF(Overview!$A$2:$A$73,3,Overview!$AE$2:$AE$73) | AD31: =SUMIF(Overview!$A$2:$A$73,3,Overview!$AF$2:$AF$73) | AE31: =IF($C31=0,0,AB31/$C31)
A32: 4 | B32: =COUNTIF(Overview!$A$2:$A$73,4) | C32: =SUMIF(Overview!$A$2:$A$73,4,Overview!$D$2:$D$73) | D32: =SUMIF(Overview!$A$2:$A$73,4,Overview!$F$2:$F$73) | E32: =SUMIF(Overview!$A$2:$A$73,4,Overview!$G$2:$G$73) | F32: =SUMIF(Overview!$A$2:$A$73,4,Overview!$H$2:$H$73) | G32: =IF($C32=0,0,D32/$C32) | H32: =SUMIF(Overview!$A$2:$A$73,4,Overview!$J$2:$J$73) | I32: =SUMIF(Overview!$A$2:$A$73,4,Overview!$K$2:$K$73) | J32: =SUMIF(Overview!$A$2:$A$73,4,Overview!$L$2:$L$73) | K32: =IF($C32=0,0,H32/$C32) | L32: =SUMIF(Overview!$A$2:$A$73,4,Overview!$N$2:$N$73) | M32: =SUMIF(Overview!$A$2:$A$73,4,Overview!$O$2:$O$73) | N32: =SUMIF(Overview!$A$2:$A$73,4,Overview!$P$2:$P$73) | O32: =IF($C32=0,0,L32/$C32) | P32: =SUMIF(Overview!$A$2:$A$73,4,Overview!$R$2:$R$73) | Q32: =SUMIF(Overview!$A$2:$A$73,4,Overview!$S$2:$S$73) | R32: =SUMIF(Overview!$A$2:$A$73,4,Overview!$T$2:$T$73) | S32: =IF($C32=0,0,P32/$C32) | T32: =SUMIF(Overview!$A$2:$A$73,4,Overview!$V$2:$V$73) | U32: =SUMIF(Overview!$A$2:$A$73,4,Overview!$W$2:$W$73) | V32: =SUMIF(Overview!$A$2:$A$73,4,Overview!$X$2:$X$73) | W32: =IF($C32=0,0,T32/$C32) | X32: =SUMIF(Overview!$A$2:$A$73,4,Overview!$Z$2:$Z$73) | Y32: =SUMIF(Overview!$A$2:$A$73,4,Overview!$AA$2:$AA$73) | Z32: =SUMIF(Overview!$A$2:$A$73,4,Overview!$AB$2:$AB$73) | AA32: =IF($C32=0,0,X32/$C32) | AB32: =SUMIF(Overview!$A$2:$A$73,4,Overview!$AD$2:$AD$73) | AC32: =SUMIF(Overview!$A$2:$A$73,4,Overview!$AE$2:$AE$73) | AD32: =SUMIF(Overview!$A$2:$A$73,4,Overview!$AF$2:$AF$73) | AE32: =IF($C32=0,0,AB32/$C32)
A33: 5 | B33: =COUNTIF(Overview!$A$2:$A$73,5) | C33: =SUMIF(Overview!$A$2:$A$73,5,Overview!$D$2:$D$73) | D33: =SUMIF(Overview!$A$2:$A$73,5,Overview!$F$2:$F$73) | E33: =SUMIF(Overview!$A$2:$A$73,5,Overview!$G$2:$G$73) | F33: =SUMIF(Overview!$A$2:$A$73,5,Overview!$H$2:$H$73) | G33: =IF($C33=0,0,D33/$C33) | H33: =SUMIF(Overview!$A$2:$A$73,5,Overview!$J$2:$J$73) | I33: =SUMIF(Overview!$A$2:$A$73,5,Overview!$K$2:$K$73) | J33: =SUMIF(Overview!$A$2:$A$73,5,Overview!$L$2:$L$73) | K33: =IF($C33=0,0,H33/$C33) | L33: =SUMIF(Overview!$A$2:$A$73,5,Overview!$N$2:$N$73) | M33: =SUMIF(Overview!$A$2:$A$73,5,Overview!$O$2:$O$73) | N33: =SUMIF(Overview!$A$2:$A$73,5,Overview!$P$2:$P$73) | O33: =IF($C33=0,0,L33/$C33) | P33: =SUMIF(Overview!$A$2:$A$73,5,Overview!$R$2:$R$73) | Q33: =SUMIF(Overview!$A$2:$A$73,5,Overview!$S$2:$S$73) | R33: =SUMIF(Overview!$A$2:$A$73,5,Overview!$T$2:$T$73) | S33: =IF($C33=0,0,P33/$C33) | T33: =SUMIF(Overview!$A$2:$A$73,5,Overview!$V$2:$V$73) | U33: =SUMIF(Overview!$A$2:$A$73,5,Overview!$W$2:$W$73) | V33: =SUMIF(Overview!$A$2:$A$73,5,Overview!$X$2:$X$73) | W33: =IF($C33=0,0,T33/$C33) | X33: =SUMIF(Overview!$A$2:$A$73,5,Overview!$Z$2:$Z$73) | Y33: =SUMIF(Overview!$A$2:$A$73,5,Overview!$AA$2:$AA$73) | Z33: =SUMIF(Overview!$A$2:$A$73,5,Overview!$AB$2:$AB$73) | AA33: =IF($C33=0,0,X33/$C33) | AB33: =SUMIF(Overview!$A$2:$A$73,5,Overview!$AD$2:$AD$73) | AC33: =SUMIF(Overview!$A$2:$A$73,5,Overview!$AE$2:$AE$73) | AD33: =SUMIF(Overview!$A$2:$A$73,5,Overview!$AF$2:$AF$73) | AE33: =IF($C33=0,0,AB33/$C33)
A34: 6 | B34: =COUNTIF(Overview!$A$2:$A$73,6) | C34: =SUMIF(Overview!$A$2:$A$73,6,Overview!$D$2:$D$73) | D34: =SUMIF(Overview!$A$2:$A$73,6,Overview!$F$2:$F$73) | E34: =SUMIF(Overview!$A$2:$A$73,6,Overview!$G$2:$G$73) | F34: =SUMIF(Overview!$A$2:$A$73,6,Overview!$H$2:$H$73) | G34: =IF($C34=0,0,D34/$C34) | H34: =SUMIF(Overview!$A$2:$A$73,6,Overview!$J$2:$J$73) | I34: =SUMIF(Overview!$A$2:$A$73,6,Overview!$K$2:$K$73) | J34: =SUMIF(Overview!$A$2:$A$73,6,Overview!$L$2:$L$73) | K34: =IF($C34=0,0,H34/$C34) | L34: =SUMIF(Overview!$A$2:$A$73,6,Overview!$N$2:$N$73) | M34: =SUMIF(Overview!$A$2:$A$73,6,Overview!$O$2:$O$73) | N34: =SUMIF(Overview!$A$2:$A$73,6,Overview!$P$2:$P$73) | O34: =IF($C34=0,0,L34/$C34) | P34: =SUMIF(Overview!$A$2:$A$73,6,Overview!$R$2:$R$73) | Q34: =SUMIF(Overview!$A$2:$A$73,6,Overview!$S$2:$S$73) | R34: =SUMIF(Overview!$A$2:$A$73,6,Overview!$T$2:$T$73) | S34: =IF($C34=0,0,P34/$C34) | T34: =SUMIF(Overview!$A$2:$A$73,6,Overview!$V$2:$V$73) | U34: =SUMIF(Overview!$A$2:$A$73,6,Overview!$W$2:$W$73) | V34: =SUMIF(Overview!$A$2:$A$73,6,Overview!$X$2:$X$73) | W34: =IF($C34=0,0,T34/$C34) | X34: =SUMIF(Overview!$A$2:$A$73,6,Overview!$Z$2:$Z$73) | Y34: =SUMIF(Overview!$A$2:$A$73,6,Overview!$AA$2:$AA$73) | Z34: =SUMIF(Overview!$A$2:$A$73,6,Overview!$AB$2:$AB$73) | AA34: =IF($C34=0,0,X34/$C34) | AB34: =SUMIF(Overview!$A$2:$A$73,6,Overview!$AD$2:$AD$73) | AC34: =SUMIF(Overview!$A$2:$A$73,6,Overview!$AE$2:$AE$73) | AD34: =SUMIF(Overview!$A$2:$A$73,6,Overview!$AF$2:$AF$73) | AE34: =IF($C34=0,0,AB34/$C34)
A35: 7 | B35: =COUNTIF(Overview!$A$2:$A$73,7) | C35: =SUMIF(Overview!$A$2:$A$73,7,Overview!$D$2:$D$73) | D35: =SUMIF(Overview!$A$2:$A$73,7,Overview!$F$2:$F$73) | E35: =SUMIF(Overview!$A$2:$A$73,7,Overview!$G$2:$G$73) | F35: =SUMIF(Overview!$A$2:$A$73,7,Overview!$H$2:$H$73) | G35: =IF($C35=0,0,D35/$C35) | H35: =SUMIF(Overview!$A$2:$A$73,7,Overview!$J$2:$J$73) | I35: =SUMIF(Overview!$A$2:$A$73,7,Overview!$K$2:$K$73) | J35: =SUMIF(Overview!$A$2:$A$73,7,Overview!$L$2:$L$73) | K35: =IF($C35=0,0,H35/$C35) | L35: =SUMIF(Overview!$A$2:$A$73,7,Overview!$N$2:$N$73) | M35: =SUMIF(Overview!$A$2:$A$73,7,Overview!$O$2:$O$73) | N35: =SUMIF(Overview!$A$2:$A$73,7,Overview!$P$2:$P$73) | O35: =IF($C35=0,0,L35/$C35) | P35: =SUMIF(Overview!$A$2:$A$73,7,Overview!$R$2:$R$73) | Q35: =SUMIF(Overview!$A$2:$A$73,7,Overview!$S$2:$S$73) | R35: =SUMIF(Overview!$A$2:$A$73,7,Overview!$T$2:$T$73) | S35: =IF($C35=0,0,P35/$C35) | T35: =SUMIF(Overview!$A$2:$A$73,7,Overview!$V$2:$V$73) | U35: =SUMIF(Overview!$A$2:$A$73,7,Overview!$W$2:$W$73) | V35: =SUMIF(Overview!$A$2:$A$73,7,Overview!$X$2:$X$73) | W35: =IF($C35=0,0,T35/$C35) | X35: =SUMIF(Overview!$A$2:$A$73,7,Overview!$Z$2:$Z$73) | Y35: =SUMIF(Overview!$A$2:$A$73,7,Overview!$AA$2:$AA$73) | Z35: =SUMIF(Overview!$A$2:$A$73,7,Overview!$AB$2:$AB$73) | AA35: =IF($C35=0,0,X35/$C35) | AB35: =SUMIF(Overview!$A$2:$A$73,7,Overview!$AD$2:$AD$73) | AC35: =SUMIF(Overview!$A$2:$A$73,7,Overview!$AE$2:$AE$73) | AD35: =SUMIF(Overview!$A$2:$A$73,7,Overview!$AF$2:$AF$73) | AE35: =IF($C35=0,0,AB35/$C35)
A36: 8 | B36: =COUNTIF(Overview!$A$2:$A$73,8) | C36: =SUMIF(Overview!$A$2:$A$73,8,Overview!$D$2:$D$73) | D36: =SUMIF(Overview!$A$2:$A$73,8,Overview!$F$2:$F$73) | E36: =SUMIF(Overview!$A$2:$A$73,8,Overview!$G$2:$G$73) | F36: =SUMIF(Overview!$A$2:$A$73,8,Overview!$H$2:$H$73) | G36: =IF($C36=0,0,D36/$C36) | H36: =SUMIF(Overview!$A$2:$A$73,8,Overview!$J$2:$J$73) | I36: =SUMIF(Overview!$A$2:$A$73,8,Overview!$K$2:$K$73) | J36: =SUMIF(Overview!$A$2:$A$73,8,Overview!$L$2:$L$73) | K36: =IF($C36=0,0,H36/$C36) | L36: =SUMIF(Overview!$A$2:$A$73,8,Overview!$N$2:$N$73) | M36: =SUMIF(Overview!$A$2:$A$73,8,Overview!$O$2:$O$73) | N36: =SUMIF(Overview!$A$2:$A$73,8,Overview!$P$2:$P$73) | O36: =IF($C36=0,0,L36/$C36) | P36: =SUMIF(Overview!$A$2:$A$73,8,Overview!$R$2:$R$73) | Q36: =SUMIF(Overview!$A$2:$A$73,8,Overview!$S$2:$S$73) | R36: =SUMIF(Overview!$A$2:$A$73,8,Overview!$T$2:$T$73) | S36: =IF($C36=0,0,P36/$C36) | T36: =SUMIF(Overview!$A$2:$A$73,8,Overview!$V$2:$V$73) | U36: =SUMIF(Overview!$A$2:$A$73,8,Overview!$W$2:$W$73) | V36: =SUMIF(Overview!$A$2:$A$73,8,Overview!$X$2:$X$73) | W36: =IF($C36=0,0,T36/$C36) | X36: =SUMIF(Overview!$A$2:$A$73,8,Overview!$Z$2:$Z$73) | Y36: =SUMIF(Overview!$A$2:$A$73,8,Overview!$AA$2:$AA$73) | Z36: =SUMIF(Overview!$A$2:$A$73,8,Overview!$AB$2:$AB$73) | AA36: =IF($C36=0,0,X36/$C36) | AB36: =SUMIF(Overview!$A$2:$A$73,8,Overview!$AD$2:$AD$73) | AC36: =SUMIF(Overview!$A$2:$A$73,8,Overview!$AE$2:$AE$73) | AD36: =SUMIF(Overview!$A$2:$A$73,8,Overview!$AF$2:$AF$73) | AE36: =IF($C36=0,0,AB36/$C36)
A37: Total | B37: =COUNTA(Overview!$B$2:$B$73) | C37: =SUM(Overview!$D$2:$D$73) | D37: =SUM(Overview!$F$2:$F$73) | E37: =SUM(Overview!$G$2:$G$73) | F37: =SUM(Overview!$H$2:$H$73) | G37: =IF($C37=0,0,D37/$C37) | H37: =SUM(Overview!$J$2:$J$73) | I37: =SUM(Overview!$K$2:$K$73) | J37: =SUM(Overview!$L$2:$L$73) | K37: =IF($C37=0,0,H37/$C37) | L37: =SUM(Overview!$N$2:$N$73) | M37: =SUM(Overview!$O$2:$O$73) | N37: =SUM(Overview!$P$2:$P$73) | O37: =IF($C37=0,0,L37/$C37) | P37: =SUM(Overview!$R$2:$R$73) | Q37: =SUM(Overview!$S$2:$S$73) | R37: =SUM(Overview!$T$2:$T$73) | S37: =IF($C37=0,0,P37/$C37) | T37: =SUM(Overview!$V$2:$V$73) | U37: =SUM(Overview!$W$2:$W$73) | V37: =SUM(Overview!$X$2:$X$73) | W37: =IF($C37=0,0,T37/$C37) | X37: =SUM(Overview!$Z$2:$Z$73) | Y37: =SUM(Overview!$AA$2:$AA$73) | Z37: =SUM(Overview!$AB$2:$AB$73) | AA37: =IF($C37=0,0,X37/$C37) | AB37: =SUM(Overview!$AD$2:$AD$73) | AC37: =SUM(Overview!$AE$2:$AE$73) | AD37: =SUM(Overview!$AF$2:$AF$73) | AE37: =IF($C37=0,0,AB37/$C37)

Sheet Overview
A1: Batch | B1: Case | C1: Question | D1: Versions tested | E1: gpt-5.6-luna outcome | F1: gpt-5.6-luna passed | G1: gpt-5.6-luna failed | H1: gpt-5.6-luna errors | I1: gpt-6-luna outcome | J1: gpt-6-luna passed | K1: gpt-6-luna failed | L1: gpt-6-luna errors | M1: gpt-6-astra outcome | N1: gpt-6-astra passed | O1: gpt-6-astra failed | P1: gpt-6-astra errors | Q1: gpt-6.1-sol outcome | R1: gpt-6.1-sol passed | S1: gpt-6.1-sol failed | T1: gpt-6.1-sol errors | U1: claude-opus-5-5 outcome | V1: claude-opus-5-5 passed | W1: claude-opus-5-5 failed | X1: claude-opus-5-5 errors | Y1: claude-sonnet-5-5 outcome | Z1: claude-sonnet-5-5 passed | AA1: claude-sonnet-5-5 failed | AB1: claude-sonnet-5-5 errors | AC1: claude-haiku-5-5 outcome | AD1: claude-haiku-5-5 passed | AE1: claude-haiku-5-5 failed | AF1: claude-haiku-5-5 errors
A2: 1 | B2: issue_009 | C2: CSP layout in the transpiler | D2: =COUNTIF('gpt-5.6-luna'!$B2:$AB2,"Passed on test")+COUNTIF('gpt-5.6-luna'!$B2:$AB2,"Failed on test")+COUNTIF('gpt-5.6-luna'!$B2:$AB2,"Runtime error") | E2: =IF(F2=$D2,"Passed on test",IF(H2>0,"Runtime error","Failed on test")) | F2: =COUNTIF('gpt-5.6-luna'!$B2:$AB2,"Passed on test") | G2: =COUNTIF('gpt-5.6-luna'!$B2:$AB2,"Failed on test") | H2: =COUNTIF('gpt-5.6-luna'!$B2:$AB2,"Runtime error") | I2: =IF(J2=$D2,"Passed on test",IF(L2>0,"Runtime error","Failed on test")) | J2: =COUNTIF('gpt-6-luna'!$B2:$AB2,"Passed on test") | K2: =COUNTIF('gpt-6-luna'!$B2:$AB2,"Failed on test") | L2: =COUNTIF('gpt-6-luna'!$B2:$AB2,"Runtime error") | M2: =IF(N2=$D2,"Passed on test",IF(P2>0,"Runtime error","Failed on test")) | N2: =COUNTIF('gpt-6-astra'!$B2:$AB2,"Passed on test") | O2: =COUNTIF('gpt-6-astra'!$B2:$AB2,"Failed on test") | P2: =COUNTIF('gpt-6-astra'!$B2:$AB2,"Runtime error") | Q2: =IF(R2=$D2,"Passed on test",IF(T2>0,"Runtime error","Failed on test")) | R2: =COUNTIF('gpt-6.1-sol'!$B2:$AB2,"Passed on test") | S2: =COUNTIF('gpt-6.1-sol'!$B2:$AB2,"Failed on test") | T2: =COUNTIF('gpt-6.1-sol'!$B2:$AB2,"Runtime error") | U2: =IF(V2=$D2,"Passed on test",IF(X2>0,"Runtime error","Failed on test")) | V2: =COUNTIF('claude-opus-5-5'!$B2:$AB2,"PASS") | W2: =COUNTIF('claude-opus-5-5'!$B2:$AB2,"FAIL") | X2: =COUNTIF('claude-opus-5-5'!$B2:$AB2,"ERROR") | Y2: =IF(Z2=$D2,"Passed on test",IF(AB2>0,"Runtime error","Failed on test")) | Z2: =COUNTIF('claude-sonnet-5-5'!$B2:$AB2,"PASS") | AA2: =COUNTIF('claude-sonnet-5-5'!$B2:$AB2,"FAIL") | AB2: =COUNTIF('claude-sonnet-5-5'!$B2:$AB2,"ERROR") | AC2: =IF(AD2=$D2,"Passed on test",IF(AF2>0,"Runtime error","Failed on test")) | AD2: =COUNTIF('claude-haiku-5-5'!$B2:$AB2,"PASS") | AE2: =COUNTIF('claude-haiku-5-5'!$B2:$AB2,"FAIL") | AF2: =COUNTIF('claude-haiku-5-5'!$B2:$AB2,"ERROR")
A3: 1 | B3: issue_021_se | C3: get_statevector() with a custom gate | D3: =COUNTIF('gpt-5.6-luna'!$B3:$AB3,"Passed on test")+COUNTIF('gpt-5.6-luna'!$B3:$AB3,"Failed on test")+COUNTIF('gpt-5.6-luna'!$B3:$AB3,"Runtime error") | E3: =IF(F3=$D3,"Passed on test",IF(H3>0,"Runtime error","Failed on test")) | F3: =COUNTIF('gpt-5.6-luna'!$B3:$AB3,"Passed on test") | G3: =COUNTIF('gpt-5.6-luna'!$B3:$AB3,"Failed on test") | H3: =COUNTIF('gpt-5.6-luna'!$B3:$AB3,"Runtime error") | I3: =IF(J3=$D3,"Passed on test",IF(L3>0,"Runtime error","Failed on test")) | J3: =COUNTIF('gpt-6-luna'!$B3:$AB3,"Passed on test") | K3: =COUNTIF('gpt-6-luna'!$B3:$AB3,"Failed on test") | L3: =COUNTIF('gpt-6-luna'!$B3:$AB3,"Runtime error") | M3: =IF(N3=$D3,"Passed on test",IF(P3>0,"Runtime error","Failed on test")) | N3: =COUNTIF('gpt-6-astra'!$B3:$AB3,"Passed on test") | O3: =COUNTIF('gpt-6-astra'!$B3:$AB3,"Failed on test") | P3: =COUNTIF('gpt-6-astra'!$B3:$AB3,"Runtime error") | Q3: =IF(R3=$D3,"Passed on test",IF(T3>0,"Runtime error","Failed on test")) | R3: =COUNTIF('gpt-6.1-sol'!$B3:$AB3,"Passed on test") | S3: =COUNTIF('gpt-6.1-sol'!$B3:$AB3,"Failed on test") | T3: =COUNTIF('gpt-6.1-sol'!$B3:$AB3,"Runtime error") | U3: =IF(V3=$D3,"Passed on test",IF(X3>0,"Runtime error","Failed on test")) | V3: =COUNTIF('claude-opus-5-5'!$B3:$AB3,"PASS") | W3: =COUNTIF('claude-opus-5-5'!$B3:$AB3,"FAIL") | X3: =COUNTIF('claude-opus-5-5'!$B3:$AB3,"ERROR") | Y3: =IF(Z3=$D3,"Passed on test",IF(AB3>0,"Runtime error","Failed on test")) | Z3: =COUNTIF('claude-sonnet-5-5'!$B3:$AB3,"PASS") | AA3: =COUNTIF('claude-sonnet-5-5'!$B3:$AB3,"FAIL") | AB3: =COUNTIF('claude-sonnet-5-5'!$B3:$AB3,"ERROR") | AC3: =IF(AD3=$D3,"Passed on test",IF(AF3>0,"Runtime error","Failed on test")) | AD3: =COUNTIF('claude-haiku-5-5'!$B3:$AB3,"PASS") | AE3: =COUNTIF('claude-haiku-5-5'!$B3:$AB3,"FAIL") | AF3: =COUNTIF('claude-haiku-5-5'!$B3:$AB3,"ERROR")
A4: 1 | B4: issue_032_se | C4: iSWAP in TwoLocal | D4: =COUNTIF('gpt-5.6-luna'!$B4:$AB4,"Passed on test")+COUNTIF('gpt-5.6-luna'!$B4:$AB4,"Failed on test")+COUNTIF('gpt-5.6-luna'!$B4:$AB4,"Runtime error") | E4: =IF(F4=$D4,"Passed on test",IF(H4>0,"Runtime error","Failed on test")) | F4: =COUNTIF('gpt-5.6-luna'!$B4:$AB4,"Passed on test") | G4: =COUNTIF('gpt-5.6-luna'!$B4:$AB4,"Failed on test") | H4: =COUNTIF('gpt-5.6-luna'!$B4:$AB4,"Runtime error") | I4: =IF(J4=$D4,"Passed on test",IF(L4>0,"Runtime error","Failed on test")) | J4: =COUNTIF('gpt-6-luna'!$B4:$AB4,"Passed on test") | K4: =COUNTIF('gpt-6-luna'!$B4:$AB4,"Failed on test") | L4: =COUNTIF('gpt-6-luna'!$B4:$AB4,"Runtime error") | M4: =IF(N4=$D4,"Passed on test",IF(P4>0,"Runtime error","Failed on test")) | N4: =COUNTIF('gpt-6-astra'!$B4:$AB4,"Passed on test") | O4: =COUNTIF('gpt-6-astra'!$B4:$AB4,"Failed on test") | P4: =COUNTIF('gpt-6-astra'!$B4:$AB4,"Runtime error") | Q4: =IF(R4=$D4,"Passed on test",IF(T4>0,"Runtime error","Failed on test")) | R4: =COUNTIF('gpt-6.1-sol'!$B4:$AB4,"Passed on test") | S4: =COUNTIF('gpt-6.1-sol'!$B4:$AB4,"Failed on test") | T4: =COUNTIF('gpt-6.1-sol'!$B4:$AB4,"Runtime error") | U4: =IF(V4=$D4,"Passed on test",IF(X4>0,"Runtime error","Failed on test")) | V4: =COUNTIF('claude-opus-5-5'!$B4:$AB4,"PASS") | W4: =COUNTIF('claude-opus-5-5'!$B4:$AB4,"FAIL") | X4: =COUNTIF('claude-opus-5-5'!$B4:$AB4,"ERROR") | Y4: =IF(Z4=$D4,"Passed on test",IF(AB4>0,"Runtime error","Failed on test")) | Z4: =COUNTIF('claude-sonnet-5-5'!$B4:$AB4,"PASS") | AA4: =COUNTIF('claude-sonnet-5-5'!$B4:$AB4,"FAIL") | AB4: =COUNTIF('claude-sonnet-5-5'!$B4:$AB4,"ERROR") | AC4: =IF(AD4=$D4,"Passed on test",IF(AF4>0,"Runtime error","Failed on test")) | AD4: =COUNTIF('claude-haiku-5-5'!$B4:$AB4,"PASS") | AE4: =COUNTIF('claude-haiku-5-5'!$B4:$AB4,"FAIL") | AF4: =COUNTIF('claude-haiku-5-5'!$B4:$AB4,"ERROR")
A5: 1 | B5: issue_034 | C5: Importing Aer | D5: =COUNTIF('gpt-5.6-luna'!$B5:$AB5,"Passed on test")+COUNTIF('gpt-5.6-luna'!$B5:$AB5,"Failed on test")+COUNTIF('gpt-5.6-luna'!$B5:$AB5,"Runtime error") | E5: =IF(F5=$D5,"Passed on test",IF(H5>0,"Runtime error","Failed on test")) | F5: =COUNTIF('gpt-5.6-luna'!$B5:$AB5,"Passed on test") | G5: =COUNTIF('gpt-5.6-luna'!$B5:$AB5,"Failed on test") | H5: =COUNTIF('gpt-5.6-luna'!$B5:$AB5,"Runtime error") | I5: =IF(J5=$D5,"Passed on test",IF(L5>0,"Runtime error","Failed on test")) | J5: =COUNTIF('gpt-6-luna'!$B5:$AB5,"Passed on test") | K5: =COUNTIF('gpt-6-luna'!$B5:$AB5,"Failed on test") | L5: =COUNTIF('gpt-6-luna'!$B5:$AB5,"Runtime error") | M5: =IF(N5=$D5,"Passed on test",IF(P5>0,"Runtime error","Failed on test")) | N5: =COUNTIF('gpt-6-astra'!$B5:$AB5,"Passed on test") | O5: =COUNTIF('gpt-6-astra'!$B5:$AB5,"Failed on test") | P5: =COUNTIF('gpt-6-astra'!$B5:$AB5,"Runtime error") | Q5: =IF(R5=$D5,"Passed on test",IF(T5>0,"Runtime error","Failed on test")) | R5: =COUNTIF('gpt-6.1-sol'!$B5:$AB5,"Passed on test") | S5: =COUNTIF('gpt-6.1-sol'!$B5:$AB5,"Failed on test") | T5: =COUNTIF('gpt-6.1-sol'!$B5:$AB5,"Runtime error") | U5: =IF(V5=$D5,"Passed on test",IF(X5>0,"Runtime error","Failed on test")) | V5: =COUNTIF('claude-opus-5-5'!$B5:$AB5,"PASS") | W5: =COUNTIF('claude-opus-5-5'!$B5:$AB5,"FAIL") | X5: =COUNTIF('claude-opus-5-5'!$B5:$AB5,"ERROR") | Y5: =IF(Z5=$D5,"Passed on test",IF(AB5>0,"Runtime error","Failed on test")) | Z5: =COUNTIF('claude-sonnet-5-5'!$B5:$AB5,"PASS") | AA5: =COUNTIF('claude-sonnet-5-5'!$B5:$AB5,"FAIL") | AB5: =COUNTIF('claude-sonnet-5-5'!$B5:$AB5,"ERROR") | AC5: =IF(AD5=$D5,"Passed on test",IF(AF5>0,"Runtime error","Failed on test")) | AD5: =COUNTIF('claude-haiku-5-5'!$B5:$AB5,"PASS") | AE5: =COUNTIF('claude-haiku-5-5'!$B5:$AB5,"FAIL") | AF5: =COUNTIF('claude-haiku-5-5'!$B5:$AB5,"ERROR")
A6: 1 | B6: issue_036 | C6: Circuit to OpenQASM 2.0 | D6: =COUNTIF('gpt-5.6-luna'!$B6:$AB6,"Passed on test")+COUNTIF('gpt-5.6-luna'!$B6:$AB6,"Failed on test")+COUNTIF('gpt-5.6-luna'!$B6:$AB6,"Runtime error") | E6: =IF(F6=$D6,"Passed on test",IF(H6>0,"Runtime error","Failed on test")) | F6: =COUNTIF('gpt-5.6-luna'!$B6:$AB6,"Passed on test") | G6: =COUNTIF('gpt-5.6-luna'!$B6:$AB6,"Failed on test") | H6: =COUNTIF('gpt-5.6-luna'!$B6:$AB6,"Runtime error") | I6: =IF(J6=$D6,"Passed on test",IF(L6>0,"Runtime error","Failed on test")) | J6: =COUNTIF('gpt-6-luna'!$B6:$AB6,"Passed on test") | K6: =COUNTIF('gpt-6-luna'!$B6:$AB6,"Failed on test") | L6: =COUNTIF('gpt-6-luna'!$B6:$AB6,"Runtime error") | M6: =IF(N6=$D6,"Passed on test",IF(P6>0,"Runtime error","Failed on test")) | N6: =COUNTIF('gpt-6-astra'!$B6:$AB6,"Passed on test") | O6: =COUNTIF('gpt-6-astra'!$B6:$AB6,"Failed on test") | P6: =COUNTIF('gpt-6-astra'!$B6:$AB6,"Runtime error") | Q6: =IF(R6=$D6,"Passed on test",IF(T6>0,"Runtime error","Failed on test")) | R6: =COUNTIF('gpt-6.1-sol'!$B6:$AB6,"Passed on test") | S6: =COUNTIF('gpt-6.1-sol'!$B6:$AB6,"Failed on test") | T6: =COUNTIF('gpt-6.1-sol'!$B6:$AB6,"Runtime error") | U6: =IF(V6=$D6,"Passed on test",IF(X6>0,"Runtime error","Failed on test")) | V6: =COUNTIF('claude-opus-5-5'!$B6:$AB6,"PASS") | W6: =COUNTIF('claude-opus-5-5'!$B6:$AB6,"FAIL") | X6: =COUNTIF('claude-opus-5-5'!$B6:$AB6,"ERROR") | Y6: =IF(Z6=$D6,"Passed on test",IF(AB6>0,"Runtime error","Failed on test")) | Z6: =COUNTIF('claude-sonnet-5-5'!$B6:$AB6,"PASS") | AA6: =COUNTIF('claude-sonnet-5-5'!$B6:$AB6,"FAIL") | AB6: =COUNTIF('claude-sonnet-5-5'!$B6:$AB6,"ERROR") | AC6: =IF(AD6=$D6,"Passed on test",IF(AF6>0,"Runtime error","Failed on test")) | AD6: =COUNTIF('claude-haiku-5-5'!$B6:$AB6,"PASS") | AE6: =COUNTIF('claude-haiku-5-5'!$B6:$AB6,"FAIL") | AF6: =COUNTIF('claude-haiku-5-5'!$B6:$AB6,"ERROR")
A7: 1 | B7: issue_058_se | C7: "contains invalid instructions" | D7: =COUNTIF('gpt-5.6-luna'!$B7:$AB7,"Passed on test")+COUNTIF('gpt-5.6-luna'!$B7:$AB7,"Failed on test")+COUNTIF('gpt-5.6-luna'!$B7:$AB7,"Runtime error") | E7: =IF(F7=$D7,"Passed on test",IF(H7>0,"Runtime error","Failed on test")) | F7: =COUNTIF('gpt-5.6-luna'!$B7:$AB7,"Passed on test") | G7: =COUNTIF('gpt-5.6-luna'!$B7:$AB7,"Failed on test") | H7: =COUNTIF('gpt-5.6-luna'!$B7:$AB7,"Runtime error") | I7: =IF(J7=$D7,"Passed on test",IF(L7>0,"Runtime error","Failed on test")) | J7: =COUNTIF('gpt-6-luna'!$B7:$AB7,"Passed on test") | K7: =COUNTIF('gpt-6-luna'!$B7:$AB7,"Failed on test") | L7: =COUNTIF('gpt-6-luna'!$B7:$AB7,"Runtime error") | M7: =IF(N7=$D7,"Passed on test",IF(P7>0,"Runtime error","Failed on test")) | N7: =COUNTIF('gpt-6-astra'!$B7:$AB7,"Passed on test") | O7: =COUNTIF('gpt-6-astra'!$B7:$AB7,"Failed on test") | P7: =COUNTIF('gpt-6-astra'!$B7:$AB7,"Runtime error") | Q7: =IF(R7=$D7,"Passed on test",IF(T7>0,"Runtime error","Failed on test")) | R7: =COUNTIF('gpt-6.1-sol'!$B7:$AB7,"Passed on test") | S7: =COUNTIF('gpt-6.1-sol'!$B7:$AB7,"Failed on test") | T7: =COUNTIF('gpt-6.1-sol'!$B7:$AB7,"Runtime error") | U7: =IF(V7=$D7,"Passed on test",IF(X7>0,"Runtime error","Failed on test")) | V7: =COUNTIF('claude-opus-5-5'!$B7:$AB7,"PASS") | W7: =COUNTIF('claude-opus-5-5'!$B7:$AB7,"FAIL") | X7: =COUNTIF('claude-opus-5-5'!$B7:$AB7,"ERROR") | Y7: =IF(Z7=$D7,"Passed on test",IF(AB7>0,"Runtime error","Failed on test")) | Z7: =COUNTIF('claude-sonnet-5-5'!$B7:$AB7,"PASS") | AA7: =COUNTIF('claude-sonnet-5-5'!$B7:$AB7,"FAIL") | AB7: =COUNTIF('claude-sonnet-5-5'!$B7:$AB7,"ERROR") | AC7: =IF(AD7=$D7,"Passed on test",IF(AF7>0,"Runtime error","Failed on test")) | AD7: =COUNTIF('claude-haiku-5-5'!$B7:$AB7,"PASS") | AE7: =COUNTIF('claude-haiku-5-5'!$B7:$AB7,"FAIL") | AF7: =COUNTIF('claude-haiku-5-5'!$B7:$AB7,"ERROR")
A8: 1 | B8: issue_061 | C8: Deprecated Bit.register / Bit.index | D8: =COUNTIF('gpt-5.6-luna'!$B8:$AB8,"Passed on test")+COUNTIF('gpt-5.6-luna'!$B8:$AB8,"Failed on test")+COUNTIF('gpt-5.6-luna'!$B8:$AB8,"Runtime error") | E8: =IF(F8=$D8,"Passed on test",IF(H8>0,"Runtime error","Failed on test")) | F8: =COUNTIF('gpt-5.6-luna'!$B8:$AB8,"Passed on test") | G8: =COUNTIF('gpt-5.6-luna'!$B8:$AB8,"Failed on test") | H8: =COUNTIF('gpt-5.6-luna'!$B8:$AB8,"Runtime error") | I8: =IF(J8=$D8,"Passed on test",IF(L8>0,"Runtime error","Failed on test")) | J8: =COUNTIF('gpt-6-luna'!$B8:$AB8,"Passed on test") | K8: =COUNTIF('gpt-6-luna'!$B8:$AB8,"Failed on test") | L8: =COUNTIF('gpt-6-luna'!$B8:$AB8,"Runtime error") | M8: =IF(N8=$D8,"Passed on test",IF(P8>0,"Runtime error","Failed on test")) | N8: =COUNTIF('gpt-6-astra'!$B8:$AB8,"Passed on test") | O8: =COUNTIF('gpt-6-astra'!$B8:$AB8,"Failed on test") | P8: =COUNTIF('gpt-6-astra'!$B8:$AB8,"Runtime error") | Q8: =IF(R8=$D8,"Passed on test",IF(T8>0,"Runtime error","Failed on test")) | R8: =COUNTIF('gpt-6.1-sol'!$B8:$AB8,"Passed on test") | S8: =COUNTIF('gpt-6.1-sol'!$B8:$AB8,"Failed on test") | T8: =COUNTIF('gpt-6.1-sol'!$B8:$AB8,"Runtime error") | U8: =IF(V8=$D8,"Passed on test",IF(X8>0,"Runtime error","Failed on test")) | V8: =COUNTIF('claude-opus-5-5'!$B8:$AB8,"PASS") | W8: =COUNTIF('claude-opus-5-5'!$B8:$AB8,"FAIL") | X8: =COUNTIF('claude-opus-5-5'!$B8:$AB8,"ERROR") | Y8: =IF(Z8=$D8,"Passed on test",IF(AB8>0,"Runtime error","Failed on test")) | Z8: =COUNTIF('claude-sonnet-5-5'!$B8:$AB8,"PASS") | AA8: =COUNTIF('claude-sonnet-5-5'!$B8:$AB8,"FAIL") | AB8: =COUNTIF('claude-sonnet-5-5'!$B8:$AB8,"ERROR") | AC8: =IF(AD8=$D8,"Passed on test",IF(AF8>0,"Runtime error","Failed on test")) | AD8: =COUNTIF('claude-haiku-5-5'!$B8:$AB8,"PASS") | AE8: =COUNTIF('claude-haiku-5-5'!$B8:$AB8,"FAIL") | AF8: =COUNTIF('claude-haiku-5-5'!$B8:$AB8,"ERROR")
A9: 1 | B9: issue_072 | C9: Duplicate qubit in a layout | D9: =COUNTIF('gpt-5.6-luna'!$B9:$AB9,"Passed on test")+COUNTIF('gpt-5.6-luna'!$B9:$AB9,"Failed on test")+COUNTIF('gpt-5.6-luna'!$B9:$AB9,"Runtime error") | E9: =IF(F9=$D9,"Passed on test",IF(H9>0,"Runtime error","Failed on test")) | F9: =COUNTIF('gpt-5.6-luna'!$B9:$AB9,"Passed on test") | G9: =COUNTIF('gpt-5.6-luna'!$B9:$AB9,"Failed on test") | H9: =COUNTIF('gpt-5.6-luna'!$B9:$AB9,"Runtime error") | I9: =IF(J9=$D9,"Passed on test",IF(L9>0,"Runtime error","Failed on test")) | J9: =COUNTIF('gpt-6-luna'!$B9:$AB9,"Passed on test") | K9: =COUNTIF('gpt-6-luna'!$B9:$AB9,"Failed on test") | L9: =COUNTIF('gpt-6-luna'!$B9:$AB9,"Runtime error") | M9: =IF(N9=$D9,"Passed on test",IF(P9>0,"Runtime error","Failed on test")) | N9: =COUNTIF('gpt-6-astra'!$B9:$AB9,"Passed on test") | O9: =COUNTIF('gpt-6-astra'!$B9:$AB9,"Failed on test") | P9: =COUNTIF('gpt-6-astra'!$B9:$AB9,"Runtime error") | Q9: =IF(R9=$D9,"Passed on test",IF(T9>0,"Runtime error","Failed on test")) | R9: =COUNTIF('gpt-6.1-sol'!$B9:$AB9,"Passed on test") | S9: =COUNTIF('gpt-6.1-sol'!$B9:$AB9,"Failed on test") | T9: =COUNTIF('gpt-6.1-sol'!$B9:$AB9,"Runtime error") | U9: =IF(V9=$D9,"Passed on test",IF(X9>0,"Runtime error","Failed on test")) | V9: =COUNTIF('claude-opus-5-5'!$B9:$AB9,"PASS") | W9: =COUNTIF('claude-opus-5-5'!$B9:$AB9,"FAIL") | X9: =COUNTIF('claude-opus-5-5'!$B9:$AB9,"ERROR") | Y9: =IF(Z9=$D9,"Passed on test",IF(AB9>0,"Runtime error","Failed on test")) | Z9: =COUNTIF('claude-sonnet-5-5'!$B9:$AB9,"PASS") | AA9: =COUNTIF('claude-sonnet-5-5'!$B9:$AB9,"FAIL") | AB9: =COUNTIF('claude-sonnet-5-5'!$B9:$AB9,"ERROR") | AC9: =IF(AD9=$D9,"Passed on test",IF(AF9>0,"Runtime error","Failed on test")) | AD9: =COUNTIF('claude-haiku-5-5'!$B9:$AB9,"PASS") | AE9: =COUNTIF('claude-haiku-5-5'!$B9:$AB9,"FAIL") | AF9: =COUNTIF('claude-haiku-5-5'!$B9:$AB9,"ERROR")
A10: 1 | B10: issue_096 | C10: Missing Qiskit / IPython config files | D10: =COUNTIF('gpt-5.6-luna'!$B10:$AB10,"Passed on test")+COUNTIF('gpt-5.6-luna'!$B10:$AB10,"Failed on test")+COUNTIF('gpt-5.6-luna'!$B10:$AB10,"Runtime error") | E10: =IF(F10=$D10,"Passed on test",IF(H10>0,"Runtime error","Failed on test")) | F10: =COUNTIF('gpt-5.6-luna'!$B10:$AB10,"Passed on test") | G10: =COUNTIF('gpt-5.6-luna'!$B10:$AB10,"Failed on test") | H10: =COUNTIF('gpt-5.6-luna'!$B10:$AB10,"Runtime error") | I10: =IF(J10=$D10,"Passed on test",IF(L10>0,"Runtime error","Failed on test")) | J10: =COUNTIF('gpt-6-luna'!$B10:$AB10,"Passed on test") | K10: =COUNTIF('gpt-6-luna'!$B10:$AB10,"Failed on test") | L10: =COUNTIF('gpt-6-luna'!$B10:$AB10,"Runtime error") | M10: =IF(N10=$D10,"Passed on test",IF(P10>0,"Runtime error","Failed on test")) | N10: =COUNTIF('gpt-6-astra'!$B10:$AB10,"Passed on test") | O10: =COUNTIF('gpt-6-astra'!$B10:$AB10,"Failed on test") | P10: =COUNTIF('gpt-6-astra'!$B10:$AB10,"Runtime error") | Q10: =IF(R10=$D10,"Passed on test",IF(T10>0,"Runtime error","Failed on test")) | R10: =COUNTIF('gpt-6.1-sol'!$B10:$AB10,"Passed on test") | S10: =COUNTIF('gpt-6.1-sol'!$B10:$AB10,"Failed on test") | T10: =COUNTIF('gpt-6.1-sol'!$B10:$AB10,"Runtime error") | U10: =IF(V10=$D10,"Passed on test",IF(X10>0,"Runtime error","Failed on test")) | V10: =COUNTIF('claude-opus-5-5'!$B10:$AB10,"PASS") | W10: =COUNTIF('claude-opus-5-5'!$B10:$AB10,"FAIL") | X10: =COUNTIF('claude-opus-5-5'!$B10:$AB10,"ERROR") | Y10: =IF(Z10=$D10,"Passed on test",IF(AB10>0,"Runtime error","Failed on test")) | Z10: =COUNTIF('claude-sonnet-5-5'!$B10:$AB10,"PASS") | AA10: =COUNTIF('claude-sonnet-5-5'!$B10:$AB10,"FAIL") | AB10: =COUNTIF('claude-sonnet-5-5'!$B10:$AB10,"ERROR") | AC10: =IF(AD10=$D10,"Passed on test",IF(AF10>0,"Runtime error","Failed on test")) | AD10: =COUNTIF('claude-haiku-5-5'!$B10:$AB10,"PASS") | AE10: =COUNTIF('claude-haiku-5-5'!$B10:$AB10,"FAIL") | AF10: =COUNTIF('claude-haiku-5-5'!$B10:$AB10,"ERROR")
A11: 2 | B11: issue_155 | C11: Partial trace over registers | D11: =COUNTIF('gpt-5.6-luna'!$B11:$AB11,"Passed on test")+COUNTIF('gpt-5.6-luna'!$B11:$AB11,"Failed on test")+COUNTIF('gpt-5.6-luna'!$B11:$AB11,"Runtime error") | E11: =IF(F11=$D11,"Passed on test",IF(H11>0,"Runtime error","Failed on test")) | F11: =COUNTIF('gpt-5.6-luna'!$B11:$AB11,"Passed on test") | G11: =COUNTIF('gpt-5.6-luna'!$B11:$AB11,"Failed on test") | H11: =COUNTIF('gpt-5.6-luna'!$B11:$AB11,"Runtime error") | I11: =IF(J11=$D11,"Passed on test",IF(L11>0,"Runtime error","Failed on test")) | J11: =COUNTIF('gpt-6-luna'!$B11:$AB11,"Passed on test") | K11: =COUNTIF('gpt-6-luna'!$B11:$AB11,"Failed on test") | L11: =COUNTIF('gpt-6-luna'!$B11:$AB11,"Runtime error") | M11: =IF(N11=$D11,"Passed on test",IF(P11>0,"Runtime error","Failed on test")) | N11: =COUNTIF('gpt-6-astra'!$B11:$AB11,"Passed on test") | O11: =COUNTIF('gpt-6-astra'!$B11:$AB11,"Failed on test") | P11: =COUNTIF('gpt-6-astra'!$B11:$AB11,"Runtime error") | Q11: =IF(R11=$D11,"Passed on test",IF(T11>0,"Runtime error","Failed on test")) | R11: =COUNTIF('gpt-6.1-sol'!$B11:$AB11,"Passed on test") | S11: =COUNTIF('gpt-6.1-sol'!$B11:$AB11,"Failed on test") | T11: =COUNTIF('gpt-6.1-sol'!$B11:$AB11,"Runtime error") | U11: =IF(V11=$D11,"Passed on test",IF(X11>0,"Runtime error","Failed on test")) | V11: =COUNTIF('claude-opus-5-5'!$B11:$AB11,"PASS") | W11: =COUNTIF('claude-opus-5-5'!$B11:$AB11,"FAIL") | X11: =COUNTIF('claude-opus-5-5'!$B11:$AB11,"ERROR") | Y11: =IF(Z11=$D11,"Passed on test",IF(AB11>0,"Runtime error","Failed on test")) | Z11: =COUNTIF('claude-sonnet-5-5'!$B11:$AB11,"PASS") | AA11: =COUNTIF('claude-sonnet-5-5'!$B11:$AB11,"FAIL") | AB11: =COUNTIF('claude-sonnet-5-5'!$B11:$AB11,"ERROR") | AC11: =IF(AD11=$D11,"Passed on test",IF(AF11>0,"Runtime error","Failed on test")) | AD11: =COUNTIF('claude-haiku-5-5'!$B11:$AB11,"PASS") | AE11: =COUNTIF('claude-haiku-5-5'!$B11:$AB11,"FAIL") | AF11: =COUNTIF('claude-haiku-5-5'!$B11:$AB11,"ERROR")
A12: 2 | B12: issue_157 | C12: Controlled initialize | D12: =COUNTIF('gpt-5.6-luna'!$B12:$AB12,"Passed on test")+COUNTIF('gpt-5.6-luna'!$B12:$AB12,"Failed on test")+COUNTIF('gpt-5.6-luna'!$B12:$AB12,"Runtime error") | E12: =IF(F12=$D12,"Passed on test",IF(H12>0,"Runtime error","Failed on test")) | F12: =COUNTIF('gpt-5.6-luna'!$B12:$AB12,"Passed on test") | G12: =COUNTIF('gpt-5.6-luna'!$B12:$AB12,"Failed on test") | H12: =COUNTIF('gpt-5.6-luna'!$B12:$AB12,"Runtime error") | I12: =IF(J12=$D12,"Passed on test",IF(L12>0,"Runtime error","Failed on test")) | J12: =COUNTIF('gpt-6-luna'!$B12:$AB12,"Passed on test") | K12: =COUNTIF('gpt-6-luna'!$B12:$AB12,"Failed on test") | L12: =COUNTIF('gpt-6-luna'!$B12:$AB12,"Runtime error") | M12: =IF(N12=$D12,"Passed on test",IF(P12>0,"Runtime error","Failed on test")) | N12: =COUNTIF('gpt-6-astra'!$B12:$AB12,"Passed on test") | O12: =COUNTIF('gpt-6-astra'!$B12:$AB12,"Failed on test") | P12: =COUNTIF('gpt-6-astra'!$B12:$AB12,"Runtime error") | Q12: =IF(R12=$D12,"Passed on test",IF(T12>0,"Runtime error","Failed on test")) | R12: =COUNTIF('gpt-6.1-sol'!$B12:$AB12,"Passed on test") | S12: =COUNTIF('gpt-6.1-sol'!$B12:$AB12,"Failed on test") | T12: =COUNTIF('gpt-6.1-sol'!$B12:$AB12,"Runtime error") | U12: =IF(V12=$D12,"Passed on test",IF(X12>0,"Runtime error","Failed on test")) | V12: =COUNTIF('claude-opus-5-5'!$B12:$AB12,"PASS") | W12: =COUNTIF('claude-opus-5-5'!$B12:$AB12,"FAIL") | X12: =COUNTIF('claude-opus-5-5'!$B12:$AB12,"ERROR") | Y12: =IF(Z12=$D12,"Passed on test",IF(AB12>0,"Runtime error","Failed on test")) | Z12: =COUNTIF('claude-sonnet-5-5'!$B12:$AB12,"PASS") | AA12: =COUNTIF('claude-sonnet-5-5'!$B12:$AB12,"FAIL") | AB12: =COUNTIF('claude-sonnet-5-5'!$B12:$AB12,"ERROR") | AC12: =IF(AD12=$D12,"Passed on test",IF(AF12>0,"Runtime error","Failed on test")) | AD12: =COUNTIF('claude-haiku-5-5'!$B12:$AB12,"PASS") | AE12: =COUNTIF('claude-haiku-5-5'!$B12:$AB12,"FAIL") | AF12: =COUNTIF('claude-haiku-5-5'!$B12:$AB12,"ERROR")
A13: 2 | B13: issue_174 | C13: Conditions on a classical register in OpenQASM 2 | D13: =COUNTIF('gpt-5.6-luna'!$B13:$AB13,"Passed on test")+COUNTIF('gpt-5.6-luna'!$B13:$AB13,"Failed on test")+COUNTIF('gpt-5.6-luna'!$B13:$AB13,"Runtime error") | E13: =IF(F13=$D13,"Passed on test",IF(H13>0,"Runtime error","Failed on test")) | F13: =COUNTIF('gpt-5.6-luna'!$B13:$AB13,"Passed on test") | G13: =COUNTIF('gpt-5.6-luna'!$B13:$AB13,"Failed on test") | H13: =COUNTIF('gpt-5.6-luna'!$B13:$AB13,"Runtime error") | I13: =IF(J13=$D13,"Passed on test",IF(L13>0,"Runtime error","Failed on test")) | J13: =COUNTIF('gpt-6-luna'!$B13:$AB13,"Passed on test") | K13: =COUNTIF('gpt-6-luna'!$B13:$AB13,"Failed on test") | L13: =COUNTIF('gpt-6-luna'!$B13:$AB13,"Runtime error") | M13: =IF(N13=$D13,"Passed on test",IF(P13>0,"Runtime error","Failed on test")) | N13: =COUNTIF('gpt-6-astra'!$B13:$AB13,"Passed on test") | O13: =COUNTIF('gpt-6-astra'!$B13:$AB13,"Failed on test") | P13: =COUNTIF('gpt-6-astra'!$B13:$AB13,"Runtime error") | Q13: =IF(R13=$D13,"Passed on test",IF(T13>0,"Runtime error","Failed on test")) | R13: =COUNTIF('gpt-6.1-sol'!$B13:$AB13,"Passed on test") | S13: =COUNTIF('gpt-6.1-sol'!$B13:$AB13,"Failed on test") | T13: =COUNTIF('gpt-6.1-sol'!$B13:$AB13,"Runtime error") | U13: =IF(V13=$D13,"Passed on test",IF(X13>0,"Runtime error","Failed on test")) | V13: =COUNTIF('claude-opus-5-5'!$B13:$AB13,"PASS") | W13: =COUNTIF('claude-opus-5-5'!$B13:$AB13,"FAIL") | X13: =COUNTIF('claude-opus-5-5'!$B13:$AB13,"ERROR") | Y13: =IF(Z13=$D13,"Passed on test",IF(AB13>0,"Runtime error","Failed on test")) | Z13: =COUNTIF('claude-sonnet-5-5'!$B13:$AB13,"PASS") | AA13: =COUNTIF('claude-sonnet-5-5'!$B13:$AB13,"FAIL") | AB13: =COUNTIF('claude-sonnet-5-5'!$B13:$AB13,"ERROR") | AC13: =IF(AD13=$D13,"Passed on test",IF(AF13>0,"Runtime error","Failed on test")) | AD13: =COUNTIF('claude-haiku-5-5'!$B13:$AB13,"PASS") | AE13: =COUNTIF('claude-haiku-5-5'!$B13:$AB13,"FAIL") | AF13: =COUNTIF('claude-haiku-5-5'!$B13:$AB13,"ERROR")
... A73: 8 | B73: issue_921 | C73: run_algorithm() inputs | D73: =COUNTIF('gpt-5.6-luna'!$B73:$AB73,"Passed on test")+COUNTIF('gpt-5.6-luna'!$B73:$AB73,"Failed on test")+COUNTIF('gpt-5.6-luna'!$B73:$AB73,"Runtime error") | E73: =IF(F73=$D73,"Passed on test",IF(H73>0,"Runtime error","Failed on test")) | F73: =COUNTIF('gpt-5.6-luna'!$B73:$AB73,"Passed on test") | G73: =COUNTIF('gpt-5.6-luna'!$B73:$AB73,"Failed on test") | H73: =COUNTIF('gpt-5.6-luna'!$B73:$AB73,"Runtime error") | I73: =IF(J73=$D73,"Passed on test",IF(L73>0,"Runtime error","Failed on test")) | J73: =COUNTIF('gpt-6-luna'!$B73:$AB73,"Passed on test") | K73: =COUNTIF('gpt-6-luna'!$B73:$AB73,"Failed on test") | L73: =COUNTIF('gpt-6-luna'!$B73:$AB73,"Runtime error") | M73: =IF(N73=$D73,"Passed on test",IF(P73>0,"Runtime error","Failed on test")) | N73: =COUNTIF('gpt-6-astra'!$B73:$AB73,"Passed on test") | O73: =COUNTIF('gpt-6-astra'!$B73:$AB73,"Failed on test") | P73: =COUNTIF('gpt-6-astra'!$B73:$AB73,"Runtime error") | Q73: =IF(R73=$D73,"Passed on test",IF(T73>0,"Runtime error","Failed on test")) | R73: =COUNTIF('gpt-6.1-sol'!$B73:$AB73,"Passed on test") | S73: =COUNTIF('gpt-6.1-sol'!$B73:$AB73,"Failed on test") | T73: =COUNTIF('gpt-6.1-sol'!$B73:$AB73,"Runtime error") | U73: =IF(V73=$D73,"Passed on test",IF(X73>0,"Runtime error","Failed on test")) | V73: =COUNTIF('claude-opus-5-5'!$B73:$AB73,"PASS") | W73: =COUNTIF('claude-opus-5-5'!$B73:$AB73,"FAIL") | X73: =COUNTIF('claude-opus-5-5'!$B73:$AB73,"ERROR") | Y73: =IF(Z73=$D73,"Passed on test",IF(AB73>0,"Runtime error","Failed on test")) | Z73: =COUNTIF('claude-sonnet-5-5'!$B73:$AB73,"PASS") | AA73: =COUNTIF('claude-sonnet-5-5'!$B73:$AB73,"FAIL") | AB73: =COUNTIF('claude-sonnet-5-5'!$B73:$AB73,"ERROR") | AC73: =IF(AD73=$D73,"Passed on test",IF(AF73>0,"Runtime error","Failed on test")) | AD73: =COUNTIF('claude-haiku-5-5'!$B73:$AB73,"PASS") | AE73: =COUNTIF('claude-haiku-5-5'!$B73:$AB73,"FAIL") | AF73: =COUNTIF('claude-haiku-5-5'!$B73:$AB73,"ERROR")

Sheet gpt-5.6-luna
A1: case_id | B1: 0.25.0 | C1: 0.25.1 | D1: 0.25.2 | E1: 0.25.3 | F1: 0.45.0 | G1: 0.45.1 | H1: 0.45.2 | I1: 0.45.3 | J1: 0.46.0 | K1: 0.46.1 | L1: 0.46.2 | M1: 0.46.3 | N1: 1.0.0 | O1: 1.0.1 | P1: 1.0.2 | Q1: 1.1.0 | R1: 1.1.1 | S1: 1.1.2 | T1: 1.2.0 | U1: 1.2.1 | V1: 1.2.2 | W1: 1.2.4 | X1: 2.0.0 | Y1: 2.2.0 | Z1: 2.3.0 | AA1: 2.4.0 | AB1: 2.5.0
A2: issue_009 | B2: NOT_TESTED | C2: NOT_TESTED | D2: NOT_TESTED | E2: NOT_TESTED | F2: Runtime error | G2: Runtime error | H2: Failed on test | I2: Failed on test | J2: Runtime error | K2: Runtime error | L2: Runtime error | M2: Runtime error | N2: NOT_TESTED | O2: NOT_TESTED | P2: NOT_TESTED | Q2: NOT_TESTED | R2: NOT_TESTED | S2: NOT_TESTED | T2: NOT_TESTED | U2: NOT_TESTED | V2: NOT_TESTED | W2: NOT_TESTED | X2: NOT_TESTED | Y2: NOT_TESTED | Z2: NOT_TESTED | AA2: NOT_TESTED | AB2: NOT_TESTED
A3: issue_021_se | B3: Runtime error | C3: Runtime error | D3: Runtime error | E3: Runtime error | F3: Runtime error | G3: Runtime error | H3: Runtime error | I3: Runtime error | J3: Runtime error | K3: Runtime error | L3: Runtime error | M3: Runtime error | N3: NOT_TESTED | O3: NOT_TESTED | P3: NOT_TESTED | Q3: NOT_TESTED | R3: NOT_TESTED | S3: NOT_TESTED | T3: NOT_TESTED | U3: NOT_TESTED | V3: NOT_TESTED | W3: NOT_TESTED | X3: NOT_TESTED | Y3: NOT_TESTED | Z3: NOT_TESTED | AA3: NOT_TESTED | AB3: NOT_TESTED
A4: issue_032_se | B4: Passed on test | C4: Passed on test | D4: Passed on test | E4: Passed on test | F4: NOT_TESTED | G4: NOT_TESTED | H4: NOT_TESTED | I4: NOT_TESTED | J4: NOT_TESTED | K4: NOT_TESTED | L4: NOT_TESTED | M4: NOT_TESTED | N4: NOT_TESTED | O4: NOT_TESTED | P4: NOT_TESTED | Q4: NOT_TESTED | R4: NOT_TESTED | S4: NOT_TESTED | T4: NOT_TESTED | U4: NOT_TESTED | V4: NOT_TESTED | W4: NOT_TESTED | X4: NOT_TESTED | Y4: NOT_TESTED | Z4: NOT_TESTED | AA4: NOT_TESTED | AB4: NOT_TESTED
A5: issue_034 | B5: NOT_TESTED | C5: NOT_TESTED | D5: NOT_TESTED | E5: NOT_TESTED | F5: NOT_TESTED | G5: NOT_TESTED | H5: NOT_TESTED | I5: NOT_TESTED | J5: NOT_TESTED | K5: NOT_TESTED | L5: NOT_TESTED | M5: NOT_TESTED | N5: Passed on test | O5: Passed on test | P5: Passed on test | Q5: Passed on test | R5: Passed on test | S5: Passed on test | T5: Passed on test | U5: Passed on test | V5: Passed on test | W5: Passed on test | X5: Passed on test | Y5: Passed on test | Z5: Passed on test | AA5: Passed on test | AB5: Passed on test
A6: issue_036 | B6: NOT_TESTED | C6: NOT_TESTED | D6: NOT_TESTED | E6: NOT_TESTED | F6: NOT_TESTED | G6: NOT_TESTED | H6: NOT_TESTED | I6: NOT_TESTED | J6: NOT_TESTED | K6: NOT_TESTED | L6: NOT_TESTED | M6: NOT_TESTED | N6: Passed on test | O6: Passed on test | P6: Passed on test | Q6: Passed on test | R6: Passed on test | S6: Passed on test | T6: Passed on test | U6: Passed on test | V6: Passed on test | W6: Passed on test | X6: Passed on test | Y6: Passed on test | Z6: Passed on test | AA6: Passed on test | AB6: Passed on test
A7: issue_058_se | B7: Passed on test | C7: Passed on test | D7: Passed on test | E7: Passed on test | F7: Passed on test | G7: Passed on test | H7: Passed on test | I7: Passed on test | J7: Passed on test | K7: Passed on test | L7: Passed on test | M7: Passed on test | N7: NOT_TESTED | O7: NOT_TESTED | P7: NOT_TESTED | Q7: NOT_TESTED | R7: NOT_TESTED | S7: NOT_TESTED | T7: NOT_TESTED | U7: NOT_TESTED | V7: NOT_TESTED | W7: NOT_TESTED | X7: NOT_TESTED | Y7: NOT_TESTED | Z7: NOT_TESTED | AA7: NOT_TESTED | AB7: NOT_TESTED
A8: issue_061 | B8: NOT_TESTED | C8: NOT_TESTED | D8: NOT_TESTED | E8: NOT_TESTED | F8: NOT_TESTED | G8: NOT_TESTED | H8: NOT_TESTED | I8: NOT_TESTED | J8: NOT_TESTED | K8: NOT_TESTED | L8: NOT_TESTED | M8: NOT_TESTED | N8: Passed on test | O8: Passed on test | P8: Passed on test | Q8: Passed on test | R8: Passed on test | S8: Passed on test | T8: Passed on test | U8: Passed on test | V8: Passed on test | W8: Passed on test | X8: Passed on test | Y8: Passed on test | Z8: Passed on test | AA8: Passed on test | AB8: Passed on test
A9: issue_072 | B9: Passed on test | C9: Passed on test | D9: Passed on test | E9: Passed on test | F9: NOT_TESTED | G9: NOT_TESTED | H9: NOT_TESTED | I9: NOT_TESTED | J9: NOT_TESTED | K9: NOT_TESTED | L9: NOT_TESTED | M9: NOT_TESTED | N9: NOT_TESTED | O9: NOT_TESTED | P9: NOT_TESTED | Q9: NOT_TESTED | R9: NOT_TESTED | S9: NOT_TESTED | T9: NOT_TESTED | U9: NOT_TESTED | V9: NOT_TESTED | W9: NOT_TESTED | X9: NOT_TESTED | Y9: NOT_TESTED | Z9: NOT_TESTED | AA9: NOT_TESTED | AB9: NOT_TESTED
A10: issue_096 | B10: Failed on test | C10: Failed on test | D10: Failed on test | E10: Failed on test | F10: Failed on test | G10: Failed on test | H10: Failed on test | I10: Failed on test | J10: Failed on test | K10: Failed on test | L10: Failed on test | M10: Failed on test | N10: Failed on test | O10: Failed on test | P10: Failed on test | Q10: Failed on test | R10: Failed on test | S10: Failed on test | T10: Failed on test | U10: Failed on test | V10: Failed on test | W10: Failed on test | X10: Failed on test | Y10: Failed on test | Z10: Failed on test | AA10: Failed on test | AB10: Failed on test
A11: issue_155 | B11: Passed on test | C11: Passed on test | D11: Passed on test | E11: Passed on test | F11: Passed on test | G11: Passed on test | H11: Passed on test | I11: Passed on test | J11: Passed on test | K11: Passed on test | L11: Passed on test | M11: Passed on test | N11: NOT_TESTED | O11: NOT_TESTED | P11: NOT_TESTED | Q11: NOT_TESTED | R11: NOT_TESTED | S11: NOT_TESTED | T11: NOT_TESTED | U11: NOT_TESTED | V11: NOT_TESTED | W11: NOT_TESTED | X11: NOT_TESTED | Y11: NOT_TESTED | Z11: NOT_TESTED | AA11: NOT_TESTED | AB11: NOT_TESTED
A12: issue_157 | B12: Runtime error | C12: Runtime error | D12: Runtime error | E12: Runtime error | F12: Passed on test | G12: Passed on test | H12: Passed on test | I12: Passed on test | J12: Passed on test | K12: Passed on test | L12: Passed on test | M12: Passed on test | N12: NOT_TESTED | O12: NOT_TESTED | P12: NOT_TESTED | Q12: NOT_TESTED | R12: NOT_TESTED | S12: NOT_TESTED | T12: NOT_TESTED | U12: NOT_TESTED | V12: NOT_TESTED | W12: NOT_TESTED | X12: NOT_TESTED | Y12: NOT_TESTED | Z12: NOT_TESTED | AA12: NOT_TESTED | AB12: NOT_TESTED
... A73: issue_921 | B73: Runtime error | C73: Runtime error | D73: Runtime error | E73: Runtime error | F73: NOT_TESTED | G73: NOT_TESTED | H73: NOT_TESTED | I73: NOT_TESTED | J73: NOT_TESTED | K73: NOT_TESTED | L73: NOT_TESTED | M73: NOT_TESTED | N73: NOT_TESTED | O73: NOT_TESTED | P73: NOT_TESTED | Q73: NOT_TESTED | R73: NOT_TESTED | S73: NOT_TESTED | T73: NOT_TESTED | U73: NOT_TESTED | V73: NOT_TESTED | W73: NOT_TESTED | X73: NOT_TESTED | Y73: NOT_TESTED | Z73: NOT_TESTED | AA73: NOT_TESTED | AB73: NOT_TESTED

Sheet gpt-6-luna
A1: case_id | B1: 0.25.0 | C1: 0.25.1 | D1: 0.25.2 | E1: 0.25.3 | F1: 0.45.0 | G1: 0.45.1 | H1: 0.45.2 | I1: 0.45.3 | J1: 0.46.0 | K1: 0.46.1 | L1: 0.46.2 | M1: 0.46.3 | N1: 1.0.0 | O1: 1.0.1 | P1: 1.0.2 | Q1: 1.1.0 | R1: 1.1.1 | S1: 1.1.2 | T1: 1.2.0 | U1: 1.2.1 | V1: 1.2.2 | W1: 1.2.4 | X1: 2.0.0 | Y1: 2.2.0 | Z1: 2.3.0 | AA1: 2.4.0 | AB1: 2.5.0
A2: issue_009 | B2: NOT_TESTED | C2: NOT_TESTED | D2: NOT_TESTED | E2: NOT_TESTED | F2: Passed on test | G2: Passed on test | H2: Passed on test | I2: Passed on test | J2: Passed on test | K2: Passed on test | L2: Passed on test | M2: Passed on test | N2: NOT_TESTED | O2: NOT_TESTED | P2: NOT_TESTED | Q2: NOT_TESTED | R2: NOT_TESTED | S2: NOT_TESTED | T2: NOT_TESTED | U2: NOT_TESTED | V2: NOT_TESTED | W2: NOT_TESTED | X2: NOT_TESTED | Y2: NOT_TESTED | Z2: NOT_TESTED | AA2: NOT_TESTED | AB2: NOT_TESTED
A3: issue_021_se | B3: Runtime error | C3: Runtime error | D3: Runtime error | E3: Runtime error | F3: Runtime error | G3: Runtime error | H3: Runtime error | I3: Runtime error | J3: Runtime error | K3: Runtime error | L3: Runtime error | M3: Runtime error | N3: NOT_TESTED | O3: NOT_TESTED | P3: NOT_TESTED | Q3: NOT_TESTED | R3: NOT_TESTED | S3: NOT_TESTED | T3: NOT_TESTED | U3: NOT_TESTED | V3: NOT_TESTED | W3: NOT_TESTED | X3: NOT_TESTED | Y3: NOT_TESTED | Z3: NOT_TESTED | AA3: NOT_TESTED | AB3: NOT_TESTED
A4: issue_032_se | B4: Passed on test | C4: Passed on test | D4: Passed on test | E4: Passed on test | F4: NOT_TESTED | G4: NOT_TESTED | H4: NOT_TESTED | I4: NOT_TESTED | J4: NOT_TESTED | K4: NOT_TESTED | L4: NOT_TESTED | M4: NOT_TESTED | N4: NOT_TESTED | O4: NOT_TESTED | P4: NOT_TESTED | Q4: NOT_TESTED | R4: NOT_TESTED | S4: NOT_TESTED | T4: NOT_TESTED | U4: NOT_TESTED | V4: NOT_TESTED | W4: NOT_TESTED | X4: NOT_TESTED | Y4: NOT_TESTED | Z4: NOT_TESTED | AA4: NOT_TESTED | AB4: NOT_TESTED
A5: issue_034 | B5: NOT_TESTED | C5: NOT_TESTED | D5: NOT_TESTED | E5: NOT_TESTED | F5: NOT_TESTED | G5: NOT_TESTED | H5: NOT_TESTED | I5: NOT_TESTED | J5: NOT_TESTED | K5: NOT_TESTED | L5: NOT_TESTED | M5: NOT_TESTED | N5: Passed on test | O5: Passed on test | P5: Passed on test | Q5: Passed on test | R5: Passed on test | S5: Passed on test | T5: Passed on test | U5: Passed on test | V5: Passed on test | W5: Passed on test | X5: Passed on test | Y5: Passed on test | Z5: Passed on test | AA5: Passed on test | AB5: Passed on test
A6: issue_036 | B6: NOT_TESTED | C6: NOT_TESTED | D6: NOT_TESTED | E6: NOT_TESTED | F6: NOT_TESTED | G6: NOT_TESTED | H6: NOT_TESTED | I6: NOT_TESTED | J6: NOT_TESTED | K6: NOT_TESTED | L6: NOT_TESTED | M6: NOT_TESTED | N6: Passed on test | O6: Passed on test | P6: Passed on test | Q6: Passed on test | R6: Passed on test | S6: Passed on test | T6: Passed on test | U6: Passed on test | V6: Passed on test | W6: Passed on test | X6: Passed on test | Y6: Passed on test | Z6: Passed on test | AA6: Passed on test | AB6: Passed on test
A7: issue_058_se | B7: Passed on test | C7: Passed on test | D7: Passed on test | E7: Passed on test | F7: Passed on test | G7: Passed on test | H7: Passed on test | I7: Passed on test | J7: Passed on test | K7: Passed on test | L7: Passed on test | M7: Passed on test | N7: NOT_TESTED | O7: NOT_TESTED | P7: NOT_TESTED | Q7: NOT_TESTED | R7: NOT_TESTED | S7: NOT_TESTED | T7: NOT_TESTED | U7: NOT_TESTED | V7: NOT_TESTED | W7: NOT_TESTED | X7: NOT_TESTED | Y7: NOT_TESTED | Z7: NOT_TESTED | AA7: NOT_TESTED | AB7: NOT_TESTED
A8: issue_061 | B8: NOT_TESTED | C8: NOT_TESTED | D8: NOT_TESTED | E8: NOT_TESTED | F8: NOT_TESTED | G8: NOT_TESTED | H8: NOT_TESTED | I8: NOT_TESTED | J8: NOT_TESTED | K8: NOT_TESTED | L8: NOT_TESTED | M8: NOT_TESTED | N8: Passed on test | O8: Passed on test | P8: Passed on test | Q8: Passed on test | R8: Passed on test | S8: Passed on test | T8: Passed on test | U8: Passed on test | V8: Passed on test | W8: Passed on test | X8: Passed on test | Y8: Passed on test | Z8: Passed on test | AA8: Passed on test | AB8: Passed on test
A9: issue_072 | B9: Passed on test | C9: Passed on test | D9: Passed on test | E9: Passed on test | F9: NOT_TESTED | G9: NOT_TESTED | H9: NOT_TESTED | I9: NOT_TESTED | J9: NOT_TESTED | K9: NOT_TESTED | L9: NOT_TESTED | M9: NOT_TESTED | N9: NOT_TESTED | O9: NOT_TESTED | P9: NOT_TESTED | Q9: NOT_TESTED | R9: NOT_TESTED | S9: NOT_TESTED | T9: NOT_TESTED | U9: NOT_TESTED | V9: NOT_TESTED | W9: NOT_TESTED | X9: NOT_TESTED | Y9: NOT_TESTED | Z9: NOT_TESTED | AA9: NOT_TESTED | AB9: NOT_TESTED
A10: issue_096 | B10: Failed on test | C10: Failed on test | D10: Failed on test | E10: Failed on test | F10: Failed on test | G10: Failed on test | H10: Failed on test | I10: Failed on test | J10: Failed on test | K10: Failed on test | L10: Failed on test | M10: Failed on test | N10: Failed on test | O10: Failed on test | P10: Failed on test | Q10: Failed on test | R10: Failed on test | S10: Failed on test | T10: Failed on test | U10: Failed on test | V10: Failed on test | W10: Failed on test | X10: Failed on test | Y10: Failed on test | Z10: Failed on test | AA10: Failed on test | AB10: Failed on test
