Workbook

Sheet Overview
A1: Batch | B1: Case | C1: Question | D1: Versions tested | E1: gpt-5.6-luna outcome | F1: gpt-5.6-luna passed on test | G1: gpt-5.6-luna failed on test | H1: gpt-5.6-luna runtime errors | I1: gpt-6-luna outcome | J1: gpt-6-luna passed on test | K1: gpt-6-luna failed on test | L1: gpt-6-luna runtime errors | M1: gpt-6-astra outcome | N1: gpt-6-astra passed on test | O1: gpt-6-astra failed on test | P1: gpt-6-astra runtime errors | Q1: gpt-6.1-sol outcome | R1: gpt-6.1-sol passed on test | S1: gpt-6.1-sol failed on test | T1: gpt-6.1-sol runtime errors | U1: Best model (most versions passed) | V1: Agreement | W1: Note
A2: 1 | B2: issue_009 | C2: CSP layout in the transpiler | D2: =COUNTIF('gpt-5.6-luna'!$B2:$AB2,"Passed on test")+COUNTIF('gpt-5.6-luna'!$B2:$AB2,"Failed on test")+COUNTIF('gpt-5.6-luna'!$B2:$AB2,"Runtime error") | E2: =IF(F2=$D2,"Passed on test",IF(H2>0,"Runtime error","Failed on test")) | F2: =COUNTIF('gpt-5.6-luna'!$B2:$AB2,"Passed on test") | G2: =COUNTIF('gpt-5.6-luna'!$B2:$AB2,"Failed on test") | H2: =COUNTIF('gpt-5.6-luna'!$B2:$AB2,"Runtime error") | I2: =IF(J2=$D2,"Passed on test",IF(L2>0,"Runtime error","Failed on test")) | J2: =COUNTIF('gpt-6-luna'!$B2:$AB2,"Passed on test") | K2: =COUNTIF('gpt-6-luna'!$B2:$AB2,"Failed on test") | L2: =COUNTIF('gpt-6-luna'!$B2:$AB2,"Runtime error") | M2: =IF(N2=$D2,"Passed on test",IF(P2>0,"Runtime error","Failed on test")) | N2: =COUNTIF('gpt-6-astra'!$B2:$AB2,"Passed on test") | O2: =COUNTIF('gpt-6-astra'!$B2:$AB2,"Failed on test") | P2: =COUNTIF('gpt-6-astra'!$B2:$AB2,"Runtime error") | Q2: =IF(R2=$D2,"Passed on test",IF(T2>0,"Runtime error","Failed on test")) | R2: =COUNTIF('gpt-6.1-sol'!$B2:$AB2,"Passed on test") | S2: =COUNTIF('gpt-6.1-sol'!$B2:$AB2,"Failed on test") | T2: =COUNTIF('gpt-6.1-sol'!$B2:$AB2,"Runtime error") | U2: =IF(MAX(F2,J2,N2,R2)=0,"None",IF(MIN(F2,J2,N2,R2)=MAX(F2,J2,N2,R2),"All four",_xlfn.TEXTJOIN(", ",TRUE,IF(F2=MAX(F2,J2,N2,R2),"gpt-5.6-luna",""),IF(J2=MAX(F2,J2,N2,R2),"gpt-6-luna",""),IF(N2=MAX(F2,J2,N2,R2),"gpt-6-astra",""),IF(R2=MAX(F2,J2,N2,R2),"gpt-6.1-sol","")))) | V2: =IF(MAX(F2,J2,N2,R2)<>MIN(F2,J2,N2,R2),"differ",IF(F2=$D2,"all_pass",IF(F2=0,"all_zero","same_partial"))) | W2: gpt-5.6-luna applied the CSPLayout result with ApplyLayout, which rejects a 3-qubit layout on a 5-qubit backend; the others pass it to transpile() as initial_layout
A3: 1 | B3: issue_021_se | C3: get_statevector() with a custom gate | D3: =COUNTIF('gpt-5.6-luna'!$B3:$AB3,"Passed on test")+COUNTIF('gpt-5.6-luna'!$B3:$AB3,"Failed on test")+COUNTIF('gpt-5.6-luna'!$B3:$AB3,"Runtime error") | E3: =IF(F3=$D3,"Passed on test",IF(H3>0,"Runtime error","Failed on test")) | F3: =COUNTIF('gpt-5.6-luna'!$B3:$AB3,"Passed on test") | G3: =COUNTIF('gpt-5.6-luna'!$B3:$AB3,"Failed on test") | H3: =COUNTIF('gpt-5.6-luna'!$B3:$AB3,"Runtime error") | I3: =IF(J3=$D3,"Passed on test",IF(L3>0,"Runtime error","Failed on test")) | J3: =COUNTIF('gpt-6-luna'!$B3:$AB3,"Passed on test") | K3: =COUNTIF('gpt-6-luna'!$B3:$AB3,"Failed on test") | L3: =COUNTIF('gpt-6-luna'!$B3:$AB3,"Runtime error") | M3: =IF(N3=$D3,"Passed on test",IF(P3>0,"Runtime error","Failed on test")) | N3: =COUNTIF('gpt-6-astra'!$B3:$AB3,"Passed on test") | O3: =COUNTIF('gpt-6-astra'!$B3:$AB3,"Failed on test") | P3: =COUNTIF('gpt-6-astra'!$B3:$AB3,"Runtime error") | Q3: =IF(R3=$D3,"Passed on test",IF(T3>0,"Runtime error","Failed on test")) | R3: =COUNTIF('gpt-6.1-sol'!$B3:$AB3,"Passed on test") | S3: =COUNTIF('gpt-6.1-sol'!$B3:$AB3,"Failed on test") | T3: =COUNTIF('gpt-6.1-sol'!$B3:$AB3,"Runtime error") | U3: =IF(MAX(F3,J3,N3,R3)=0,"None",IF(MIN(F3,J3,N3,R3)=MAX(F3,J3,N3,R3),"All four",_xlfn.TEXTJOIN(", ",TRUE,IF(F3=MAX(F3,J3,N3,R3),"gpt-5.6-luna",""),IF(J3=MAX(F3,J3,N3,R3),"gpt-6-luna",""),IF(N3=MAX(F3,J3,N3,R3),"gpt-6-astra",""),IF(R3=MAX(F3,J3,N3,R3),"gpt-6.1-sol","")))) | V3: =IF(MAX(F3,J3,N3,R3)<>MIN(F3,J3,N3,R3),"differ",IF(F3=$D3,"all_pass",IF(F3=0,"all_zero","same_partial"))) | W3: Both luna models used a one-level decompose(), which leaves unsupported instructions; gpt-6-astra and gpt-6.1-sol transpile() first
A4: 1 | B4: issue_032_se | C4: iSWAP in TwoLocal | D4: =COUNTIF('gpt-5.6-luna'!$B4:$AB4,"Passed on test")+COUNTIF('gpt-5.6-luna'!$B4:$AB4,"Failed on test")+COUNTIF('gpt-5.6-luna'!$B4:$AB4,"Runtime error") | E4: =IF(F4=$D4,"Passed on test",IF(H4>0,"Runtime error","Failed on test")) | F4: =COUNTIF('gpt-5.6-luna'!$B4:$AB4,"Passed on test") | G4: =COUNTIF('gpt-5.6-luna'!$B4:$AB4,"Failed on test") | H4: =COUNTIF('gpt-5.6-luna'!$B4:$AB4,"Runtime error") | I4: =IF(J4=$D4,"Passed on test",IF(L4>0,"Runtime error","Failed on test")) | J4: =COUNTIF('gpt-6-luna'!$B4:$AB4,"Passed on test") | K4: =COUNTIF('gpt-6-luna'!$B4:$AB4,"Failed on test") | L4: =COUNTIF('gpt-6-luna'!$B4:$AB4,"Runtime error") | M4: =IF(N4=$D4,"Passed on test",IF(P4>0,"Runtime error","Failed on test")) | N4: =COUNTIF('gpt-6-astra'!$B4:$AB4,"Passed on test") | O4: =COUNTIF('gpt-6-astra'!$B4:$AB4,"Failed on test") | P4: =COUNTIF('gpt-6-astra'!$B4:$AB4,"Runtime error") | Q4: =IF(R4=$D4,"Passed on test",IF(T4>0,"Runtime error","Failed on test")) | R4: =COUNTIF('gpt-6.1-sol'!$B4:$AB4,"Passed on test") | S4: =COUNTIF('gpt-6.1-sol'!$B4:$AB4,"Failed on test") | T4: =COUNTIF('gpt-6.1-sol'!$B4:$AB4,"Runtime error") | U4: =IF(MAX(F4,J4,N4,R4)=0,"None",IF(MIN(F4,J4,N4,R4)=MAX(F4,J4,N4,R4),"All four",_xlfn.TEXTJOIN(", ",TRUE,IF(F4=MAX(F4,J4,N4,R4),"gpt-5.6-luna",""),IF(J4=MAX(F4,J4,N4,R4),"gpt-6-luna",""),IF(N4=MAX(F4,J4,N4,R4),"gpt-6-astra",""),IF(R4=MAX(F4,J4,N4,R4),"gpt-6.1-sol","")))) | V4: =IF(MAX(F4,J4,N4,R4)<>MIN(F4,J4,N4,R4),"differ",IF(F4=$D4,"all_pass",IF(F4=0,"all_zero","same_partial"))) | W4: All four pass (iSwapGate() instead of the string 'iswap')
A5: 1 | B5: issue_034 | C5: Importing Aer | D5: =COUNTIF('gpt-5.6-luna'!$B5:$AB5,"Passed on test")+COUNTIF('gpt-5.6-luna'!$B5:$AB5,"Failed on test")+COUNTIF('gpt-5.6-luna'!$B5:$AB5,"Runtime error") | E5: =IF(F5=$D5,"Passed on test",IF(H5>0,"Runtime error","Failed on test")) | F5: =COUNTIF('gpt-5.6-luna'!$B5:$AB5,"Passed on test") | G5: =COUNTIF('gpt-5.6-luna'!$B5:$AB5,"Failed on test") | H5: =COUNTIF('gpt-5.6-luna'!$B5:$AB5,"Runtime error") | I5: =IF(J5=$D5,"Passed on test",IF(L5>0,"Runtime error","Failed on test")) | J5: =COUNTIF('gpt-6-luna'!$B5:$AB5,"Passed on test") | K5: =COUNTIF('gpt-6-luna'!$B5:$AB5,"Failed on test") | L5: =COUNTIF('gpt-6-luna'!$B5:$AB5,"Runtime error") | M5: =IF(N5=$D5,"Passed on test",IF(P5>0,"Runtime error","Failed on test")) | N5: =COUNTIF('gpt-6-astra'!$B5:$AB5,"Passed on test") | O5: =COUNTIF('gpt-6-astra'!$B5:$AB5,"Failed on test") | P5: =COUNTIF('gpt-6-astra'!$B5:$AB5,"Runtime error") | Q5: =IF(R5=$D5,"Passed on test",IF(T5>0,"Runtime error","Failed on test")) | R5: =COUNTIF('gpt-6.1-sol'!$B5:$AB5,"Passed on test") | S5: =COUNTIF('gpt-6.1-sol'!$B5:$AB5,"Failed on test") | T5: =COUNTIF('gpt-6.1-sol'!$B5:$AB5,"Runtime error") | U5: =IF(MAX(F5,J5,N5,R5)=0,"None",IF(MIN(F5,J5,N5,R5)=MAX(F5,J5,N5,R5),"All four",_xlfn.TEXTJOIN(", ",TRUE,IF(F5=MAX(F5,J5,N5,R5),"gpt-5.6-luna",""),IF(J5=MAX(F5,J5,N5,R5),"gpt-6-luna",""),IF(N5=MAX(F5,J5,N5,R5),"gpt-6-astra",""),IF(R5=MAX(F5,J5,N5,R5),"gpt-6.1-sol","")))) | V5: =IF(MAX(F5,J5,N5,R5)<>MIN(F5,J5,N5,R5),"differ",IF(F5=$D5,"all_pass",IF(F5=0,"all_zero","same_partial"))) | W5: All four pass (from qiskit_aer import Aer)
A6: 1 | B6: issue_036 | C6: Circuit to OpenQASM 2.0 | D6: =COUNTIF('gpt-5.6-luna'!$B6:$AB6,"Passed on test")+COUNTIF('gpt-5.6-luna'!$B6:$AB6,"Failed on test")+COUNTIF('gpt-5.6-luna'!$B6:$AB6,"Runtime error") | E6: =IF(F6=$D6,"Passed on test",IF(H6>0,"Runtime error","Failed on test")) | F6: =COUNTIF('gpt-5.6-luna'!$B6:$AB6,"Passed on test") | G6: =COUNTIF('gpt-5.6-luna'!$B6:$AB6,"Failed on test") | H6: =COUNTIF('gpt-5.6-luna'!$B6:$AB6,"Runtime error") | I6: =IF(J6=$D6,"Passed on test",IF(L6>0,"Runtime error","Failed on test")) | J6: =COUNTIF('gpt-6-luna'!$B6:$AB6,"Passed on test") | K6: =COUNTIF('gpt-6-luna'!$B6:$AB6,"Failed on test") | L6: =COUNTIF('gpt-6-luna'!$B6:$AB6,"Runtime error") | M6: =IF(N6=$D6,"Passed on test",IF(P6>0,"Runtime error","Failed on test")) | N6: =COUNTIF('gpt-6-astra'!$B6:$AB6,"Passed on test") | O6: =COUNTIF('gpt-6-astra'!$B6:$AB6,"Failed on test") | P6: =COUNTIF('gpt-6-astra'!$B6:$AB6,"Runtime error") | Q6: =IF(R6=$D6,"Passed on test",IF(T6>0,"Runtime error","Failed on test")) | R6: =COUNTIF('gpt-6.1-sol'!$B6:$AB6,"Passed on test") | S6: =COUNTIF('gpt-6.1-sol'!$B6:$AB6,"Failed on test") | T6: =COUNTIF('gpt-6.1-sol'!$B6:$AB6,"Runtime error") | U6: =IF(MAX(F6,J6,N6,R6)=0,"None",IF(MIN(F6,J6,N6,R6)=MAX(F6,J6,N6,R6),"All four",_xlfn.TEXTJOIN(", ",TRUE,IF(F6=MAX(F6,J6,N6,R6),"gpt-5.6-luna",""),IF(J6=MAX(F6,J6,N6,R6),"gpt-6-luna",""),IF(N6=MAX(F6,J6,N6,R6),"gpt-6-astra",""),IF(R6=MAX(F6,J6,N6,R6),"gpt-6.1-sol","")))) | V6: =IF(MAX(F6,J6,N6,R6)<>MIN(F6,J6,N6,R6),"differ",IF(F6=$D6,"all_pass",IF(F6=0,"all_zero","same_partial"))) | W6: All four pass (qiskit.qasm2.dumps(c) instead of the removed c.qasm())
A7: 1 | B7: issue_058_se | C7: "contains invalid instructions" | D7: =COUNTIF('gpt-5.6-luna'!$B7:$AB7,"Passed on test")+COUNTIF('gpt-5.6-luna'!$B7:$AB7,"Failed on test")+COUNTIF('gpt-5.6-luna'!$B7:$AB7,"Runtime error") | E7: =IF(F7=$D7,"Passed on test",IF(H7>0,"Runtime error","Failed on test")) | F7: =COUNTIF('gpt-5.6-luna'!$B7:$AB7,"Passed on test") | G7: =COUNTIF('gpt-5.6-luna'!$B7:$AB7,"Failed on test") | H7: =COUNTIF('gpt-5.6-luna'!$B7:$AB7,"Runtime error") | I7: =IF(J7=$D7,"Passed on test",IF(L7>0,"Runtime error","Failed on test")) | J7: =COUNTIF('gpt-6-luna'!$B7:$AB7,"Passed on test") | K7: =COUNTIF('gpt-6-luna'!$B7:$AB7,"Failed on test") | L7: =COUNTIF('gpt-6-luna'!$B7:$AB7,"Runtime error") | M7: =IF(N7=$D7,"Passed on test",IF(P7>0,"Runtime error","Failed on test")) | N7: =COUNTIF('gpt-6-astra'!$B7:$AB7,"Passed on test") | O7: =COUNTIF('gpt-6-astra'!$B7:$AB7,"Failed on test") | P7: =COUNTIF('gpt-6-astra'!$B7:$AB7,"Runtime error") | Q7: =IF(R7=$D7,"Passed on test",IF(T7>0,"Runtime error","Failed on test")) | R7: =COUNTIF('gpt-6.1-sol'!$B7:$AB7,"Passed on test") | S7: =COUNTIF('gpt-6.1-sol'!$B7:$AB7,"Failed on test") | T7: =COUNTIF('gpt-6.1-sol'!$B7:$AB7,"Runtime error") | U7: =IF(MAX(F7,J7,N7,R7)=0,"None",IF(MIN(F7,J7,N7,R7)=MAX(F7,J7,N7,R7),"All four",_xlfn.TEXTJOIN(", ",TRUE,IF(F7=MAX(F7,J7,N7,R7),"gpt-5.6-luna",""),IF(J7=MAX(F7,J7,N7,R7),"gpt-6-luna",""),IF(N7=MAX(F7,J7,N7,R7),"gpt-6-astra",""),IF(R7=MAX(F7,J7,N7,R7),"gpt-6.1-sol","")))) | V7: =IF(MAX(F7,J7,N7,R7)<>MIN(F7,J7,N7,R7),"differ",IF(F7=$D7,"all_pass",IF(F7=0,"all_zero","same_partial"))) | W7: All four pass (Transpiles the circuit for the backend before run())
A8: 1 | B8: issue_061 | C8: Deprecated Bit.register / Bit.index | D8: =COUNTIF('gpt-5.6-luna'!$B8:$AB8,"Passed on test")+COUNTIF('gpt-5.6-luna'!$B8:$AB8,"Failed on test")+COUNTIF('gpt-5.6-luna'!$B8:$AB8,"Runtime error") | E8: =IF(F8=$D8,"Passed on test",IF(H8>0,"Runtime error","Failed on test")) | F8: =COUNTIF('gpt-5.6-luna'!$B8:$AB8,"Passed on test") | G8: =COUNTIF('gpt-5.6-luna'!$B8:$AB8,"Failed on test") | H8: =COUNTIF('gpt-5.6-luna'!$B8:$AB8,"Runtime error") | I8: =IF(J8=$D8,"Passed on test",IF(L8>0,"Runtime error","Failed on test")) | J8: =COUNTIF('gpt-6-luna'!$B8:$AB8,"Passed on test") | K8: =COUNTIF('gpt-6-luna'!$B8:$AB8,"Failed on test") | L8: =COUNTIF('gpt-6-luna'!$B8:$AB8,"Runtime error") | M8: =IF(N8=$D8,"Passed on test",IF(P8>0,"Runtime error","Failed on test")) | N8: =COUNTIF('gpt-6-astra'!$B8:$AB8,"Passed on test") | O8: =COUNTIF('gpt-6-astra'!$B8:$AB8,"Failed on test") | P8: =COUNTIF('gpt-6-astra'!$B8:$AB8,"Runtime error") | Q8: =IF(R8=$D8,"Passed on test",IF(T8>0,"Runtime error","Failed on test")) | R8: =COUNTIF('gpt-6.1-sol'!$B8:$AB8,"Passed on test") | S8: =COUNTIF('gpt-6.1-sol'!$B8:$AB8,"Failed on test") | T8: =COUNTIF('gpt-6.1-sol'!$B8:$AB8,"Runtime error") | U8: =IF(MAX(F8,J8,N8,R8)=0,"None",IF(MIN(F8,J8,N8,R8)=MAX(F8,J8,N8,R8),"All four",_xlfn.TEXTJOIN(", ",TRUE,IF(F8=MAX(F8,J8,N8,R8),"gpt-5.6-luna",""),IF(J8=MAX(F8,J8,N8,R8),"gpt-6-luna",""),IF(N8=MAX(F8,J8,N8,R8),"gpt-6-astra",""),IF(R8=MAX(F8,J8,N8,R8),"gpt-6.1-sol","")))) | V8: =IF(MAX(F8,J8,N8,R8)<>MIN(F8,J8,N8,R8),"differ",IF(F8=$D8,"all_pass",IF(F8=0,"all_zero","same_partial"))) | W8: All four pass (qc.find_bit(qbit).registers[0])
A9: 1 | B9: issue_072 | C9: Duplicate qubit in a layout | D9: =COUNTIF('gpt-5.6-luna'!$B9:$AB9,"Passed on test")+COUNTIF('gpt-5.6-luna'!$B9:$AB9,"Failed on test")+COUNTIF('gpt-5.6-luna'!$B9:$AB9,"Runtime error") | E9: =IF(F9=$D9,"Passed on test",IF(H9>0,"Runtime error","Failed on test")) | F9: =COUNTIF('gpt-5.6-luna'!$B9:$AB9,"Passed on test") | G9: =COUNTIF('gpt-5.6-luna'!$B9:$AB9,"Failed on test") | H9: =COUNTIF('gpt-5.6-luna'!$B9:$AB9,"Runtime error") | I9: =IF(J9=$D9,"Passed on test",IF(L9>0,"Runtime error","Failed on test")) | J9: =COUNTIF('gpt-6-luna'!$B9:$AB9,"Passed on test") | K9: =COUNTIF('gpt-6-luna'!$B9:$AB9,"Failed on test") | L9: =COUNTIF('gpt-6-luna'!$B9:$AB9,"Runtime error") | M9: =IF(N9=$D9,"Passed on test",IF(P9>0,"Runtime error","Failed on test")) | N9: =COUNTIF('gpt-6-astra'!$B9:$AB9,"Passed on test") | O9: =COUNTIF('gpt-6-astra'!$B9:$AB9,"Failed on test") | P9: =COUNTIF('gpt-6-astra'!$B9:$AB9,"Runtime error") | Q9: =IF(R9=$D9,"Passed on test",IF(T9>0,"Runtime error","Failed on test")) | R9: =COUNTIF('gpt-6.1-sol'!$B9:$AB9,"Passed on test") | S9: =COUNTIF('gpt-6.1-sol'!$B9:$AB9,"Failed on test") | T9: =COUNTIF('gpt-6.1-sol'!$B9:$AB9,"Runtime error") | U9: =IF(MAX(F9,J9,N9,R9)=0,"None",IF(MIN(F9,J9,N9,R9)=MAX(F9,J9,N9,R9),"All four",_xlfn.TEXTJOIN(", ",TRUE,IF(F9=MAX(F9,J9,N9,R9),"gpt-5.6-luna",""),IF(J9=MAX(F9,J9,N9,R9),"gpt-6-luna",""),IF(N9=MAX(F9,J9,N9,R9),"gpt-6-astra",""),IF(R9=MAX(F9,J9,N9,R9),"gpt-6.1-sol","")))) | V9: =IF(MAX(F9,J9,N9,R9)<>MIN(F9,J9,N9,R9),"differ",IF(F9=$D9,"all_pass",IF(F9=0,"all_zero","same_partial"))) | W9: All four pass (Maps qreg[5] to the unused qubit 15)
A10: 1 | B10: issue_096 | C10: Missing Qiskit / IPython config files | D10: =COUNTIF('gpt-5.6-luna'!$B10:$AB10,"Passed on test")+COUNTIF('gpt-5.6-luna'!$B10:$AB10,"Failed on test")+COUNTIF('gpt-5.6-luna'!$B10:$AB10,"Runtime error") | E10: =IF(F10=$D10,"Passed on test",IF(H10>0,"Runtime error","Failed on test")) | F10: =COUNTIF('gpt-5.6-luna'!$B10:$AB10,"Passed on test") | G10: =COUNTIF('gpt-5.6-luna'!$B10:$AB10,"Failed on test") | H10: =COUNTIF('gpt-5.6-luna'!$B10:$AB10,"Runtime error") | I10: =IF(J10=$D10,"Passed on test",IF(L10>0,"Runtime error","Failed on test")) | J10: =COUNTIF('gpt-6-luna'!$B10:$AB10,"Passed on test") | K10: =COUNTIF('gpt-6-luna'!$B10:$AB10,"Failed on test") | L10: =COUNTIF('gpt-6-luna'!$B10:$AB10,"Runtime error") | M10: =IF(N10=$D10,"Passed on test",IF(P10>0,"Runtime error","Failed on test")) | N10: =COUNTIF('gpt-6-astra'!$B10:$AB10,"Passed on test") | O10: =COUNTIF('gpt-6-astra'!$B10:$AB10,"Failed on test") | P10: =COUNTIF('gpt-6-astra'!$B10:$AB10,"Runtime error") | Q10: =IF(R10=$D10,"Passed on test",IF(T10>0,"Runtime error","Failed on test")) | R10: =COUNTIF('gpt-6.1-sol'!$B10:$AB10,"Passed on test") | S10: =COUNTIF('gpt-6.1-sol'!$B10:$AB10,"Failed on test") | T10: =COUNTIF('gpt-6.1-sol'!$B10:$AB10,"Runtime error") | U10: =IF(MAX(F10,J10,N10,R10)=0,"None",IF(MIN(F10,J10,N10,R10)=MAX(F10,J10,N10,R10),"All four",_xlfn.TEXTJOIN(", ",TRUE,IF(F10=MAX(F10,J10,N10,R10),"gpt-5.6-luna",""),IF(J10=MAX(F10,J10,N10,R10),"gpt-6-luna",""),IF(N10=MAX(F10,J10,N10,R10),"gpt-6-astra",""),IF(R10=MAX(F10,J10,N10,R10),"gpt-6.1-sol","")))) | V10: =IF(MAX(F10,J10,N10,R10)<>MIN(F10,J10,N10,R10),"differ",IF(F10=$D10,"all_pass",IF(F10=0,"all_zero","same_partial"))) | W10: All create an empty config file, but not the [default] content and IPython file the test expects
A11: 2 | B11: issue_155 | C11: Partial trace over registers | D11: =COUNTIF('gpt-5.6-luna'!$B11:$AB11,"Passed on test")+COUNTIF('gpt-5.6-luna'!$B11:$AB11,"Failed on test")+COUNTIF('gpt-5.6-luna'!$B11:$AB11,"Runtime error") | E11: =IF(F11=$D11,"Passed on test",IF(H11>0,"Runtime error","Failed on test")) | F11: =COUNTIF('gpt-5.6-luna'!$B11:$AB11,"Passed on test") | G11: =COUNTIF('gpt-5.6-luna'!$B11:$AB11,"Failed on test") | H11: =COUNTIF('gpt-5.6-luna'!$B11:$AB11,"Runtime error") | I11: =IF(J11=$D11,"Passed on test",IF(L11>0,"Runtime error","Failed on test")) | J11: =COUNTIF('gpt-6-luna'!$B11:$AB11,"Passed on test") | K11: =COUNTIF('gpt-6-luna'!$B11:$AB11,"Failed on test") | L11: =COUNTIF('gpt-6-luna'!$B11:$AB11,"Runtime error") | M11: =IF(N11=$D11,"Passed on test",IF(P11>0,"Runtime error","Failed on test")) | N11: =COUNTIF('gpt-6-astra'!$B11:$AB11,"Passed on test") | O11: =COUNTIF('gpt-6-astra'!$B11:$AB11,"Failed on test") | P11: =COUNTIF('gpt-6-astra'!$B11:$AB11,"Runtime error") | Q11: =IF(R11=$D11,"Passed on test",IF(T11>0,"Runtime error","Failed on test")) | R11: =COUNTIF('gpt-6.1-sol'!$B11:$AB11,"Passed on test") | S11: =COUNTIF('gpt-6.1-sol'!$B11:$AB11,"Failed on test") | T11: =COUNTIF('gpt-6.1-sol'!$B11:$AB11,"Runtime error") | U11: =IF(MAX(F11,J11,N11,R11)=0,"None",IF(MIN(F11,J11,N11,R11)=MAX(F11,J11,N11,R11),"All four",_xlfn.TEXTJOIN(", ",TRUE,IF(F11=MAX(F11,J11,N11,R11),"gpt-5.6-luna",""),IF(J11=MAX(F11,J11,N11,R11),"gpt-6-luna",""),IF(N11=MAX(F11,J11,N11,R11),"gpt-6-astra",""),IF(R11=MAX(F11,J11,N11,R11),"gpt-6.1-sol","")))) | V11: =IF(MAX(F11,J11,N11,R11)<>MIN(F11,J11,N11,R11),"differ",IF(F11=$D11,"all_pass",IF(F11=0,"all_zero","same_partial"))) | W11: gpt-5.6-luna used qc.qubits.index(), which works on 0.25; the other three used find_bit(), which doesn't exist there
A12: 2 | B12: issue_157 | C12: Controlled initialize | D12: =COUNTIF('gpt-5.6-luna'!$B12:$AB12,"Passed on test")+COUNTIF('gpt-5.6-luna'!$B12:$AB12,"Failed on test")+COUNTIF('gpt-5.6-luna'!$B12:$AB12,"Runtime error") | E12: =IF(F12=$D12,"Passed on test",IF(H12>0,"Runtime error","Failed on test")) | F12: =COUNTIF('gpt-5.6-luna'!$B12:$AB12,"Passed on test") | G12: =COUNTIF('gpt-5.6-luna'!$B12:$AB12,"Failed on test") | H12: =COUNTIF('gpt-5.6-luna'!$B12:$AB12,"Runtime error") | I12: =IF(J12=$D12,"Passed on test",IF(L12>0,"Runtime error","Failed on test")) | J12: =COUNTIF('gpt-6-luna'!$B12:$AB12,"Passed on test") | K12: =COUNTIF('gpt-6-luna'!$B12:$AB12,"Failed on test") | L12: =COUNTIF('gpt-6-luna'!$B12:$AB12,"Runtime error") | M12: =IF(N12=$D12,"Passed on test",IF(P12>0,"Runtime error","Failed on test")) | N12: =COUNTIF('gpt-6-astra'!$B12:$AB12,"Passed on test") | O12: =COUNTIF('gpt-6-astra'!$B12:$AB12,"Failed on test") | P12: =COUNTIF('gpt-6-astra'!$B12:$AB12,"Runtime error") | Q12: =IF(R12=$D12,"Passed on test",IF(T12>0,"Runtime error","Failed on test")) | R12: =COUNTIF('gpt-6.1-sol'!$B12:$AB12,"Passed on test") | S12: =COUNTIF('gpt-6.1-sol'!$B12:$AB12,"Failed on test") | T12: =COUNTIF('gpt-6.1-sol'!$B12:$AB12,"Runtime error") | U12: =IF(MAX(F12,J12,N12,R12)=0,"None",IF(MIN(F12,J12,N12,R12)=MAX(F12,J12,N12,R12),"All four",_xlfn.TEXTJOIN(", ",TRUE,IF(F12=MAX(F12,J12,N12,R12),"gpt-5.6-luna",""),IF(J12=MAX(F12,J12,N12,R12),"gpt-6-luna",""),IF(N12=MAX(F12,J12,N12,R12),"gpt-6-astra",""),IF(R12=MAX(F12,J12,N12,R12),"gpt-6.1-sol","")))) | V12: =IF(MAX(F12,J12,N12,R12)<>MIN(F12,J12,N12,R12),"differ",IF(F12=$D12,"all_pass",IF(F12=0,"all_zero","same_partial"))) | W12: All four use prepare_state(), which doesn't exist in 0.25
A13: 2 | B13: issue_174 | C13: Conditions on a classical register in OpenQASM 2 | D13: =COUNTIF('gpt-5.6-luna'!$B13:$AB13,"Passed on test")+COUNTIF('gpt-5.6-luna'!$B13:$AB13,"Failed on test")+COUNTIF('gpt-5.6-luna'!$B13:$AB13,"Runtime error") | E13: =IF(F13=$D13,"Passed on test",IF(H13>0,"Runtime error","Failed on test")) | F13: =COUNTIF('gpt-5.6-luna'!$B13:$AB13,"Passed on test") | G13: =COUNTIF('gpt-5.6-luna'!$B13:$AB13,"Failed on test") | H13: =COUNTIF('gpt-5.6-luna'!$B13:$AB13,"Runtime error") | I13: =IF(J13=$D13,"Passed on test",IF(L13>0,"Runtime error","Failed on test")) | J13: =COUNTIF('gpt-6-luna'!$B13:$AB13,"Passed on test") | K13: =COUNTIF('gpt-6-luna'!$B13:$AB13,"Failed on test") | L13: =COUNTIF('gpt-6-luna'!$B13:$AB13,"Runtime error") | M13: =IF(N13=$D13,"Passed on test",IF(P13>0,"Runtime error","Failed on test")) | N13: =COUNTIF('gpt-6-astra'!$B13:$AB13,"Passed on test") | O13: =COUNTIF('gpt-6-astra'!$B13:$AB13,"Failed on test") | P13: =COUNTIF('gpt-6-astra'!$B13:$AB13,"Runtime error") | Q13: =IF(R13=$D13,"Passed on test",IF(T13>0,"Runtime error","Failed on test")) | R13: =COUNTIF('gpt-6.1-sol'!$B13:$AB13,"Passed on test") | S13: =COUNTIF('gpt-6.1-sol'!$B13:$AB13,"Failed on test") | T13: =COUNTIF('gpt-6.1-sol'!$B13:$AB13,"Runtime error") | U13: =IF(MAX(F13,J13,N13,R13)=0,"None",IF(MIN(F13,J13,N13,R13)=MAX(F13,J13,N13,R13),"All four",_xlfn.TEXTJOIN(", ",TRUE,IF(F13=MAX(F13,J13,N13,R13),"gpt-5.6-luna",""),IF(J13=MAX(F13,J13,N13,R13),"gpt-6-luna",""),IF(N13=MAX(F13,J13,N13,R13),"gpt-6-astra",""),IF(R13=MAX(F13,J13,N13,R13),"gpt-6.1-sol","")))) | V13: =IF(MAX(F13,J13,N13,R13)<>MIN(F13,J13,N13,R13),"differ",IF(F13=$D13,"all_pass",IF(F13=0,"all_zero","same_partial"))) | W13: Same QASM fix everywhere, but the luna fixes put the # FIX: comment inside the QASM string, which crashes the parser
... A73: 8 | B73: issue_921 | C73: run_algorithm() inputs | D73: =COUNTIF('gpt-5.6-luna'!$B73:$AB73,"Passed on test")+COUNTIF('gpt-5.6-luna'!$B73:$AB73,"Failed on test")+COUNTIF('gpt-5.6-luna'!$B73:$AB73,"Runtime error") | E73: =IF(F73=$D73,"Passed on test",IF(H73>0,"Runtime error","Failed on test")) | F73: =COUNTIF('gpt-5.6-luna'!$B73:$AB73,"Passed on test") | G73: =COUNTIF('gpt-5.6-luna'!$B73:$AB73,"Failed on test") | H73: =COUNTIF('gpt-5.6-luna'!$B73:$AB73,"Runtime error") | I73: =IF(J73=$D73,"Passed on test",IF(L73>0,"Runtime error","Failed on test")) | J73: =COUNTIF('gpt-6-luna'!$B73:$AB73,"Passed on test") | K73: =COUNTIF('gpt-6-luna'!$B73:$AB73,"Failed on test") | L73: =COUNTIF('gpt-6-luna'!$B73:$AB73,"Runtime error") | M73: =IF(N73=$D73,"Passed on test",IF(P73>0,"Runtime error","Failed on test")) | N73: =COUNTIF('gpt-6-astra'!$B73:$AB73,"Passed on test") | O73: =COUNTIF('gpt-6-astra'!$B73:$AB73,"Failed on test") | P73: =COUNTIF('gpt-6-astra'!$B73:$AB73,"Runtime error") | Q73: =IF(R73=$D73,"Passed on test",IF(T73>0,"Runtime error","Failed on test")) | R73: =COUNTIF('gpt-6.1-sol'!$B73:$AB73,"Passed on test") | S73: =COUNTIF('gpt-6.1-sol'!$B73:$AB73,"Failed on test") | T73: =COUNTIF('gpt-6.1-sol'!$B73:$AB73,"Runtime error") | U73: =IF(MAX(F73,J73,N73,R73)=0,"None",IF(MIN(F73,J73,N73,R73)=MAX(F73,J73,N73,R73),"All four",_xlfn.TEXTJOIN(", ",TRUE,IF(F73=MAX(F73,J73,N73,R73),"gpt-5.6-luna",""),IF(J73=MAX(F73,J73,N73,R73),"gpt-6-luna",""),IF(N73=MAX(F73,J73,N73,R73),"gpt-6-astra",""),IF(R73=MAX(F73,J73,N73,R73),"gpt-6.1-sol","")))) | V73: =IF(MAX(F73,J73,N73,R73)<>MIN(F73,J73,N73,R73),"differ",IF(F73=$D73,"all_pass",IF(F73=0,"all_zero","same_partial"))) | W73: All keep run_algorithm, which no longer exists (gpt-6-luna said "NO BUG")

Sheet Metrics
A1: LLM bug-repair results: the four GPT models on the same 72 cases (1000 case × version pairs)
A2: All numbers are formulas over the four model sheets (one status per case × version, same layout as each model's own Summary sheet) and the Overview sheet, except section 7, which compares the fix files. Timeouts (120 s) count as Runtime error. issue_096, issue_453, issue_497, issue_622, issue_769, issue_876, issue_877, issue_958 and issue_985 were rescored on 19 Oct 2026 using Nick's updated Part 2 test.py files from origin/main. issue_189, issue_671, issue_747, issue_775, issue_810, issue_886, issue_911, issue_944, issue_977, issue_994 and issue_1035 were rescored the same day on Nick's main test.py files. Timeouts (120 s) count as runtime errors.
A4: 1. Case × version pairs
A5: Result | B5: gpt-5.6-luna | C5: % | D5: gpt-6-luna | E5: % | F5: gpt-6-astra | G5: % | H5: gpt-6.1-sol | I5: %
A6: Passed on test | B6: =COUNTIF('gpt-5.6-luna'!$B$2:$AB$73,"Passed on test") | C6: =IF(B$9=0,0,B6/B$9) | D6: =COUNTIF('gpt-6-luna'!$B$2:$AB$73,"Passed on test") | E6: =IF(D$9=0,0,D6/D$9) | F6: =COUNTIF('gpt-6-astra'!$B$2:$AB$73,"Passed on test") | G6: =IF(F$9=0,0,F6/F$9) | H6: =COUNTIF('gpt-6.1-sol'!$B$2:$AB$73,"Passed on test") | I6: =IF(H$9=0,0,H6/H$9)
A7: Failed on test | B7: =COUNTIF('gpt-5.6-luna'!$B$2:$AB$73,"Failed on test") | C7: =IF(B$9=0,0,B7/B$9) | D7: =COUNTIF('gpt-6-luna'!$B$2:$AB$73,"Failed on test") | E7: =IF(D$9=0,0,D7/D$9) | F7: =COUNTIF('gpt-6-astra'!$B$2:$AB$73,"Failed on test") | G7: =IF(F$9=0,0,F7/F$9) | H7: =COUNTIF('gpt-6.1-sol'!$B$2:$AB$73,"Failed on test") | I7: =IF(H$9=0,0,H7/H$9)
A8: Runtime error | B8: =COUNTIF('gpt-5.6-luna'!$B$2:$AB$73,"Runtime error") | C8: =IF(B$9=0,0,B8/B$9) | D8: =COUNTIF('gpt-6-luna'!$B$2:$AB$73,"Runtime error") | E8: =IF(D$9=0,0,D8/D$9) | F8: =COUNTIF('gpt-6-astra'!$B$2:$AB$73,"Runtime error") | G8: =IF(F$9=0,0,F8/F$9) | H8: =COUNTIF('gpt-6.1-sol'!$B$2:$AB$73,"Runtime error") | I8: =IF(H$9=0,0,H8/H$9)
A9: Total tested | B9: =SUM(B6:B8) | C9: =SUM(C6:C8) | D9: =SUM(D6:D8) | E9: =SUM(E6:E8) | F9: =SUM(F6:F8) | G9: =SUM(G6:G8) | H9: =SUM(H6:H8) | I9: =SUM(I6:I8)
A10: Not tested (version not listed for that case) | B10: =COUNTIF('gpt-5.6-luna'!$B$2:$AB$73,"NOT_TESTED") | D10: =COUNTIF('gpt-6-luna'!$B$2:$AB$73,"NOT_TESTED") | F10: =COUNTIF('gpt-6-astra'!$B$2:$AB$73,"NOT_TESTED") | H10: =COUNTIF('gpt-6.1-sol'!$B$2:$AB$73,"NOT_TESTED")
A12: 2. Cases by outcome ("Passed on test" only if every version passed)
A13: Outcome | B13: gpt-5.6-luna | C13: % | D13: gpt-6-luna | E13: % | F13: gpt-6-astra | G13: % | H13: gpt-6.1-sol | I13: %
A14: Passed on test | B14: =COUNTIF(Overview!$E$2:$E$73,"Passed on test") | C14: =IF(B$17=0,0,B14/B$17) | D14: =COUNTIF(Overview!$I$2:$I$73,"Passed on test") | E14: =IF(D$17=0,0,D14/D$17) | F14: =COUNTIF(Overview!$M$2:$M$73,"Passed on test") | G14: =IF(F$17=0,0,F14/F$17) | H14: =COUNTIF(Overview!$Q$2:$Q$73,"Passed on test") | I14: =IF(H$17=0,0,H14/H$17)
A15: Failed on test | B15: =COUNTIF(Overview!$E$2:$E$73,"Failed on test") | C15: =IF(B$17=0,0,B15/B$17) | D15: =COUNTIF(Overview!$I$2:$I$73,"Failed on test") | E15: =IF(D$17=0,0,D15/D$17) | F15: =COUNTIF(Overview!$M$2:$M$73,"Failed on test") | G15: =IF(F$17=0,0,F15/F$17) | H15: =COUNTIF(Overview!$Q$2:$Q$73,"Failed on test") | I15: =IF(H$17=0,0,H15/H$17)
A16: Runtime error | B16: =COUNTIF(Overview!$E$2:$E$73,"Runtime error") | C16: =IF(B$17=0,0,B16/B$17) | D16: =COUNTIF(Overview!$I$2:$I$73,"Runtime error") | E16: =IF(D$17=0,0,D16/D$17) | F16: =COUNTIF(Overview!$M$2:$M$73,"Runtime error") | G16: =IF(F$17=0,0,F16/F$17) | H16: =COUNTIF(Overview!$Q$2:$Q$73,"Runtime error") | I16: =IF(H$17=0,0,H16/H$17)
A17: Total cases | B17: =SUM(B14:B16) | C17: =SUM(C14:C16) | D17: =SUM(D14:D16) | E17: =SUM(E14:E16) | F17: =SUM(F14:F16) | G17: =SUM(G14:G16) | H17: =SUM(H14:H16) | I17: =SUM(I14:I16)
A18: A case counts as "Runtime error" if any version crashed or timed out, otherwise "Failed on test".
A20: 3. Cases that passed on at least one version
A21: Measure | B21: gpt-5.6-luna | C21: % | D21: gpt-6-luna | E21: % | F21: gpt-6-astra | G21: % | H21: gpt-6.1-sol | I21: %
A22: Passed on at least one version | B22: =COUNTIF(Overview!$F$2:$F$73,">0") | C22: =IF(COUNTA(Overview!$B$2:$B$73)=0,0,B22/COUNTA(Overview!$B$2:$B$73)) | D22: =COUNTIF(Overview!$J$2:$J$73,">0") | E22: =IF(COUNTA(Overview!$B$2:$B$73)=0,0,D22/COUNTA(Overview!$B$2:$B$73)) | F22: =COUNTIF(Overview!$N$2:$N$73,">0") | G22: =IF(COUNTA(Overview!$B$2:$B$73)=0,0,F22/COUNTA(Overview!$B$2:$B$73)) | H22: =COUNTIF(Overview!$R$2:$R$73,">0") | I22: =IF(COUNTA(Overview!$B$2:$B$73)=0,0,H22/COUNTA(Overview!$B$2:$B$73))
A23: Passed on every version (as in section 2) | B23: =B14 | C23: =IF(COUNTA(Overview!$B$2:$B$73)=0,0,B23/COUNTA(Overview!$B$2:$B$73)) | D23: =D14 | E23: =IF(COUNTA(Overview!$B$2:$B$73)=0,0,D23/COUNTA(Overview!$B$2:$B$73)) | F23: =F14 | G23: =IF(COUNTA(Overview!$B$2:$B$73)=0,0,F23/COUNTA(Overview!$B$2:$B$73)) | H23: =H14 | I23: =IF(COUNTA(Overview!$B$2:$B$73)=0,0,H23/COUNTA(Overview!$B$2:$B$73))
A24: Passed on some but not all versions | B24: =B22-B23 | C24: =IF(COUNTA(Overview!$B$2:$B$73)=0,0,B24/COUNTA(Overview!$B$2:$B$73)) | D24: =D22-D23 | E24: =IF(COUNTA(Overview!$B$2:$B$73)=0,0,D24/COUNTA(Overview!$B$2:$B$73)) | F24: =F22-F23 | G24: =IF(COUNTA(Overview!$B$2:$B$73)=0,0,F24/COUNTA(Overview!$B$2:$B$73)) | H24: =H22-H23 | I24: =IF(COUNTA(Overview!$B$2:$B$73)=0,0,H24/COUNTA(Overview!$B$2:$B$73))
A25: Passed on no version | B25: =COUNTIF(Overview!$F$2:$F$73,0) | C25: =IF(COUNTA(Overview!$B$2:$B$73)=0,0,B25/COUNTA(Overview!$B$2:$B$73)) | D25: =COUNTIF(Overview!$J$2:$J$73,0) | E25: =IF(COUNTA(Overview!$B$2:$B$73)=0,0,D25/COUNTA(Overview!$B$2:$B$73)) | F25: =COUNTIF(Overview!$N$2:$N$73,0) | G25: =IF(COUNTA(Overview!$B$2:$B$73)=0,0,F25/COUNTA(Overview!$B$2:$B$73)) | H25: =COUNTIF(Overview!$R$2:$R$73,0) | I25: =IF(COUNTA(Overview!$B$2:$B$73)=0,0,H25/COUNTA(Overview!$B$2:$B$73))
A28: 4. By batch
A29: Batch | B29: Cases | C29: Pairs tested | D29: gpt-5.6-luna: Every version | E29: gpt-5.6-luna: ≥1 version | F29: gpt-5.6-luna: Pairs passed | G29: gpt-5.6-luna: Pairs % | H29: gpt-6-luna: Every version | I29: gpt-6-luna: ≥1 version | J29: gpt-6-luna: Pairs passed | K29: gpt-6-luna: Pairs % | L29: gpt-6-astra: Every version | M29: gpt-6-astra: ≥1 version | N29: gpt-6-astra: Pairs passed | O29: gpt-6-astra: Pairs % | P29: gpt-6.1-sol: Every version | Q29: gpt-6.1-sol: ≥1 version | R29: gpt-6.1-sol: Pairs passed | S29: gpt-6.1-sol: Pairs %
A30: 1 | B30: =COUNTIF(Overview!$A$2:$A$73,1) | C30: =SUMIF(Overview!$A$2:$A$73,1,Overview!$D$2:$D$73) | D30: =COUNTIFS(Overview!$A$2:$A$73,1,Overview!$E$2:$E$73,"Passed on test") | E30: =COUNTIFS(Overview!$A$2:$A$73,1,Overview!$F$2:$F$73,">0") | F30: =SUMIF(Overview!$A$2:$A$73,1,Overview!$F$2:$F$73) | G30: =IF($C30=0,0,F30/$C30) | H30: =COUNTIFS(Overview!$A$2:$A$73,1,Overview!$I$2:$I$73,"Passed on test") | I30: =COUNTIFS(Overview!$A$2:$A$73,1,Overview!$J$2:$J$73,">0") | J30: =SUMIF(Overview!$A$2:$A$73,1,Overview!$J$2:$J$73) | K30: =IF($C30=0,0,J30/$C30) | L30: =COUNTIFS(Overview!$A$2:$A$73,1,Overview!$M$2:$M$73,"Passed on test") | M30: =COUNTIFS(Overview!$A$2:$A$73,1,Overview!$N$2:$N$73,">0") | N30: =SUMIF(Overview!$A$2:$A$73,1,Overview!$N$2:$N$73) | O30: =IF($C30=0,0,N30/$C30) | P30: =COUNTIFS(Overview!$A$2:$A$73,1,Overview!$Q$2:$Q$73,"Passed on test") | Q30: =COUNTIFS(Overview!$A$2:$A$73,1,Overview!$R$2:$R$73,">0") | R30: =SUMIF(Overview!$A$2:$A$73,1,Overview!$R$2:$R$73) | S30: =IF($C30=0,0,R30/$C30)
A31: 2 | B31: =COUNTIF(Overview!$A$2:$A$73,2) | C31: =SUMIF(Overview!$A$2:$A$73,2,Overview!$D$2:$D$73) | D31: =COUNTIFS(Overview!$A$2:$A$73,2,Overview!$E$2:$E$73,"Passed on test") | E31: =COUNTIFS(Overview!$A$2:$A$73,2,Overview!$F$2:$F$73,">0") | F31: =SUMIF(Overview!$A$2:$A$73,2,Overview!$F$2:$F$73) | G31: =IF($C31=0,0,F31/$C31) | H31: =COUNTIFS(Overview!$A$2:$A$73,2,Overview!$I$2:$I$73,"Passed on test") | I31: =COUNTIFS(Overview!$A$2:$A$73,2,Overview!$J$2:$J$73,">0") | J31: =SUMIF(Overview!$A$2:$A$73,2,Overview!$J$2:$J$73) | K31: =IF($C31=0,0,J31/$C31) | L31: =COUNTIFS(Overview!$A$2:$A$73,2,Overview!$M$2:$M$73,"Passed on test") | M31: =COUNTIFS(Overview!$A$2:$A$73,2,Overview!$N$2:$N$73,">0") | N31: =SUMIF(Overview!$A$2:$A$73,2,Overview!$N$2:$N$73) | O31: =IF($C31=0,0,N31/$C31) | P31: =COUNTIFS(Overview!$A$2:$A$73,2,Overview!$Q$2:$Q$73,"Passed on test") | Q31: =COUNTIFS(Overview!$A$2:$A$73,2,Overview!$R$2:$R$73,">0") | R31: =SUMIF(Overview!$A$2:$A$73,2,Overview!$R$2:$R$73) | S31: =IF($C31=0,0,R31/$C31)
A32: 3 | B32: =COUNTIF(Overview!$A$2:$A$73,3) | C32: =SUMIF(Overview!$A$2:$A$73,3,Overview!$D$2:$D$73) | D32: =COUNTIFS(Overview!$A$2:$A$73,3,Overview!$E$2:$E$73,"Passed on test") | E32: =COUNTIFS(Overview!$A$2:$A$73,3,Overview!$F$2:$F$73,">0") | F32: =SUMIF(Overview!$A$2:$A$73,3,Overview!$F$2:$F$73) | G32: =IF($C32=0,0,F32/$C32) | H32: =COUNTIFS(Overview!$A$2:$A$73,3,Overview!$I$2:$I$73,"Passed on test") | I32: =COUNTIFS(Overview!$A$2:$A$73,3,Overview!$J$2:$J$73,">0") | J32: =SUMIF(Overview!$A$2:$A$73,3,Overview!$J$2:$J$73) | K32: =IF($C32=0,0,J32/$C32) | L32: =COUNTIFS(Overview!$A$2:$A$73,3,Overview!$M$2:$M$73,"Passed on test") | M32: =COUNTIFS(Overview!$A$2:$A$73,3,Overview!$N$2:$N$73,">0") | N32: =SUMIF(Overview!$A$2:$A$73,3,Overview!$N$2:$N$73) | O32: =IF($C32=0,0,N32/$C32) | P32: =COUNTIFS(Overview!$A$2:$A$73,3,Overview!$Q$2:$Q$73,"Passed on test") | Q32: =COUNTIFS(Overview!$A$2:$A$73,3,Overview!$R$2:$R$73,">0") | R32: =SUMIF(Overview!$A$2:$A$73,3,Overview!$R$2:$R$73) | S32: =IF($C32=0,0,R32/$C32)
A33: 4 | B33: =COUNTIF(Overview!$A$2:$A$73,4) | C33: =SUMIF(Overview!$A$2:$A$73,4,Overview!$D$2:$D$73) | D33: =COUNTIFS(Overview!$A$2:$A$73,4,Overview!$E$2:$E$73,"Passed on test") | E33: =COUNTIFS(Overview!$A$2:$A$73,4,Overview!$F$2:$F$73,">0") | F33: =SUMIF(Overview!$A$2:$A$73,4,Overview!$F$2:$F$73) | G33: =IF($C33=0,0,F33/$C33) | H33: =COUNTIFS(Overview!$A$2:$A$73,4,Overview!$I$2:$I$73,"Passed on test") | I33: =COUNTIFS(Overview!$A$2:$A$73,4,Overview!$J$2:$J$73,">0") | J33: =SUMIF(Overview!$A$2:$A$73,4,Overview!$J$2:$J$73) | K33: =IF($C33=0,0,J33/$C33) | L33: =COUNTIFS(Overview!$A$2:$A$73,4,Overview!$M$2:$M$73,"Passed on test") | M33: =COUNTIFS(Overview!$A$2:$A$73,4,Overview!$N$2:$N$73,">0") | N33: =SUMIF(Overview!$A$2:$A$73,4,Overview!$N$2:$N$73) | O33: =IF($C33=0,0,N33/$C33) | P33: =COUNTIFS(Overview!$A$2:$A$73,4,Overview!$Q$2:$Q$73,"Passed on test") | Q33: =COUNTIFS(Overview!$A$2:$A$73,4,Overview!$R$2:$R$73,">0") | R33: =SUMIF(Overview!$A$2:$A$73,4,Overview!$R$2:$R$73) | S33: =IF($C33=0,0,R33/$C33)
A34: 5 | B34: =COUNTIF(Overview!$A$2:$A$73,5) | C34: =SUMIF(Overview!$A$2:$A$73,5,Overview!$D$2:$D$73) | D34: =COUNTIFS(Overview!$A$2:$A$73,5,Overview!$E$2:$E$73,"Passed on test") | E34: =COUNTIFS(Overview!$A$2:$A$73,5,Overview!$F$2:$F$73,">0") | F34: =SUMIF(Overview!$A$2:$A$73,5,Overview!$F$2:$F$73) | G34: =IF($C34=0,0,F34/$C34) | H34: =COUNTIFS(Overview!$A$2:$A$73,5,Overview!$I$2:$I$73,"Passed on test") | I34: =COUNTIFS(Overview!$A$2:$A$73,5,Overview!$J$2:$J$73,">0") | J34: =SUMIF(Overview!$A$2:$A$73,5,Overview!$J$2:$J$73) | K34: =IF($C34=0,0,J34/$C34) | L34: =COUNTIFS(Overview!$A$2:$A$73,5,Overview!$M$2:$M$73,"Passed on test") | M34: =COUNTIFS(Overview!$A$2:$A$73,5,Overview!$N$2:$N$73,">0") | N34: =SUMIF(Overview!$A$2:$A$73,5,Overview!$N$2:$N$73) | O34: =IF($C34=0,0,N34/$C34) | P34: =COUNTIFS(Overview!$A$2:$A$73,5,Overview!$Q$2:$Q$73,"Passed on test") | Q34: =COUNTIFS(Overview!$A$2:$A$73,5,Overview!$R$2:$R$73,">0") | R34: =SUMIF(Overview!$A$2:$A$73,5,Overview!$R$2:$R$73) | S34: =IF($C34=0,0,R34/$C34)
A35: 6 | B35: =COUNTIF(Overview!$A$2:$A$73,6) | C35: =SUMIF(Overview!$A$2:$A$73,6,Overview!$D$2:$D$73) | D35: =COUNTIFS(Overview!$A$2:$A$73,6,Overview!$E$2:$E$73,"Passed on test") | E35: =COUNTIFS(Overview!$A$2:$A$73,6,Overview!$F$2:$F$73,">0") | F35: =SUMIF(Overview!$A$2:$A$73,6,Overview!$F$2:$F$73) | G35: =IF($C35=0,0,F35/$C35) | H35: =COUNTIFS(Overview!$A$2:$A$73,6,Overview!$I$2:$I$73,"Passed on test") | I35: =COUNTIFS(Overview!$A$2:$A$73,6,Overview!$J$2:$J$73,">0") | J35: =SUMIF(Overview!$A$2:$A$73,6,Overview!$J$2:$J$73) | K35: =IF($C35=0,0,J35/$C35) | L35: =COUNTIFS(Overview!$A$2:$A$73,6,Overview!$M$2:$M$73,"Passed on test") | M35: =COUNTIFS(Overview!$A$2:$A$73,6,Overview!$N$2:$N$73,">0") | N35: =SUMIF(Overview!$A$2:$A$73,6,Overview!$N$2:$N$73) | O35: =IF($C35=0,0,N35/$C35) | P35: =COUNTIFS(Overview!$A$2:$A$73,6,Overview!$Q$2:$Q$73,"Passed on test") | Q35: =COUNTIFS(Overview!$A$2:$A$73,6,Overview!$R$2:$R$73,">0") | R35: =SUMIF(Overview!$A$2:$A$73,6,Overview!$R$2:$R$73) | S35: =IF($C35=0,0,R35/$C35)
A36: 7 | B36: =COUNTIF(Overview!$A$2:$A$73,7) | C36: =SUMIF(Overview!$A$2:$A$73,7,Overview!$D$2:$D$73) | D36: =COUNTIFS(Overview!$A$2:$A$73,7,Overview!$E$2:$E$73,"Passed on test") | E36: =COUNTIFS(Overview!$A$2:$A$73,7,Overview!$F$2:$F$73,">0") | F36: =SUMIF(Overview!$A$2:$A$73,7,Overview!$F$2:$F$73) | G36: =IF($C36=0,0,F36/$C36) | H36: =COUNTIFS(Overview!$A$2:$A$73,7,Overview!$I$2:$I$73,"Passed on test") | I36: =COUNTIFS(Overview!$A$2:$A$73,7,Overview!$J$2:$J$73,">0") | J36: =SUMIF(Overview!$A$2:$A$73,7,Overview!$J$2:$J$73) | K36: =IF($C36=0,0,J36/$C36) | L36: =COUNTIFS(Overview!$A$2:$A$73,7,Overview!$M$2:$M$73,"Passed on test") | M36: =COUNTIFS(Overview!$A$2:$A$73,7,Overview!$N$2:$N$73,">0") | N36: =SUMIF(Overview!$A$2:$A$73,7,Overview!$N$2:$N$73) | O36: =IF($C36=0,0,N36/$C36) | P36: =COUNTIFS(Overview!$A$2:$A$73,7,Overview!$Q$2:$Q$73,"Passed on test") | Q36: =COUNTIFS(Overview!$A$2:$A$73,7,Overview!$R$2:$R$73,">0") | R36: =SUMIF(Overview!$A$2:$A$73,7,Overview!$R$2:$R$73) | S36: =IF($C36=0,0,R36/$C36)
A37: 8 | B37: =COUNTIF(Overview!$A$2:$A$73,8) | C37: =SUMIF(Overview!$A$2:$A$73,8,Overview!$D$2:$D$73) | D37: =COUNTIFS(Overview!$A$2:$A$73,8,Overview!$E$2:$E$73,"Passed on test") | E37: =COUNTIFS(Overview!$A$2:$A$73,8,Overview!$F$2:$F$73,">0") | F37: =SUMIF(Overview!$A$2:$A$73,8,Overview!$F$2:$F$73) | G37: =IF($C37=0,0,F37/$C37) | H37: =COUNTIFS(Overview!$A$2:$A$73,8,Overview!$I$2:$I$73,"Passed on test") | I37: =COUNTIFS(Overview!$A$2:$A$73,8,Overview!$J$2:$J$73,">0") | J37: =SUMIF(Overview!$A$2:$A$73,8,Overview!$J$2:$J$73) | K37: =IF($C37=0,0,J37/$C37) | L37: =COUNTIFS(Overview!$A$2:$A$73,8,Overview!$M$2:$M$73,"Passed on test") | M37: =COUNTIFS(Overview!$A$2:$A$73,8,Overview!$N$2:$N$73,">0") | N37: =SUMIF(Overview!$A$2:$A$73,8,Overview!$N$2:$N$73) | O37: =IF($C37=0,0,N37/$C37) | P37: =COUNTIFS(Overview!$A$2:$A$73,8,Overview!$Q$2:$Q$73,"Passed on test") | Q37: =COUNTIFS(Overview!$A$2:$A$73,8,Overview!$R$2:$R$73,">0") | R37: =SUMIF(Overview!$A$2:$A$73,8,Overview!$R$2:$R$73) | S37: =IF($C37=0,0,R37/$C37)
A38: Total | B38: =COUNTA(Overview!$B$2:$B$73) | C38: =SUM(Overview!$D$2:$D$73) | D38: =COUNTIF(Overview!$E$2:$E$73,"Passed on test") | E38: =COUNTIF(Overview!$F$2:$F$73,">0") | F38: =SUM(Overview!$F$2:$F$73) | G38: =IF($C38=0,0,F38/$C38) | H38: =COUNTIF(Overview!$I$2:$I$73,"Passed on test") | I38: =COUNTIF(Overview!$J$2:$J$73,">0") | J38: =SUM(Overview!$J$2:$J$73) | K38: =IF($C38=0,0,J38/$C38) | L38: =COUNTIF(Overview!$M$2:$M$73,"Passed on test") | M38: =COUNTIF(Overview!$N$2:$N$73,">0") | N38: =SUM(Overview!$N$2:$N$73) | O38: =IF($C38=0,0,N38/$C38) | P38: =COUNTIF(Overview!$Q$2:$Q$73,"Passed on test") | Q38: =COUNTIF(Overview!$R$2:$R$73,">0") | R38: =SUM(Overview!$R$2:$R$73) | S38: =IF($C38=0,0,R38/$C38)
A41: 5. Head to head: cases where the row model passed more versions than the column model
A42: Row model \ column model | B42: gpt-5.6-luna | C42: gpt-6-luna | D42: gpt-6-astra | E42: gpt-6.1-sol
A43: gpt-5.6-luna | B43: - | C43: =SUMPRODUCT(--(Overview!$F$2:$F$73>Overview!$J$2:$J$73)) | D43: =SUMPRODUCT(--(Overview!$F$2:$F$73>Overview!$N$2:$N$73)) | E43: =SUMPRODUCT(--(Overview!$F$2:$F$73>Overview!$R$2:$R$73))
A44: gpt-6-luna | B44: =SUMPRODUCT(--(Overview!$J$2:$J$73>Overview!$F$2:$F$73)) | C44: - | D44: =SUMPRODUCT(--(Overview!$J$2:$J$73>Overview!$N$2:$N$73)) | E44: =SUMPRODUCT(--(Overview!$J$2:$J$73>Overview!$R$2:$R$73))
A45: gpt-6-astra | B45: =SUMPRODUCT(--(Overview!$N$2:$N$73>Overview!$F$2:$F$73)) | C45: =SUMPRODUCT(--(Overview!$N$2:$N$73>Overview!$J$2:$J$73)) | D45: - | E45: =SUMPRODUCT(--(Overview!$N$2:$N$73>Overview!$R$2:$R$73))
A46: gpt-6.1-sol | B46: =SUMPRODUCT(--(Overview!$R$2:$R$73>Overview!$F$2:$F$73)) | C46: =SUMPRODUCT(--(Overview!$R$2:$R$73>Overview!$J$2:$J$73)) | D46: =SUMPRODUCT(--(Overview!$R$2:$R$73>Overview!$N$2:$N$73)) | E46: -
A49: 6. Agreement: did the four GPT models get the same score on a case?
...

Sheet gpt-5.6-luna
A1: case_id | B1: 0.25.0 | C1: 0.25.1 | D1: 0.25.2 | E1: 0.25.3 | F1: 0.45.0 | G1: 0.45.1 | H1: 0.45.2 | I1: 0.45.3 | J1: 0.46.0 | K1: 0.46.1 | L1: 0.46.2 | M1: 0.46.3 | N1: 1.0.0 | O1: 1.0.1 | P1: 1.0.2 | Q1: 1.1.0 | R1: 1.1.1 | S1: 1.1.2 | T1: 1.2.0 | U1: 1.2.1 | V1: 1.2.2 | W1: 1.2.4 | X1: 2.0.0 | Y1: 2.2.0 | Z1: 2.3.0 | AA1: 2.4.0 | AB1: 2.5.0
A2: issue_009 | B2: NOT_TESTED | C2: NOT_TESTED | D2: NOT_TESTED | E2: NOT_TESTED | F2: Runtime error | G2: Runtime error | H2: Failed on test | I2: Failed on test | J2: Runtime error | K2: Runtime error | L2: Runtime error | M2: Runtime error | N2: NOT_TESTED | O2: NOT_TESTED | P2: NOT_TESTED | Q2: NOT_TESTED | R2: NOT_TESTED | S2: NOT_TESTED | T2: NOT_TESTED | U2: NOT_TESTED | V2: NOT_TESTED | W2: NOT_TESTED | X2: NOT_TESTED | Y2: NOT_TESTED | Z2: NOT_TESTED | AA2: NOT_TESTED | AB2: NOT_TESTED
A3: issue_021_se | B3: Runtime error | C3: Runtime error | D3: Runtime error | E3: Runtime error | F3: Runtime error | G3: Runtime error | H3: Runtime error | I3: Runtime error | J3: Runtime error | K3: Runtime error | L3: Runtime error | M3: Runtime error | N3: NOT_TESTED | O3: NOT_TESTED | P3: NOT_TESTED | Q3: NOT_TESTED | R3: NOT_TESTED | S3: NOT_TESTED | T3: NOT_TESTED | U3: NOT_TESTED | V3: NOT_TESTED | W3: NOT_TESTED | X3: NOT_TESTED | Y3: NOT_TESTED | Z3: NOT_TESTED | AA3: NOT_TESTED | AB3: NOT_TESTED
A4: issue_032_se | B4: Passed on test | C4: Passed on test | D4: Passed on test | E4: Passed on test | F4: NOT_TESTED | G4: NOT_TESTED | H4: NOT_TESTED | I4: NOT_TESTED | J4: NOT_TESTED | K4: NOT_TESTED | L4: NOT_TESTED | M4: NOT_TESTED | N4: NOT_TESTED | O4: NOT_TESTED | P4: NOT_TESTED | Q4: NOT_TESTED | R4: NOT_TESTED | S4: NOT_TESTED | T4: NOT_TESTED | U4: NOT_TESTED | V4: NOT_TESTED | W4: NOT_TESTED | X4: NOT_TESTED | Y4: NOT_TESTED | Z4: NOT_TESTED | AA4: NOT_TESTED | AB4: NOT_TESTED
A5: issue_034 | B5: NOT_TESTED | C5: NOT_TESTED | D5: NOT_TESTED | E5: NOT_TESTED | F5: NOT_TESTED | G5: NOT_TESTED | H5: NOT_TESTED | I5: NOT_TESTED | J5: NOT_TESTED | K5: NOT_TESTED | L5: NOT_TESTED | M5: NOT_TESTED | N5: Passed on test | O5: Passed on test | P5: Passed on test | Q5: Passed on test | R5: Passed on test | S5: Passed on test | T5: Passed on test | U5: Passed on test | V5: Passed on test | W5: Passed on test | X5: Passed on test | Y5: Passed on test | Z5: Passed on test | AA5: Passed on test | AB5: Passed on test
A6: issue_036 | B6: NOT_TESTED | C6: NOT_TESTED | D6: NOT_TESTED | E6: NOT_TESTED | F6: NOT_TESTED | G6: NOT_TESTED | H6: NOT_TESTED | I6: NOT_TESTED | J6: NOT_TESTED | K6: NOT_TESTED | L6: NOT_TESTED | M6: NOT_TESTED | N6: Passed on test | O6: Passed on test | P6: Passed on test | Q6: Passed on test | R6: Passed on test | S6: Passed on test | T6: Passed on test | U6: Passed on test | V6: Passed on test | W6: Passed on test | X6: Passed on test | Y6: Passed on test | Z6: Passed on test | AA6: Passed on test | AB6: Passed on test
A7: issue_058_se | B7: Passed on test | C7: Passed on test | D7: Passed on test | E7: Passed on test | F7: Passed on test | G7: Passed on test | H7: Passed on test | I7: Passed on test | J7: Passed on test | K7: Passed on test | L7: Passed on test | M7: Passed on test | N7: NOT_TESTED | O7: NOT_TESTED | P7: NOT_TESTED | Q7: NOT_TESTED | R7: NOT_TESTED | S7: NOT_TESTED | T7: NOT_TESTED | U7: NOT_TESTED | V7: NOT_TESTED | W7: NOT_TESTED | X7: NOT_TESTED | Y7: NOT_TESTED | Z7: NOT_TESTED | AA7: NOT_TESTED | AB7: NOT_TESTED
A8: issue_061 | B8: NOT_TESTED | C8: NOT_TESTED | D8: NOT_TESTED | E8: NOT_TESTED | F8: NOT_TESTED | G8: NOT_TESTED | H8: NOT_TESTED | I8: NOT_TESTED | J8: NOT_TESTED | K8: NOT_TESTED | L8: NOT_TESTED | M8: NOT_TESTED | N8: Passed on test | O8: Passed on test | P8: Passed on test | Q8: Passed on test | R8: Passed on test | S8: Passed on test | T8: Passed on test | U8: Passed on test | V8: Passed on test | W8: Passed on test | X8: Passed on test | Y8: Passed on test | Z8: Passed on test | AA8: Passed on test | AB8: Passed on test
A9: issue_072 | B9: Passed on test | C9: Passed on test | D9: Passed on test | E9: Passed on test | F9: NOT_TESTED | G9: NOT_TESTED | H9: NOT_TESTED | I9: NOT_TESTED | J9: NOT_TESTED | K9: NOT_TESTED | L9: NOT_TESTED | M9: NOT_TESTED | N9: NOT_TESTED | O9: NOT_TESTED | P9: NOT_TESTED | Q9: NOT_TESTED | R9: NOT_TESTED | S9: NOT_TESTED | T9: NOT_TESTED | U9: NOT_TESTED | V9: NOT_TESTED | W9: NOT_TESTED | X9: NOT_TESTED | Y9: NOT_TESTED | Z9: NOT_TESTED | AA9: NOT_TESTED | AB9: NOT_TESTED
A10: issue_096 | B10: Failed on test | C10: Failed on test | D10: Failed on test | E10: Failed on test | F10: Failed on test | G10: Failed on test | H10: Failed on test | I10: Failed on test | J10: Failed on test | K10: Failed on test | L10: Failed on test | M10: Failed on test | N10: Failed on test | O10: Failed on test | P10: Failed on test | Q10: Failed on test | R10: Failed on test | S10: Failed on test | T10: Failed on test | U10: Failed on test | V10: Failed on test | W10: Failed on test | X10: Failed on test | Y10: Failed on test | Z10: Failed on test | AA10: Failed on test | AB10: Failed on test
A11: issue_155 | B11: Passed on test | C11: Passed on test | D11: Passed on test | E11: Passed on test | F11: Passed on test | G11: Passed on test | H11: Passed on test | I11: Passed on test | J11: Passed on test | K11: Passed on test | L11: Passed on test | M11: Passed on test | N11: NOT_TESTED | O11: NOT_TESTED | P11: NOT_TESTED | Q11: NOT_TESTED | R11: NOT_TESTED | S11: NOT_TESTED | T11: NOT_TESTED | U11: NOT_TESTED | V11: NOT_TESTED | W11: NOT_TESTED | X11: NOT_TESTED | Y11: NOT_TESTED | Z11: NOT_TESTED | AA11: NOT_TESTED | AB11: NOT_TESTED
A12: issue_157 | B12: Runtime error | C12: Runtime error | D12: Runtime error | E12: Runtime error | F12: Passed on test | G12: Passed on test | H12: Passed on test | I12: Passed on test | J12: Passed on test | K12: Passed on test | L12: Passed on test | M12: Passed on test | N12: NOT_TESTED | O12: NOT_TESTED | P12: NOT_TESTED | Q12: NOT_TESTED | R12: NOT_TESTED | S12: NOT_TESTED | T12: NOT_TESTED | U12: NOT_TESTED | V12: NOT_TESTED | W12: NOT_TESTED | X12: NOT_TESTED | Y12: NOT_TESTED | Z12: NOT_TESTED | AA12: NOT_TESTED | AB12: NOT_TESTED
... A73: issue_921 | B73: Runtime error | C73: Runtime error | D73: Runtime error | E73: Runtime error | F73: NOT_TESTED | G73: NOT_TESTED | H73: NOT_TESTED | I73: NOT_TESTED | J73: NOT_TESTED | K73: NOT_TESTED | L73: NOT_TESTED | M73: NOT_TESTED | N73: NOT_TESTED | O73: NOT_TESTED | P73: NOT_TESTED | Q73: NOT_TESTED | R73: NOT_TESTED | S73: NOT_TESTED | T73: NOT_TESTED | U73: NOT_TESTED | V73: NOT_TESTED | W73: NOT_TESTED | X73: NOT_TESTED | Y73: NOT_TESTED | Z73: NOT_TESTED | AA73: NOT_TESTED | AB73: NOT_TESTED

Sheet gpt-6-luna
A1: case_id | B1: 0.25.0 | C1: 0.25.1 | D1: 0.25.2 | E1: 0.25.3 | F1: 0.45.0 | G1: 0.45.1 | H1: 0.45.2 | I1: 0.45.3 | J1: 0.46.0 | K1: 0.46.1 | L1: 0.46.2 | M1: 0.46.3 | N1: 1.0.0 | O1: 1.0.1 | P1: 1.0.2 | Q1: 1.1.0 | R1: 1.1.1 | S1: 1.1.2 | T1: 1.2.0 | U1: 1.2.1 | V1: 1.2.2 | W1: 1.2.4 | X1: 2.0.0 | Y1: 2.2.0 | Z1: 2.3.0 | AA1: 2.4.0 | AB1: 2.5.0
A2: issue_009 | B2: NOT_TESTED | C2: NOT_TESTED | D2: NOT_TESTED | E2: NOT_TESTED | F2: Passed on test | G2: Passed on test | H2: Passed on test | I2: Passed on test | J2: Passed on test | K2: Passed on test | L2: Passed on test | M2: Passed on test | N2: NOT_TESTED | O2: NOT_TESTED | P2: NOT_TESTED | Q2: NOT_TESTED | R2: NOT_TESTED | S2: NOT_TESTED | T2: NOT_TESTED | U2: NOT_TESTED | V2: NOT_TESTED | W2: NOT_TESTED | X2: NOT_TESTED | Y2: NOT_TESTED | Z2: NOT_TESTED | AA2: NOT_TESTED | AB2: NOT_TESTED
A3: issue_021_se | B3: Runtime error | C3: Runtime error | D3: Runtime error | E3: Runtime error | F3: Runtime error | G3: Runtime error | H3: Runtime error | I3: Runtime error | J3: Runtime error | K3: Runtime error | L3: Runtime error | M3: Runtime error | N3: NOT_TESTED | O3: NOT_TESTED | P3: NOT_TESTED | Q3: NOT_TESTED | R3: NOT_TESTED | S3: NOT_TESTED | T3: NOT_TESTED | U3: NOT_TESTED | V3: NOT_TESTED | W3: NOT_TESTED | X3: NOT_TESTED | Y3: NOT_TESTED | Z3: NOT_TESTED | AA3: NOT_TESTED | AB3: NOT_TESTED
A4: issue_032_se | B4: Passed on test | C4: Passed on test | D4: Passed on test | E4: Passed on test | F4: NOT_TESTED | G4: NOT_TESTED | H4: NOT_TESTED | I4: NOT_TESTED | J4: NOT_TESTED | K4: NOT_TESTED | L4: NOT_TESTED | M4: NOT_TESTED | N4: NOT_TESTED | O4: NOT_TESTED | P4: NOT_TESTED | Q4: NOT_TESTED | R4: NOT_TESTED | S4: NOT_TESTED | T4: NOT_TESTED | U4: NOT_TESTED | V4: NOT_TESTED | W4: NOT_TESTED | X4: NOT_TESTED | Y4: NOT_TESTED | Z4: NOT_TESTED | AA4: NOT_TESTED | AB4: NOT_TESTED
A5: issue_034 | B5: NOT_TESTED | C5: NOT_TESTED | D5: NOT_TESTED | E5: NOT_TESTED | F5: NOT_TESTED | G5: NOT_TESTED | H5: NOT_TESTED | I5: NOT_TESTED | J5: NOT_TESTED | K5: NOT_TESTED | L5: NOT_TESTED | M5: NOT_TESTED | N5: Passed on test | O5: Passed on test | P5: Passed on test | Q5: Passed on test | R5: Passed on test | S5: Passed on test | T5: Passed on test | U5: Passed on test | V5: Passed on test | W5: Passed on test | X5: Passed on test | Y5: Passed on test | Z5: Passed on test | AA5: Passed on test | AB5: Passed on test
A6: issue_036 | B6: NOT_TESTED | C6: NOT_TESTED | D6: NOT_TESTED | E6: NOT_TESTED | F6: NOT_TESTED | G6: NOT_TESTED | H6: NOT_TESTED | I6: NOT_TESTED | J6: NOT_TESTED | K6: NOT_TESTED | L6: NOT_TESTED | M6: NOT_TESTED | N6: Passed on test | O6: Passed on test | P6: Passed on test | Q6: Passed on test | R6: Passed on test | S6: Passed on test | T6: Passed on test | U6: Passed on test | V6: Passed on test | W6: Passed on test | X6: Passed on test | Y6: Passed on test | Z6: Passed on test | AA6: Passed on test | AB6: Passed on test
A7: issue_058_se | B7: Passed on test | C7: Passed on test | D7: Passed on test | E7: Passed on test | F7: Passed on test | G7: Passed on test | H7: Passed on test | I7: Passed on test | J7: Passed on test | K7: Passed on test | L7: Passed on test | M7: Passed on test | N7: NOT_TESTED | O7: NOT_TESTED | P7: NOT_TESTED | Q7: NOT_TESTED | R7: NOT_TESTED | S7: NOT_TESTED | T7: NOT_TESTED | U7: NOT_TESTED | V7: NOT_TESTED | W7: NOT_TESTED | X7: NOT_TESTED | Y7: NOT_TESTED | Z7: NOT_TESTED | AA7: NOT_TESTED | AB7: NOT_TESTED
A8: issue_061 | B8: NOT_TESTED | C8: NOT_TESTED | D8: NOT_TESTED | E8: NOT_TESTED | F8: NOT_TESTED | G8: NOT_TESTED | H8: NOT_TESTED | I8: NOT_TESTED | J8: NOT_TESTED | K8: NOT_TESTED | L8: NOT_TESTED | M8: NOT_TESTED | N8: Passed on test | O8: Passed on test | P8: Passed on test | Q8: Passed on test | R8: Passed on test | S8: Passed on test | T8: Passed on test | U8: Passed on test | V8: Passed on test | W8: Passed on test | X8: Passed on test | Y8: Passed on test | Z8: Passed on test | AA8: Passed on test | AB8: Passed on test
A9: issue_072 | B9: Passed on test | C9: Passed on test | D9: Passed on test | E9: Passed on test | F9: NOT_TESTED | G9: NOT_TESTED | H9: NOT_TESTED | I9: NOT_TESTED | J9: NOT_TESTED | K9: NOT_TESTED | L9: NOT_TESTED | M9: NOT_TESTED | N9: NOT_TESTED | O9: NOT_TESTED | P9: NOT_TESTED | Q9: NOT_TESTED | R9: NOT_TESTED | S9: NOT_TESTED | T9: NOT_TESTED | U9: NOT_TESTED | V9: NOT_TESTED | W9: NOT_TESTED | X9: NOT_TESTED | Y9: NOT_TESTED | Z9: NOT_TESTED | AA9: NOT_TESTED | AB9: NOT_TESTED
A10: issue_096 | B10: Failed on test | C10: Failed on test | D10: Failed on test | E10: Failed on test | F10: Failed on test | G10: Failed on test | H10: Failed on test | I10: Failed on test | J10: Failed on test | K10: Failed on test | L10: Failed on test | M10: Failed on test | N10: Failed on test | O10: Failed on test | P10: Failed on test | Q10: Failed on test | R10: Failed on test | S10: Failed on test | T10: Failed on test | U10: Failed on test | V10: Failed on test | W10: Failed on test | X10: Failed on test | Y10: Failed on test | Z10: Failed on test | AA10: Failed on test | AB10: Failed on test
A11: issue_155 | B11: Runtime error | C11: Runtime error | D11: Runtime error | E11: Runtime error | F11: Passed on test | G11: Passed on test | H11: Passed on test | I11: Passed on test | J11: Passed on test | K11: Passed on test | L11: Passed on test | M11: Passed on test | N11: NOT_TESTED | O11: NOT_TESTED | P11: NOT_TESTED | Q11: NOT_TESTED | R11: NOT_TESTED | S11: NOT_TESTED | T11: NOT_TESTED | U11: NOT_TESTED | V11: NOT_TESTED | W11: NOT_TESTED | X11: NOT_TESTED | Y11: NOT_TESTED | Z11: NOT_TESTED | AA11: NOT_TESTED | AB11: NOT_TESTED
A12: issue_157 | B12: Runtime error | C12: Runtime error | D12: Runtime error | E12: Runtime error | F12: Passed on test | G12: Passed on test | H12: Passed on test | I12: Passed on test | J12: Passed on test | K12: Passed on test | L12: Passed on test | M12: Passed on test | N12: NOT_TESTED | O12: NOT_TESTED | P12: NOT_TESTED | Q12: NOT_TESTED | R12: NOT_TESTED | S12: NOT_TESTED | T12: NOT_TESTED | U12: NOT_TESTED | V12: NOT_TESTED | W12: NOT_TESTED | X12: NOT_TESTED | Y12: NOT_TESTED | Z12: NOT_TESTED | AA12: NOT_TESTED | AB12: NOT_TESTED
... A73: issue_921 | B73: Runtime error | C73: Runtime error | D73: Runtime error | E73: Runtime error | F73: NOT_TESTED | G73: NOT_TESTED | H73: NOT_TESTED | I73: NOT_TESTED | J73: NOT_TESTED | K73: NOT_TESTED | L73: NOT_TESTED | M73: NOT_TESTED | N73: NOT_TESTED | O73: NOT_TESTED | P73: NOT_TESTED | Q73: NOT_TESTED | R73: NOT_TESTED | S73: NOT_TESTED | T73: NOT_TESTED | U73: NOT_TESTED | V73: NOT_TESTED | W73: NOT_TESTED | X73: NOT_TESTED | Y73: NOT_TESTED | Z73: NOT_TESTED | AA73: NOT_TESTED | AB73: NOT_TESTED

Sheet gpt-6-astra
A1: case_id | B1: 0.25.0 | C1: 0.25.1 | D1: 0.25.2 | E1: 0.25.3 | F1: 0.45.0 | G1: 0.45.1 | H1: 0.45.2 | I1: 0.45.3 | J1: 0.46.0 | K1: 0.46.1 | L1: 0.46.2 | M1: 0.46.3 | N1: 1.0.0 | O1: 1.0.1 | P1: 1.0.2 | Q1: 1.1.0 | R1: 1.1.1 | S1: 1.1.2 | T1: 1.2.0 | U1: 1.2.1 | V1: 1.2.2 | W1: 1.2.4 | X1: 2.0.0 | Y1: 2.2.0 | Z1: 2.3.0 | AA1: 2.4.0 | AB1: 2.5.0
A2: issue_009 | B2: NOT_TESTED | C2: NOT_TESTED | D2: NOT_TESTED | E2: NOT_TESTED | F2: Passed on test | G2: Passed on test | H2: Passed on test | I2: Passed on test | J2: Passed on test | K2: Passed on test | L2: Passed on test | M2: Passed on test | N2: NOT_TESTED | O2: NOT_TESTED | P2: NOT_TESTED | Q2: NOT_TESTED | R2: NOT_TESTED | S2: NOT_TESTED | T2: NOT_TESTED | U2: NOT_TESTED | V2: NOT_TESTED | W2: NOT_TESTED | X2: NOT_TESTED | Y2: NOT_TESTED | Z2: NOT_TESTED | AA2: NOT_TESTED | AB2: NOT_TESTED
A3: issue_021_se | B3: Passed on test | C3: Passed on test | D3: Passed on test | E3: Passed on test | F3: Passed on test | G3: Passed on test | H3: Passed on test | I3: Passed on test | J3: Passed on test | K3: Passed on test | L3: Passed on test | M3: Passed on test | N3: NOT_TESTED | O3: NOT_TESTED | P3: NOT_TESTED | Q3: NOT_TESTED | R3: NOT_TESTED | S3: NOT_TESTED | T3: NOT_TESTED | U3: NOT_TESTED | V3: NOT_TESTED | W3: NOT_TESTED | X3: NOT_TESTED | Y3: NOT_TESTED | Z3: NOT_TESTED | AA3: NOT_TESTED | AB3: NOT_TESTED
A4: issue_032_se | B4: Passed on test | C4: Passed on test | D4: Passed on test | E4: Passed on test | F4: NOT_TESTED | G4: NOT_TESTED | H4: NOT_TESTED | I4: NOT_TESTED | J4: NOT_TESTED | K4: NOT_TESTED | L4: NOT_TESTED | M4: NOT_TESTED | N4: NOT_TESTED | O4: NOT_TESTED | P4: NOT_TESTED | Q4: NOT_TESTED | R4: NOT_TESTED | S4: NOT_TESTED | T4: NOT_TESTED | U4: NOT_TESTED | V4: NOT_TESTED | W4: NOT_TESTED | X4: NOT_TESTED | Y4: NOT_TESTED | Z4: NOT_TESTED | AA4: NOT_TESTED | AB4: NOT_TESTED
A5: issue_034 | B5: NOT_TESTED | C5: NOT_TESTED | D5: NOT_TESTED | E5: NOT_TESTED | F5: NOT_TESTED | G5: NOT_TESTED | H5: NOT_TESTED | I5: NOT_TESTED | J5: NOT_TESTED | K5: NOT_TESTED | L5: NOT_TESTED | M5: NOT_TESTED | N5: Passed on test | O5: Passed on test | P5: Passed on test | Q5: Passed on test | R5: Passed on test | S5: Passed on test | T5: Passed on test | U5: Passed on test | V5: Passed on test | W5: Passed on test | X5: Passed on test | Y5: Passed on test | Z5: Passed on test | AA5: Passed on test | AB5: Passed on test
A6: issue_036 | B6: NOT_TESTED | C6: NOT_TESTED | D6: NOT_TESTED | E6: NOT_TESTED | F6: NOT_TESTED | G6: NOT_TESTED | H6: NOT_TESTED | I6: NOT_TESTED | J6: NOT_TESTED | K6: NOT_TESTED | L6: NOT_TESTED | M6: NOT_TESTED | N6: Passed on test | O6: Passed on test | P6: Passed on test | Q6: Passed on test | R6: Passed on test | S6: Passed on test | T6: Passed on test | U6: Passed on test | V6: Passed on test | W6: Passed on test | X6: Passed on test | Y6: Passed on test | Z6: Passed on test | AA6: Passed on test | AB6: Passed on test
A7: issue_058_se | B7: Passed on test | C7: Passed on test | D7: Passed on test | E7: Passed on test | F7: Passed on test | G7: Passed on test | H7: Passed on test | I7: Passed on test | J7: Passed on test | K7: Passed on test | L7: Passed on test | M7: Passed on test | N7: NOT_TESTED | O7: NOT_TESTED | P7: NOT_TESTED | Q7: NOT_TESTED | R7: NOT_TESTED | S7: NOT_TESTED | T7: NOT_TESTED | U7: NOT_TESTED | V7: NOT_TESTED | W7: NOT_TESTED | X7: NOT_TESTED | Y7: NOT_TESTED | Z7: NOT_TESTED | AA7: NOT_TESTED | AB7: NOT_TESTED
A8: issue_061 | B8: NOT_TESTED | C8: NOT_TESTED | D8: NOT_TESTED | E8: NOT_TESTED | F8: NOT_TESTED | G8: NOT_TESTED | H8: NOT_TESTED | I8: NOT_TESTED | J8: NOT_TESTED | K8: NOT_TESTED | L8: NOT_TESTED | M8: NOT_TESTED | N8: Passed on test | O8: Passed on test | P8: Passed on test | Q8: Passed on test | R8: Passed on test | S8: Passed on test | T8: Passed on test | U8: Passed on test | V8: Passed on test | W8: Passed on test | X8: Passed on test | Y8: Passed on test | Z8: Passed on test | AA8: Passed on test | AB8: Passed on test
A9: issue_072 | B9: Passed on test | C9: Passed on test | D9: Passed on test | E9: Passed on test | F9: NOT_TESTED | G9: NOT_TESTED | H9: NOT_TESTED | I9: NOT_TESTED | J9: NOT_TESTED | K9: NOT_TESTED | L9: NOT_TESTED | M9: NOT_TESTED | N9: NOT_TESTED | O9: NOT_TESTED | P9: NOT_TESTED | Q9: NOT_TESTED | R9: NOT_TESTED | S9: NOT_TESTED | T9: NOT_TESTED | U9: NOT_TESTED | V9: NOT_TESTED | W9: NOT_TESTED | X9: NOT_TESTED | Y9: NOT_TESTED | Z9: NOT_TESTED | AA9: NOT_TESTED | AB9: NOT_TESTED
A10: issue_096 | B10: Failed on test | C10: Failed on test | D10: Failed on test | E10: Failed on test | F10: Failed on test | G10: Failed on test | H10: Failed on test | I10: Failed on test | J10: Failed on test | K10: Failed on test | L10: Failed on test | M10: Failed on test | N10: Failed on test | O10: Failed on test | P10: Failed on test | Q10: Failed on test | R10: Failed on test | S10: Failed on test | T10: Failed on test | U10: Failed on test | V10: Failed on test | W10: Failed on test | X10: Failed on test | Y10: Failed on test | Z10: Failed on test | AA10: Failed on test | AB10: Failed on test
A11: issue_155 | B11: Runtime error | C11: Runtime error | D11: Runtime error | E11: Runtime error | F11: Passed on test | G11: Passed on test | H11: Passed on test | I11: Passed on test | J11: Passed on test | K11: Passed on test | L11: Passed on test | M11: Passed on test | N11: NOT_TESTED | O11: NOT_TESTED | P11: NOT_TESTED | Q11: NOT_TESTED | R11: NOT_TESTED | S11: NOT_TESTED | T11: NOT_TESTED | U11: NOT_TESTED | V11: NOT_TESTED | W11: NOT_TESTED | X11: NOT_TESTED | Y11: NOT_TESTED | Z11: NOT_TESTED | AA11: NOT_TESTED | AB11: NOT_TESTED
A12: issue_157 | B12: Runtime error | C12: Runtime error | D12: Runtime error | E12: Runtime error | F12: Passed on test | G12: Passed on test | H12: Passed on test | I12: Passed on test | J12: Passed on test | K12: Passed on test | L12: Passed on test | M12: Passed on test | N12: NOT_TESTED | O12: NOT_TESTED | P12: NOT_TESTED | Q12: NOT_TESTED | R12: NOT_TESTED | S12: NOT_TESTED | T12: NOT_TESTED | U12: NOT_TESTED | V12: NOT_TESTED | W12: NOT_TESTED | X12: NOT_TESTED | Y12: NOT_TESTED | Z12: NOT_TESTED | AA12: NOT_TESTED | AB12: NOT_TESTED
... A73: issue_921 | B73: Runtime error | C73: Runtime error | D73: Runtime error | E73: Runtime error | F73: NOT_TESTED | G73: NOT_TESTED | H73: NOT_TESTED | I73: NOT_TESTED | J73: NOT_TESTED | K73: NOT_TESTED | L73: NOT_TESTED | M73: NOT_TESTED | N73: NOT_TESTED | O73: NOT_TESTED | P73: NOT_TESTED | Q73: NOT_TESTED | R73: NOT_TESTED | S73: NOT_TESTED | T73: NOT_TESTED | U73: NOT_TESTED | V73: NOT_TESTED | W73: NOT_TESTED | X73: NOT_TESTED | Y73: NOT_TESTED | Z73: NOT_TESTED | AA73: NOT_TESTED | AB73: NOT_TESTED

Sheet gpt-6.1-sol
A1: case_id | B1: 0.25.0 | C1: 0.25.1 | D1: 0.25.2 | E1: 0.25.3 | F1: 0.45.0 | G1: 0.45.1 | H1: 0.45.2 | I1: 0.45.3 | J1: 0.46.0 | K1: 0.46.1 | L1: 0.46.2 | M1: 0.46.3 | N1: 1.0.0 | O1: 1.0.1 | P1: 1.0.2 | Q1: 1.1.0 | R1: 1.1.1 | S1: 1.1.2 | T1: 1.2.0 | U1: 1.2.1 | V1: 1.2.2 | W1: 1.2.4 | X1: 2.0.0 | Y1: 2.2.0 | Z1: 2.3.0 | AA1: 2.4.0 | AB1: 2.5.0
