Workbook

Sheet Summary
A1: case_id | B1: 0.25.0 | C1: 0.25.1 | D1: 0.25.2 | E1: 0.25.3 | F1: 0.45.0 | G1: 0.45.1 | H1: 0.45.2 | I1: 0.45.3 | J1: 0.46.0 | K1: 0.46.1 | L1: 0.46.2 | M1: 0.46.3 | N1: 1.0.0 | O1: 1.0.1 | P1: 1.0.2 | Q1: 1.1.0 | R1: 1.1.1 | S1: 1.1.2 | T1: 1.2.0 | U1: 1.2.1 | V1: 1.2.2 | W1: 1.2.4 | X1: 2.0.0 | Y1: 2.2.0 | Z1: 2.3.0 | AA1: 2.4.0 | AB1: 2.5.0 | AC1: error_type_0.25.0 | AD1: error_message_0.25.0 | AE1: error_description_0.25.0 | AF1: error_type_0.25.1 | AG1: error_message_0.25.1 | AH1: error_description_0.25.1 | AI1: error_type_0.25.2 | AJ1: error_message_0.25.2 | AK1: error_description_0.25.2 | AL1: error_type_0.25.3 | AM1: error_message_0.25.3 | AN1: error_description_0.25.3 | AO1: error_type_0.45.0 | AP1: error_message_0.45.0 | AQ1: error_description_0.45.0 | AR1: error_type_0.45.1 | AS1: error_message_0.45.1 | AT1: error_description_0.45.1 | AU1: error_type_0.45.2 | AV1: error_message_0.45.2 | AW1: error_description_0.45.2 | AX1: error_type_0.45.3 | AY1: error_message_0.45.3 | AZ1: error_description_0.45.3 | BA1: error_type_0.46.0 | BB1: error_message_0.46.0 | BC1: error_description_0.46.0 | BD1: error_type_0.46.1 | BE1: error_message_0.46.1 | BF1: error_description_0.46.1 | BG1: error_type_0.46.2 | BH1: error_message_0.46.2 | BI1: error_description_0.46.2 | BJ1: error_type_0.46.3 | BK1: error_message_0.46.3 | BL1: error_description_0.46.3 | BM1: error_type_1.0.0 | BN1: error_message_1.0.0 | BO1: error_description_1.0.0 | BP1: error_type_1.0.1 | BQ1: error_message_1.0.1 | BR1: error_description_1.0.1 | BS1: error_type_1.0.2 | BT1: error_message_1.0.2 | BU1: error_description_1.0.2 | BV1: error_type_1.1.0 | BW1: error_message_1.1.0 | BX1: error_description_1.1.0 | BY1: error_type_1.1.1 | BZ1: error_message_1.1.1 | CA1: error_description_1.1.1 | CB1: error_type_1.1.2 | CC1: error_message_1.1.2 | CD1: error_description_1.1.2 | CE1: error_type_1.2.0 | CF1: error_message_1.2.0 | CG1: error_description_1.2.0 | CH1: error_type_1.2.1 | CI1: error_message_1.2.1 | CJ1: error_description_1.2.1 | CK1: error_type_1.2.2 | CL1: error_message_1.2.2 | CM1: error_description_1.2.2 | CN1: error_type_1.2.4 | CO1: error_message_1.2.4 | CP1: error_description_1.2.4 | CQ1: error_type_2.0.0 | CR1: error_message_2.0.0 | CS1: error_description_2.0.0 | CT1: error_type_2.2.0 | CU1: error_message_2.2.0 | CV1: error_description_2.2.0 | CW1: error_type_2.3.0 | CX1: error_message_2.3.0 | CY1: error_description_2.3.0 | CZ1: error_type_2.4.0 | DA1: error_message_2.4.0 | DB1: error_description_2.4.0 | DC1: error_type_2.5.0 | DD1: error_message_2.5.0 | DE1: error_description_2.5.0
A2: issue_009 | B2: NOT_TESTED | C2: NOT_TESTED | D2: NOT_TESTED | E2: NOT_TESTED | F2: Runtime error | G2: Runtime error | H2: Failed on test | I2: Failed on test | J2: Runtime error | K2: Runtime error | L2: Runtime error | M2: Runtime error | N2: NOT_TESTED | O2: NOT_TESTED | P2: NOT_TESTED | Q2: NOT_TESTED | R2: NOT_TESTED | S2: NOT_TESTED | T2: NOT_TESTED | U2: NOT_TESTED | V2: NOT_TESTED | W2: NOT_TESTED | X2: NOT_TESTED | Y2: NOT_TESTED | Z2: NOT_TESTED | AA2: NOT_TESTED | AB2: NOT_TESTED | AO2: TranspilerError | AP2: qiskit.transpiler.exceptions.TranspilerError: "The 'layout' must be full (with ancilla)." | AQ2: The LLM ran CSPLayout and ApplyLayout by hand in a PassManager but never added the passes that extend the 3-qubit layout to the backend's 5 qubits (FullAncillaAllocation / EnlargeWithAncilla), so ApplyLayout rejects the partial layout. | AR2: TranspilerError | AS2: qiskit.transpiler.exceptions.TranspilerError: "The 'layout' must be full (with ancilla)." | AT2: The LLM ran CSPLayout and ApplyLayout by hand in a PassManager but never added the passes that extend the 3-qubit layout to the backend's 5 qubits (FullAncillaAllocation / EnlargeWithAncilla), so ApplyLayout rejects the partial layout. | AU2: AssertionError | AV2: AssertionError: 3 != 5 | AW2: The LLM ran CSPLayout and ApplyLayout by hand but never extended the layout to the backend's 5 qubits; here CSPLayout happened to pick physical qubits 0-2, so ApplyLayout accepted it and returned a 3-qubit circuit instead of one compiled for the 5-qubit backend. | AX2: AssertionError | AY2: AssertionError: 3 != 5 | AZ2: The LLM ran CSPLayout and ApplyLayout by hand but never extended the layout to the backend's 5 qubits; here CSPLayout happened to pick physical qubits 0-2, so ApplyLayout accepted it and returned a 3-qubit circuit instead of one compiled for the 5-qubit backend. | BA2: TranspilerError | BB2: qiskit.transpiler.exceptions.TranspilerError: "The 'layout' must be full (with ancilla)." | BC2: The LLM ran CSPLayout and ApplyLayout by hand in a PassManager but never added the passes that extend the 3-qubit layout to the backend's 5 qubits (FullAncillaAllocation / EnlargeWithAncilla), so ApplyLayout rejects the partial layout. | BD2: TranspilerError | BE2: qiskit.transpiler.exceptions.TranspilerError: "The 'layout' must be full (with ancilla)." | BF2: The LLM ran CSPLayout and ApplyLayout by hand in a PassManager but never added the passes that extend the 3-qubit layout to the backend's 5 qubits (FullAncillaAllocation / EnlargeWithAncilla), so ApplyLayout rejects the partial layout. | BG2: TranspilerError | BH2: qiskit.transpiler.exceptions.TranspilerError: "The 'layout' must be full (with ancilla)." | BI2: The LLM ran CSPLayout and ApplyLayout by hand in a PassManager but never added the passes that extend the 3-qubit layout to the backend's 5 qubits (FullAncillaAllocation / EnlargeWithAncilla), so ApplyLayout rejects the partial layout. | BJ2: TranspilerError | BK2: qiskit.transpiler.exceptions.TranspilerError: "The 'layout' must be full (with ancilla)." | BL2: The LLM ran CSPLayout and ApplyLayout by hand in a PassManager but never added the passes that extend the 3-qubit layout to the backend's 5 qubits (FullAncillaAllocation / EnlargeWithAncilla), so ApplyLayout rejects the partial layout.
A3: issue_018_se | B3: NOT_TESTED | C3: NOT_TESTED | D3: NOT_TESTED | E3: NOT_TESTED | F3: NOT_TESTED | G3: NOT_TESTED | H3: NOT_TESTED | I3: NOT_TESTED | J3: NOT_TESTED | K3: NOT_TESTED | L3: NOT_TESTED | M3: NOT_TESTED | N3: Failed on test | O3: Failed on test | P3: Failed on test | Q3: Failed on test | R3: Failed on test | S3: Failed on test | T3: Failed on test | U3: Failed on test | V3: Failed on test | W3: Failed on test | X3: Failed on test | Y3: Failed on test | Z3: Failed on test | AA3: Failed on test | AB3: Failed on test | BM3: AssertionError | BN3: AssertionError: Not equal to tolerance rtol=0, atol=1e-12 The ideal magic-square strategy must win every input pair. Mismatched elements: 6 / 9 (66.7%) Max absolute difference: 0.5 Max relative difference: inf x: array([0. , 0.5, 0.5, 0.5, 0. , 0.5, | BO3: The LLM swapped which inputs choose Alice's and Bob's answers, so the strategy still loses 6 of the 9 input pairs half the time instead of always winning (the Aer simulator also crashes natively here, as it does for fixed.py). | BP3: AssertionError | BQ3: AssertionError: Not equal to tolerance rtol=0, atol=1e-12 The ideal magic-square strategy must win every input pair. Mismatched elements: 6 / 9 (66.7%) Max absolute difference: 0.5 Max relative difference: inf x: array([0. , 0.5, 0.5, 0.5, 0. , 0.5, | BR3: The LLM swapped which inputs choose Alice's and Bob's answers, so the strategy still loses 6 of the 9 input pairs half the time instead of always winning (the Aer simulator also crashes natively here, as it does for fixed.py). | BS3: AssertionError | BT3: AssertionError: Not equal to tolerance rtol=0, atol=1e-12 The ideal magic-square strategy must win every input pair. Mismatched elements: 6 / 9 (66.7%) Max absolute difference: 0.5 Max relative difference: inf x: array([0. , 0.5, 0.5, 0.5, 0. , 0.5, | BU3: The LLM swapped which inputs choose Alice's and Bob's answers, so the strategy still loses 6 of the 9 input pairs half the time instead of always winning (the Aer simulator also crashes natively here, as it does for fixed.py). | BV3: AssertionError | BW3: AssertionError: Not equal to tolerance rtol=0, atol=1e-12 The ideal magic-square strategy must win every input pair. Mismatched elements: 6 / 9 (66.7%) First 5 mismatches are at indices: [1]: 0.4999999999999999 (ACTUAL), 0.0 (DESIRED) [2]: 0.49999999 | BX3: The LLM swapped which inputs choose Alice's and Bob's answers, so the strategy still loses 6 of the 9 input pairs half the time instead of always winning (the Aer simulator also crashes natively here, as it does for fixed.py). | BY3: AssertionError | BZ3: AssertionError: Not equal to tolerance rtol=0, atol=1e-12 The ideal magic-square strategy must win every input pair. Mismatched elements: 6 / 9 (66.7%) First 5 mismatches are at indices: [1]: 0.4999999999999999 (ACTUAL), 0.0 (DESIRED) [2]: 0.49999999 | CA3: The LLM swapped which inputs choose Alice's and Bob's answers, so the strategy still loses 6 of the 9 input pairs half the time instead of always winning (the Aer simulator also crashes natively here, as it does for fixed.py). | CB3: AssertionError | CC3: AssertionError: Not equal to tolerance rtol=0, atol=1e-12 The ideal magic-square strategy must win every input pair. Mismatched elements: 6 / 9 (66.7%) First 5 mismatches are at indices: [1]: 0.4999999999999999 (ACTUAL), 0.0 (DESIRED) [2]: 0.49999999 | CD3: The LLM swapped which inputs choose Alice's and Bob's answers, so the strategy still loses 6 of the 9 input pairs half the time instead of always winning (the Aer simulator also crashes natively here, as it does for fixed.py). | CE3: AssertionError | CF3: AssertionError: Not equal to tolerance rtol=0, atol=1e-12 The ideal magic-square strategy must win every input pair. Mismatched elements: 6 / 9 (66.7%) First 5 mismatches are at indices: [1]: 0.4999999999999999 (ACTUAL), 0.0 (DESIRED) [2]: 0.49999999 | CG3: The LLM swapped which inputs choose Alice's and Bob's answers, so the strategy still loses 6 of the 9 input pairs half the time instead of always winning (the Aer simulator also crashes natively here, as it does for fixed.py). | CH3: AssertionError | CI3: AssertionError: Not equal to tolerance rtol=0, atol=1e-12 The ideal magic-square strategy must win every input pair. Mismatched elements: 6 / 9 (66.7%) First 5 mismatches are at indices: [1]: 0.4999999999999999 (ACTUAL), 0.0 (DESIRED) [2]: 0.49999999 | CJ3: The LLM swapped which inputs choose Alice's and Bob's answers, so the strategy still loses 6 of the 9 input pairs half the time instead of always winning (the Aer simulator also crashes natively here, as it does for fixed.py). | CK3: AssertionError | CL3: AssertionError: Not equal to tolerance rtol=0, atol=1e-12 The ideal magic-square strategy must win every input pair. Mismatched elements: 6 / 9 (66.7%) First 5 mismatches are at indices: [1]: 0.4999999999999999 (ACTUAL), 0.0 (DESIRED) [2]: 0.49999999 | CM3: The LLM swapped which inputs choose Alice's and Bob's answers, so the strategy still loses 6 of the 9 input pairs half the time instead of always winning (the Aer simulator also crashes natively here, as it does for fixed.py). | CN3: AssertionError | CO3: AssertionError: Not equal to tolerance rtol=0, atol=1e-12 The ideal magic-square strategy must win every input pair. Mismatched elements: 6 / 9 (66.7%) First 5 mismatches are at indices: [1]: 0.4999999999999999 (ACTUAL), 0.0 (DESIRED) [2]: 0.49999999 | CP3: The LLM swapped which inputs choose Alice's and Bob's answers, so the strategy still loses 6 of the 9 input pairs half the time instead of always winning (the Aer simulator also crashes natively here, as it does for fixed.py). | CQ3: AssertionError | CR3: AssertionError: Not equal to tolerance rtol=0, atol=1e-12 The ideal magic-square strategy must win every input pair. Mismatched elements: 6 / 9 (66.7%) First 5 mismatches are at indices: [1]: 0.4999999999999999 (ACTUAL), 0.0 (DESIRED) [2]: 0.49999999 | CS3: The LLM swapped which inputs choose Alice's and Bob's answers, so the strategy still loses 6 of the 9 input pairs half the time instead of always winning (the Aer simulator also crashes natively here, as it does for fixed.py). | CT3: AssertionError | CU3: AssertionError: Not equal to tolerance rtol=0, atol=1e-12 The ideal magic-square strategy must win every input pair. Mismatched elements: 6 / 9 (66.7%) First 5 mismatches are at indices: [1]: 0.4999999999999999 (ACTUAL), 0.0 (DESIRED) [2]: 0.49999999 | CV3: The LLM swapped which inputs choose Alice's and Bob's answers, so the strategy still loses 6 of the 9 input pairs half the time instead of always winning (the Aer simulator also crashes natively here, as it does for fixed.py). | CW3: AssertionError | CX3: AssertionError: Not equal to tolerance rtol=0, atol=1e-12 The ideal magic-square strategy must win every input pair. Mismatched elements: 6 / 9 (66.7%) First 5 mismatches are at indices: [1]: 0.4999999999999999 (ACTUAL), 0.0 (DESIRED) [2]: 0.49999999 | CY3: The LLM swapped which inputs choose Alice's and Bob's answers, so the strategy still loses 6 of the 9 input pairs half the time instead of always winning (the Aer simulator also crashes natively here, as it does for fixed.py). | CZ3: AssertionError | DA3: AssertionError: Not equal to tolerance rtol=0, atol=1e-12 The ideal magic-square strategy must win every input pair. Mismatched elements: 6 / 9 (66.7%) First 5 mismatches are at indices: [1]: 0.4999999999999999 (ACTUAL), 0.0 (DESIRED) [2]: 0.49999999 | DB3: The LLM swapped which inputs choose Alice's and Bob's answers, so the strategy still loses 6 of the 9 input pairs half the time instead of always winning (the Aer simulator also crashes natively here, as it does for fixed.py). | DC3: AssertionError | DD3: AssertionError: Not equal to tolerance rtol=0, atol=1e-12 The ideal magic-square strategy must win every input pair. Mismatched elements: 6 / 9 (66.7%) First 5 mismatches are at indices: [1]: 0.4999999999999999 (ACTUAL), 0.0 (DESIRED) [2]: 0.49999999 | DE3: The LLM swapped which inputs choose Alice's and Bob's answers, so the strategy still loses 6 of the 9 input pairs half the time instead of always winning (the Aer simulator also crashes natively here, as it does for fixed.py).
A4: issue_021_se | B4: Runtime error | C4: Runtime error | D4: Runtime error | E4: Runtime error | F4: Runtime error | G4: Runtime error | H4: Runtime error | I4: Runtime error | J4: Runtime error | K4: Runtime error | L4: Runtime error | M4: Runtime error | N4: NOT_TESTED | O4: NOT_TESTED | P4: NOT_TESTED | Q4: NOT_TESTED | R4: NOT_TESTED | S4: NOT_TESTED | T4: NOT_TESTED | U4: NOT_TESTED | V4: NOT_TESTED | W4: NOT_TESTED | X4: NOT_TESTED | Y4: NOT_TESTED | Z4: NOT_TESTED | AA4: NOT_TESTED | AB4: NOT_TESTED | AC4: QiskitError | AD4: qiskit.exceptions.QiskitError: 'ERROR: [Experiment 0] Circuit contains invalid instructions {"gates": {disentangler_dg}} for "statevector" method , ERROR: Circuit contains invalid instructions {"gates": {disentangler_dg}} for "statevector" method' | AE4: Calling circuit.decompose() only unrolls one level, leaving a 'disentangler_dg' instruction that the Aer statevector simulator cannot run, so the simulation fails. | AF4: QiskitError | AG4: qiskit.exceptions.QiskitError: 'ERROR: [Experiment 0] Circuit contains invalid instructions {"gates": {disentangler_dg}} for "statevector" method , ERROR: Circuit contains invalid instructions {"gates": {disentangler_dg}} for "statevector" method' | AH4: Calling circuit.decompose() only unrolls one level, leaving a 'disentangler_dg' instruction that the Aer statevector simulator cannot run, so the simulation fails. | AI4: QiskitError | AJ4: qiskit.exceptions.QiskitError: 'ERROR: [Experiment 0] Circuit contains invalid instructions {"gates": {disentangler_dg}} for "statevector" method , ERROR: Circuit contains invalid instructions {"gates": {disentangler_dg}} for "statevector" method' | AK4: Calling circuit.decompose() only unrolls one level, leaving a 'disentangler_dg' instruction that the Aer statevector simulator cannot run, so the simulation fails. | AL4: QiskitError | AM4: qiskit.exceptions.QiskitError: 'ERROR: [Experiment 0] Circuit contains invalid instructions {"gates": {disentangler_dg}} for "statevector" method , ERROR: Circuit contains invalid instructions {"gates": {disentangler_dg}} for "statevector" method' | AN4: Calling circuit.decompose() only unrolls one level, leaving a 'disentangler_dg' instruction that the Aer statevector simulator cannot run, so the simulation fails. | AO4: QiskitError | AP4: qiskit.exceptions.QiskitError: 'You have to select a circuit or schedule when there is more than one available' | AQ4: Calling circuit.decompose() only unrolls one level, leaving a 'state_preparation' instruction that Aer cannot load, so the simulation fails and no statevector is returned. | AR4: QiskitError | AS4: qiskit.exceptions.QiskitError: 'You have to select a circuit or schedule when there is more than one available' | AT4: Calling circuit.decompose() only unrolls one level, leaving a 'state_preparation' instruction that Aer cannot load, so the simulation fails and no statevector is returned. | AU4: QiskitError | AV4: qiskit.exceptions.QiskitError: 'You have to select a circuit or schedule when there is more than one available' | AW4: Calling circuit.decompose() only unrolls one level, leaving a 'state_preparation' instruction that Aer cannot load, so the simulation fails and no statevector is returned. | AX4: QiskitError | AY4: qiskit.exceptions.QiskitError: 'You have to select a circuit or schedule when there is more than one available' | AZ4: Calling circuit.decompose() only unrolls one level, leaving a 'state_preparation' instruction that Aer cannot load, so the simulation fails and no statevector is returned. | BA4: QiskitError | BB4: qiskit.exceptions.QiskitError: 'You have to select a circuit or schedule when there is more than one available' | BC4: Calling circuit.decompose() only unrolls one level, leaving a 'state_preparation' instruction that Aer cannot load, so the simulation fails and no statevector is returned. | BD4: QiskitError | BE4: qiskit.exceptions.QiskitError: 'You have to select a circuit or schedule when there is more than one available' | BF4: Calling circuit.decompose() only unrolls one level, leaving a 'state_preparation' instruction that Aer cannot load, so the simulation fails and no statevector is returned. | BG4: QiskitError | BH4: qiskit.exceptions.QiskitError: 'You have to select a circuit or schedule when there is more than one available' | BI4: Calling circuit.decompose() only unrolls one level, leaving a 'state_preparation' instruction that Aer cannot load, so the simulation fails and no statevector is returned. | BJ4: QiskitError | BK4: qiskit.exceptions.QiskitError: 'You have to select a circuit or schedule when there is more than one available' | BL4: Calling circuit.decompose() only unrolls one level, leaving a 'state_preparation' instruction that Aer cannot load, so the simulation fails and no statevector is returned.
A5: issue_032_se | B5: Passed on test | C5: Passed on test | D5: Passed on test | E5: Passed on test | F5: NOT_TESTED | G5: NOT_TESTED | H5: NOT_TESTED | I5: NOT_TESTED | J5: NOT_TESTED | K5: NOT_TESTED | L5: NOT_TESTED | M5: NOT_TESTED | N5: NOT_TESTED | O5: NOT_TESTED | P5: NOT_TESTED | Q5: NOT_TESTED | R5: NOT_TESTED | S5: NOT_TESTED | T5: NOT_TESTED | U5: NOT_TESTED | V5: NOT_TESTED | W5: NOT_TESTED | X5: NOT_TESTED | Y5: NOT_TESTED | Z5: NOT_TESTED | AA5: NOT_TESTED | AB5: NOT_TESTED
A6: issue_034 | B6: NOT_TESTED | C6: NOT_TESTED | D6: NOT_TESTED | E6: NOT_TESTED | F6: NOT_TESTED | G6: NOT_TESTED | H6: NOT_TESTED | I6: NOT_TESTED | J6: NOT_TESTED | K6: NOT_TESTED | L6: NOT_TESTED | M6: NOT_TESTED | N6: Passed on test | O6: Passed on test | P6: Passed on test | Q6: Passed on test | R6: Passed on test | S6: Passed on test | T6: Passed on test | U6: Passed on test | V6: Passed on test | W6: Passed on test | X6: Passed on test | Y6: Passed on test | Z6: Passed on test | AA6: Passed on test | AB6: Passed on test
A7: issue_036 | B7: NOT_TESTED | C7: NOT_TESTED | D7: NOT_TESTED | E7: NOT_TESTED | F7: NOT_TESTED | G7: NOT_TESTED | H7: NOT_TESTED | I7: NOT_TESTED | J7: NOT_TESTED | K7: NOT_TESTED | L7: NOT_TESTED | M7: NOT_TESTED | N7: Passed on test | O7: Passed on test | P7: Passed on test | Q7: Passed on test | R7: Passed on test | S7: Passed on test | T7: Passed on test | U7: Passed on test | V7: Passed on test | W7: Passed on test | X7: Passed on test | Y7: Passed on test | Z7: Passed on test | AA7: Passed on test | AB7: Passed on test
A8: issue_058_se | B8: Passed on test | C8: Passed on test | D8: Passed on test | E8: Passed on test | F8: Passed on test | G8: Passed on test | H8: Passed on test | I8: Passed on test | J8: Passed on test | K8: Passed on test | L8: Passed on test | M8: Passed on test | N8: NOT_TESTED | O8: NOT_TESTED | P8: NOT_TESTED | Q8: NOT_TESTED | R8: NOT_TESTED | S8: NOT_TESTED | T8: NOT_TESTED | U8: NOT_TESTED | V8: NOT_TESTED | W8: NOT_TESTED | X8: NOT_TESTED | Y8: NOT_TESTED | Z8: NOT_TESTED | AA8: NOT_TESTED | AB8: NOT_TESTED
A9: issue_061 | B9: NOT_TESTED | C9: NOT_TESTED | D9: NOT_TESTED | E9: NOT_TESTED | F9: NOT_TESTED | G9: NOT_TESTED | H9: NOT_TESTED | I9: NOT_TESTED | J9: NOT_TESTED | K9: NOT_TESTED | L9: NOT_TESTED | M9: NOT_TESTED | N9: Passed on test | O9: Passed on test | P9: Passed on test | Q9: Passed on test | R9: Passed on test | S9: Passed on test | T9: Passed on test | U9: Passed on test | V9: Passed on test | W9: Passed on test | X9: Passed on test | Y9: Passed on test | Z9: Passed on test | AA9: Passed on test | AB9: Passed on test
A10: issue_072 | B10: Passed on test | C10: Passed on test | D10: Passed on test | E10: Passed on test | F10: NOT_TESTED | G10: NOT_TESTED | H10: NOT_TESTED | I10: NOT_TESTED | J10: NOT_TESTED | K10: NOT_TESTED | L10: NOT_TESTED | M10: NOT_TESTED | N10: NOT_TESTED | O10: NOT_TESTED | P10: NOT_TESTED | Q10: NOT_TESTED | R10: NOT_TESTED | S10: NOT_TESTED | T10: NOT_TESTED | U10: NOT_TESTED | V10: NOT_TESTED | W10: NOT_TESTED | X10: NOT_TESTED | Y10: NOT_TESTED | Z10: NOT_TESTED | AA10: NOT_TESTED | AB10: NOT_TESTED
A11: issue_096 | B11: Failed on test | C11: Failed on test | D11: Failed on test | E11: Failed on test | F11: Failed on test | G11: Failed on test | H11: Failed on test | I11: Failed on test | J11: Failed on test | K11: Failed on test | L11: Failed on test | M11: Failed on test | N11: Failed on test | O11: Failed on test | P11: Failed on test | Q11: Failed on test | R11: Failed on test | S11: Failed on test | T11: Failed on test | U11: Failed on test | V11: Failed on test | W11: Failed on test | X11: Failed on test | Y11: Failed on test | Z11: Failed on test | AA11: Failed on test | AB11: Failed on test | AC11: AssertionError | AD11: AssertionError: '' != '[default]\n' + [default] | AssertionError: False is not true : Missing ipython_kernel_config.py (even when the profile directory already exists) | AE11: The LLM creates an empty Qiskit settings file instead of one containing '[default]', and never creates the ipython_kernel_config.py file the user needed. | AF11: AssertionError | AG11: AssertionError: '' != '[default]\n' + [default] | AssertionError: False is not true : Missing ipython_kernel_config.py (even when the profile directory already exists) | AH11: The LLM creates an empty Qiskit settings file instead of one containing '[default]', and never creates the ipython_kernel_config.py file the user needed. | AI11: AssertionError | AJ11: AssertionError: '' != '[default]\n' + [default] | AssertionError: False is not true : Missing ipython_kernel_config.py (even when the profile directory already exists) | AK11: The LLM creates an empty Qiskit settings file instead of one containing '[default]', and never creates the ipython_kernel_config.py file the user needed. | AL11: AssertionError | AM11: AssertionError: '' != '[default]\n' + [default] | AssertionError: False is not true : Missing ipython_kernel_config.py (even when the profile directory already exists) | AN11: The LLM creates an empty Qiskit settings file instead of one containing '[default]', and never creates the ipython_kernel_config.py file the user needed. | AO11: AssertionError | AP11: AssertionError: '' != '[default]\n' + [default] | AssertionError: False is not true : Missing ipython_kernel_config.py (even when the profile directory already exists) | AQ11: The LLM creates an empty Qiskit settings file instead of one containing '[default]', and never creates the ipython_kernel_config.py file the user needed. | AR11: AssertionError | AS11: AssertionError: '' != '[default]\n' + [default] | AssertionError: False is not true : Missing ipython_kernel_config.py (even when the profile directory already exists) | AT11: The LLM creates an empty Qiskit settings file instead of one containing '[default]', and never creates the ipython_kernel_config.py file the user needed. | AU11: AssertionError | AV11: AssertionError: '' != '[default]\n' + [default] | AssertionError: False is not true : Missing ipython_kernel_config.py (even when the profile directory already exists) | AW11: The LLM creates an empty Qiskit settings file instead of one containing '[default]', and never creates the ipython_kernel_config.py file the user needed. | AX11: AssertionError | AY11: AssertionError: '' != '[default]\n' + [default] | AssertionError: False is not true : Missing ipython_kernel_config.py (even when the profile directory already exists) | AZ11: The LLM creates an empty Qiskit settings file instead of one containing '[default]', and never creates the ipython_kernel_config.py file the user needed. | BA11: AssertionError | BB11: AssertionError: '' != '[default]\n' + [default] | AssertionError: False is not true : Missing ipython_kernel_config.py (even when the profile directory already exists) | BC11: The LLM creates an empty Qiskit settings file instead of one containing '[default]', and never creates the ipython_kernel_config.py file the user needed. | BD11: AssertionError | BE11: AssertionError: '' != '[default]\n' + [default] | AssertionError: False is not true : Missing ipython_kernel_config.py (even when the profile directory already exists) | BF11: The LLM creates an empty Qiskit settings file instead of one containing '[default]', and never creates the ipython_kernel_config.py file the user needed. | BG11: AssertionError | BH11: AssertionError: '' != '[default]\n' + [default] | AssertionError: False is not true : Missing ipython_kernel_config.py (even when the profile directory already exists) | BI11: The LLM creates an empty Qiskit settings file instead of one containing '[default]', and never creates the ipython_kernel_config.py file the user needed. | BJ11: AssertionError | BK11: AssertionError: '' != '[default]\n' + [default] | AssertionError: False is not true : Missing ipython_kernel_config.py (even when the profile directory already exists) | BL11: The LLM creates an empty Qiskit settings file instead of one containing '[default]', and never creates the ipython_kernel_config.py file the user needed. | BM11: AssertionError | BN11: AssertionError: '' != '[default]\n' + [default] | AssertionError: False is not true : Missing ipython_kernel_config.py (even when the profile directory already exists) | BO11: The LLM creates an empty Qiskit settings file instead of one containing '[default]', and never creates the ipython_kernel_config.py file the user needed. | BP11: AssertionError | BQ11: AssertionError: '' != '[default]\n' + [default] | AssertionError: False is not true : Missing ipython_kernel_config.py (even when the profile directory already exists) | BR11: The LLM creates an empty Qiskit settings file instead of one containing '[default]', and never creates the ipython_kernel_config.py file the user needed. | BS11: AssertionError | BT11: AssertionError: '' != '[default]\n' + [default] | AssertionError: False is not true : Missing ipython_kernel_config.py (even when the profile directory already exists) | BU11: The LLM creates an empty Qiskit settings file instead of one containing '[default]', and never creates the ipython_kernel_config.py file the user needed. | BV11: AssertionError | BW11: AssertionError: '' != '[default]\n' + [default] | AssertionError: False is not true : Missing ipython_kernel_config.py (even when the profile directory already exists) | BX11: The LLM creates an empty Qiskit settings file instead of one containing '[default]', and never creates the ipython_kernel_config.py file the user needed. | BY11: AssertionError | BZ11: AssertionError: '' != '[default]\n' + [default] | AssertionError: False is not true : Missing ipython_kernel_config.py (even when the profile directory already exists) | CA11: The LLM creates an empty Qiskit settings file instead of one containing '[default]', and never creates the ipython_kernel_config.py file the user needed. | CB11: AssertionError | CC11: AssertionError: '' != '[default]\n' + [default] | AssertionError: False is not true : Missing ipython_kernel_config.py (even when the profile directory already exists) | CD11: The LLM creates an empty Qiskit settings file instead of one containing '[default]', and never creates the ipython_kernel_config.py file the user needed. | CE11: AssertionError | CF11: AssertionError: '' != '[default]\n' + [default] | AssertionError: False is not true : Missing ipython_kernel_config.py (even when the profile directory already exists) | CG11: The LLM creates an empty Qiskit settings file instead of one containing '[default]', and never creates the ipython_kernel_config.py file the user needed. | CH11: AssertionError | CI11: AssertionError: '' != '[default]\n' + [default] | AssertionError: False is not true : Missing ipython_kernel_config.py (even when the profile directory already exists) | CJ11: The LLM creates an empty Qiskit settings file instead of one containing '[default]', and never creates the ipython_kernel_config.py file the user needed. | CK11: AssertionError | CL11: AssertionError: '' != '[default]\n' + [default] | AssertionError: False is not true : Missing ipython_kernel_config.py (even when the profile directory already exists) | CM11: The LLM creates an empty Qiskit settings file instead of one containing '[default]', and never creates the ipython_kernel_config.py file the user needed. | CN11: AssertionError | CO11: AssertionError: '' != '[default]\n' + [default] | AssertionError: False is not true : Missing ipython_kernel_config.py (even when the profile directory already exists) | CP11: The LLM creates an empty Qiskit settings file instead of one containing '[default]', and never creates the ipython_kernel_config.py file the user needed. | CQ11: AssertionError | CR11: AssertionError: '' != '[default]\n' + [default] | AssertionError: False is not true : Missing ipython_kernel_config.py (even when the profile directory already exists) | CS11: The LLM creates an empty Qiskit settings file instead of one containing '[default]', and never creates the ipython_kernel_config.py file the user needed. | CT11: AssertionError | CU11: AssertionError: '' != '[default]\n' + [default] | AssertionError: False is not true : Missing ipython_kernel_config.py (even when the profile directory already exists) | CV11: The LLM creates an empty Qiskit settings file instead of one containing '[default]', and never creates the ipython_kernel_config.py file the user needed. | CW11: AssertionError | CX11: AssertionError: '' != '[default]\n' + [default] | AssertionError: False is not true : Missing ipython_kernel_config.py (even when the profile directory already exists) | CY11: The LLM creates an empty Qiskit settings file instead of one containing '[default]', and never creates the ipython_kernel_config.py file the user needed. | CZ11: AssertionError | DA11: AssertionError: '' != '[default]\n' + [default] | AssertionError: False is not true : Missing ipython_kernel_config.py (even when the profile directory already exists) | DB11: The LLM creates an empty Qiskit settings file instead of one containing '[default]', and never creates the ipython_kernel_config.py file the user needed. | DC11: AssertionError | DD11: AssertionError: '' != '[default]\n' + [default] | AssertionError: False is not true : Missing ipython_kernel_config.py (even when the profile directory already exists) | DE11: The LLM creates an empty Qiskit settings file instead of one containing '[default]', and never creates the ipython_kernel_config.py file the user needed.
A12: issue_155 | B12: Passed on test | C12: Passed on test | D12: Passed on test | E12: Passed on test | F12: Passed on test | G12: Passed on test | H12: Passed on test | I12: Passed on test | J12: Passed on test | K12: Passed on test | L12: Passed on test | M12: Passed on test | N12: NOT_TESTED | O12: NOT_TESTED | P12: NOT_TESTED | Q12: NOT_TESTED | R12: NOT_TESTED | S12: NOT_TESTED | T12: NOT_TESTED | U12: NOT_TESTED | V12: NOT_TESTED | W12: NOT_TESTED | X12: NOT_TESTED | Y12: NOT_TESTED | Z12: NOT_TESTED | AA12: NOT_TESTED | AB12: NOT_TESTED
A13: issue_157 | B13: Runtime error | C13: Runtime error | D13: Runtime error | E13: Runtime error | F13: Passed on test | G13: Passed on test | H13: Passed on test | I13: Passed on test | J13: Passed on test | K13: Passed on test | L13: Passed on test | M13: Passed on test | N13: NOT_TESTED | O13: NOT_TESTED | P13: NOT_TESTED | Q13: NOT_TESTED | R13: NOT_TESTED | S13: NOT_TESTED | T13: NOT_TESTED | U13: NOT_TESTED | V13: NOT_TESTED | W13: NOT_TESTED | X13: NOT_TESTED | Y13: NOT_TESTED | Z13: NOT_TESTED | AA13: NOT_TESTED | AB13: NOT_TESTED | AC13: AttributeError | AD13: AttributeError: 'QuantumCircuit' object has no attribute 'prepare_state' | AE13: The LLM replaced initialize() with QuantumCircuit.prepare_state(), which does not exist yet in Qiskit 0.25 (Terra 0.17), so the script crashes with AttributeError before the gate is built. | AF13: AttributeError | AG13: AttributeError: 'QuantumCircuit' object has no attribute 'prepare_state' | AH13: The LLM replaced initialize() with QuantumCircuit.prepare_state(), which does not exist yet in Qiskit 0.25 (Terra 0.17), so the script crashes with AttributeError before the gate is built. | AI13: AttributeError | AJ13: AttributeError: 'QuantumCircuit' object has no attribute 'prepare_state' | AK13: The LLM replaced initialize() with QuantumCircuit.prepare_state(), which does not exist yet in Qiskit 0.25 (Terra 0.17), so the script crashes with AttributeError before the gate is built. | AL13: AttributeError | AM13: AttributeError: 'QuantumCircuit' object has no attribute 'prepare_state' | AN13: The LLM replaced initialize() with QuantumCircuit.prepare_state(), which does not exist yet in Qiskit 0.25 (Terra 0.17), so the script crashes with AttributeError before the gate is built.
A14: issue_174 | B14: Runtime error | C14: Runtime error | D14: Runtime error | E14: Runtime error | F14: Runtime error | G14: Runtime error | H14: Runtime error | I14: Runtime error | J14: Runtime error | K14: Runtime error | L14: Runtime error | M14: Runtime error | N14: NOT_TESTED | O14: NOT_TESTED | P14: NOT_TESTED | Q14: NOT_TESTED | R14: NOT_TESTED | S14: NOT_TESTED | T14: NOT_TESTED | U14: NOT_TESTED | V14: NOT_TESTED | W14: NOT_TESTED | X14: NOT_TESTED | Y14: NOT_TESTED | Z14: NOT_TESTED | AA14: NOT_TESTED | AB14: NOT_TESTED | AC14: QasmError | AD14: qiskit.qasm.exceptions.QasmError: 'Unable to match any token rule, got -->#<-- Check your OPENQASM source and any include statements.' | AE14: The LLM's QASM change (if (c==1) instead of if (c[0]==1)) is the same as the reference, but it put its '# FIX:' comment inside the OpenQASM string, where '#' is not valid syntax, so the QASM parser rejects the program. With that one line removed the fix passes. | AF14: QasmError | AG14: qiskit.qasm.exceptions.QasmError: 'Unable to match any token rule, got -->#<-- Check your OPENQASM source and any include statements.' | AH14: The LLM's QASM change (if (c==1) instead of if (c[0]==1)) is the same as the reference, but it put its '# FIX:' comment inside the OpenQASM string, where '#' is not valid syntax, so the QASM parser rejects the program. With that one line removed the fix passes. | AI14: QasmError | AJ14: qiskit.qasm.exceptions.QasmError: 'Unable to match any token rule, got -->#<-- Check your OPENQASM source and any include statements.' | AK14: The LLM's QASM change (if (c==1) instead of if (c[0]==1)) is the same as the reference, but it put its '# FIX:' comment inside the OpenQASM string, where '#' is not valid syntax, so the QASM parser rejects the program. With that one line removed the fix passes. | AL14: QasmError | AM14: qiskit.qasm.exceptions.QasmError: 'Unable to match any token rule, got -->#<-- Check your OPENQASM source and any include statements.' | AN14: The LLM's QASM change (if (c==1) instead of if (c[0]==1)) is the same as the reference, but it put its '# FIX:' comment inside the OpenQASM string, where '#' is not valid syntax, so the QASM parser rejects the program. With that one line removed the fix passes. | AO14: QASM2ParseError | AP14: qiskit.qasm2.exceptions.QASM2ParseError: "<input>:10,0: encountered '#', which doesn't match any valid tokens" | AQ14: The LLM's QASM change (if (c==1) instead of if (c[0]==1)) is the same as the reference, but it put its '# FIX:' comment inside the OpenQASM string, where '#' is not valid syntax, so the QASM parser rejects the program. With that one line removed the fix passes. | AR14: QASM2ParseError | AS14: qiskit.qasm2.exceptions.QASM2ParseError: "<input>:10,0: encountered '#', which doesn't match any valid tokens" | AT14: The LLM's QASM change (if (c==1) instead of if (c[0]==1)) is the same as the reference, but it put its '# FIX:' comment inside the OpenQASM string, where '#' is not valid syntax, so the QASM parser rejects the program. With that one line removed the fix passes. | AU14: QASM2ParseError | AV14: qiskit.qasm2.exceptions.QASM2ParseError: "<input>:10,0: encountered '#', which doesn't match any valid tokens" | AW14: The LLM's QASM change (if (c==1) instead of if (c[0]==1)) is the same as the reference, but it put its '# FIX:' comment inside the OpenQASM string, where '#' is not valid syntax, so the QASM parser rejects the program. With that one line removed the fix passes. | AX14: QASM2ParseError | AY14: qiskit.qasm2.exceptions.QASM2ParseError: "<input>:10,0: encountered '#', which doesn't match any valid tokens" | AZ14: The LLM's QASM change (if (c==1) instead of if (c[0]==1)) is the same as the reference, but it put its '# FIX:' comment inside the OpenQASM string, where '#' is not valid syntax, so the QASM parser rejects the program. With that one line removed the fix passes. | BA14: QASM2ParseError | BB14: qiskit.qasm2.exceptions.QASM2ParseError: "<input>:10,0: encountered '#', which doesn't match any valid tokens" | BC14: The LLM's QASM change (if (c==1) instead of if (c[0]==1)) is the same as the reference, but it put its '# FIX:' comment inside the OpenQASM string, where '#' is not valid syntax, so the QASM parser rejects the program. With that one line removed the fix passes. | BD14: QASM2ParseError | BE14: qiskit.qasm2.exceptions.QASM2ParseError: "<input>:10,0: encountered '#', which doesn't match any valid tokens" | BF14: The LLM's QASM change (if (c==1) instead of if (c[0]==1)) is the same as the reference, but it put its '# FIX:' comment inside the OpenQASM string, where '#' is not valid syntax, so the QASM parser rejects the program. With that one line removed the fix passes. | BG14: QASM2ParseError | BH14: qiskit.qasm2.exceptions.QASM2ParseError: "<input>:10,0: encountered '#', which doesn't match any valid tokens" | BI14: The LLM's QASM change (if (c==1) instead of if (c[0]==1)) is the same as the reference, but it put its '# FIX:' comment inside the OpenQASM string, where '#' is not valid syntax, so the QASM parser rejects the program. With that one line removed the fix passes. | BJ14: QASM2ParseError | BK14: qiskit.qasm2.exceptions.QASM2ParseError: "<input>:10,0: encountered '#', which doesn't match any valid tokens" | BL14: The LLM's QASM change (if (c==1) instead of if (c[0]==1)) is the same as the reference, but it put its '# FIX:' comment inside the OpenQASM string, where '#' is not valid syntax, so the QASM parser rejects the program. With that one line removed the fix passes.
A15: issue_189 | B15: NOT_TESTED | C15: NOT_TESTED | D15: NOT_TESTED | E15: NOT_TESTED | F15: Passed on test | G15: Passed on test | H15: Passed on test | I15: Passed on test | J15: Passed on test | K15: Passed on test | L15: Passed on test | M15: Passed on test | N15: Passed on test | O15: Passed on test | P15: Passed on test | Q15: Passed on test | R15: Passed on test | S15: Passed on test | T15: Passed on test | U15: Passed on test | V15: Passed on test | W15: Passed on test | X15: Passed on test | Y15: Passed on test | Z15: Passed on test | AA15: Passed on test | AB15: Passed on test | AO15: AssertionError | AP15: AssertionError: Lists differ: [2, 3, 4, 5, 6, 7, 8] != [0, 3, 4, 5, 6, 7, 8] | AQ15: The LLM fixed the qubit count (one control plus the six target qubits) but kept the original code's control order, so control qubit k gets the power 2^k (the usual QPE layout, and every gate matrix is correct). The test only accepts the Stack Overflow answer's order (control i gets 2^(2-i)), so it reports [2, 3, ..., 8] instead of [0, 3, ..., 8]. | AR15: AssertionError | AS15: AssertionError: Lists differ: [2, 3, 4, 5, 6, 7, 8] != [0, 3, 4, 5, 6, 7, 8] | AT15: The LLM fixed the qubit count (one control plus the six target qubits) but kept the original code's control order, so control qubit k gets the power 2^k (the usual QPE layout, and every gate matrix is correct). The test only accepts the Stack Overflow answer's order (control i gets 2^(2-i)), so it reports [2, 3, ..., 8] instead of [0, 3, ..., 8]. | AU15: AssertionError | AV15: AssertionError: Lists differ: [2, 3, 4, 5, 6, 7, 8] != [0, 3, 4, 5, 6, 7, 8] | AW15: The LLM fixed the qubit count (one control plus the six target qubits) but kept the original code's control order, so control qubit k gets the power 2^k (the usual QPE layout, and every gate matrix is correct). The test only accepts the Stack Overflow answer's order (control i gets 2^(2-i)), so it reports [2, 3, ..., 8] instead of [0, 3, ..., 8]. | AX15: AssertionError | AY15: AssertionError: Lists differ: [2, 3, 4, 5, 6, 7, 8] != [0, 3, 4, 5, 6, 7, 8] | AZ15: The LLM fixed the qubit count (one control plus the six target qubits) but kept the original code's control order, so control qubit k gets the power 2^k (the usual QPE layout, and every gate matrix is correct). The test only accepts the Stack Overflow answer's order (control i gets 2^(2-i)), so it reports [2, 3, ..., 8] instead of [0, 3, ..., 8]. | BA15: AssertionError | BB15: AssertionError: Lists differ: [2, 3, 4, 5, 6, 7, 8] != [0, 3, 4, 5, 6, 7, 8] | BC15: The LLM fixed the qubit count (one control plus the six target qubits) but kept the original code's control order, so control qubit k gets the power 2^k (the usual QPE layout, and every gate matrix is correct). The test only accepts the Stack Overflow answer's order (control i gets 2^(2-i)), so it reports [2, 3, ..., 8] instead of [0, 3, ..., 8]. | BD15: AssertionError | BE15: AssertionError: Lists differ: [2, 3, 4, 5, 6, 7, 8] != [0, 3, 4, 5, 6, 7, 8] | BF15: The LLM fixed the qubit count (one control plus the six target qubits) but kept the original code's control order, so control qubit k gets the power 2^k (the usual QPE layout, and every gate matrix is correct). The test only accepts the Stack Overflow answer's order (control i gets 2^(2-i)), so it reports [2, 3, ..., 8] instead of [0, 3, ..., 8]. | BG15: AssertionError | BH15: AssertionError: Lists differ: [2, 3, 4, 5, 6, 7, 8] != [0, 3, 4, 5, 6, 7, 8] | BI15: The LLM fixed the qubit count (one control plus the six target qubits) but kept the original code's control order, so control qubit k gets the power 2^k (the usual QPE layout, and every gate matrix is correct). The test only accepts the Stack Overflow answer's order (control i gets 2^(2-i)), so it reports [2, 3, ..., 8] instead of [0, 3, ..., 8]. | BJ15: AssertionError | BK15: AssertionError: Lists differ: [2, 3, 4, 5, 6, 7, 8] != [0, 3, 4, 5, 6, 7, 8] | BL15: The LLM fixed the qubit count (one control plus the six target qubits) but kept the original code's control order, so control qubit k gets the power 2^k (the usual QPE layout, and every gate matrix is correct). The test only accepts the Stack Overflow answer's order (control i gets 2^(2-i)), so it reports [2, 3, ..., 8] instead of [0, 3, ..., 8]. | BM15: AssertionError | BN15: AssertionError: Lists differ: [2, 3, 4, 5, 6, 7, 8] != [0, 3, 4, 5, 6, 7, 8] | BO15: The LLM fixed the qubit count (one control plus the six target qubits) but kept the original code's control order, so control qubit k gets the power 2^k (the usual QPE layout, and every gate matrix is correct). The test only accepts the Stack Overflow answer's order (control i gets 2^(2-i)), so it reports [2, 3, ..., 8] instead of [0, 3, ..., 8]. | BP15: AssertionError | BQ15: AssertionError: Lists differ: [2, 3, 4, 5, 6, 7, 8] != [0, 3, 4, 5, 6, 7, 8] | BR15: The LLM fixed the qubit count (one control plus the six target qubits) but kept the original code's control order, so control qubit k gets the power 2^k (the usual QPE layout, and every gate matrix is correct). The test only accepts the Stack Overflow answer's order (control i gets 2^(2-i)), so it reports [2, 3, ..., 8] instead of [0, 3, ..., 8]. | BS15: AssertionError | BT15: AssertionError: Lists differ: [2, 3, 4, 5, 6, 7, 8] != [0, 3, 4, 5, 6, 7, 8] | BU15: The LLM fixed the qubit count (one control plus the six target qubits) but kept the original code's control order, so control qubit k gets the power 2^k (the usual QPE layout, and every gate matrix is correct). The test only accepts the Stack Overflow answer's order (control i gets 2^(2-i)), so it reports [2, 3, ..., 8] instead of [0, 3, ..., 8]. | BV15: AssertionError | BW15: AssertionError: Lists differ: [2, 3, 4, 5, 6, 7, 8] != [0, 3, 4, 5, 6, 7, 8] | BX15: The LLM fixed the qubit count (one control plus the six target qubits) but kept the original code's control order, so control qubit k gets the power 2^k (the usual QPE layout, and every gate matrix is correct). The test only accepts the Stack Overflow answer's order (control i gets 2^(2-i)), so it reports [2, 3, ..., 8] instead of [0, 3, ..., 8]. | BY15: AssertionError | BZ15: AssertionError: Lists differ: [2, 3, 4, 5, 6, 7, 8] != [0, 3, 4, 5, 6, 7, 8] | CA15: The LLM fixed the qubit count (one control plus the six target qubits) but kept the original code's control order, so control qubit k gets the power 2^k (the usual QPE layout, and every gate matrix is correct). The test only accepts the Stack Overflow answer's order (control i gets 2^(2-i)), so it reports [2, 3, ..., 8] instead of [0, 3, ..., 8]. | CB15: AssertionError | CC15: AssertionError: Lists differ: [2, 3, 4, 5, 6, 7, 8] != [0, 3, 4, 5, 6, 7, 8] | CD15: The LLM fixed the qubit count (one control plus the six target qubits) but kept the original code's control order, so control qubit k gets the power 2^k (the usual QPE layout, and every gate matrix is correct). The test only accepts the Stack Overflow answer's order (control i gets 2^(2-i)), so it reports [2, 3, ..., 8] instead of [0, 3, ..., 8]. | CE15: AssertionError | CF15: AssertionError: Lists differ: [2, 3, 4, 5, 6, 7, 8] != [0, 3, 4, 5, 6, 7, 8] | CG15: The LLM fixed the qubit count (one control plus the six target qubits) but kept the original code's control order, so control qubit k gets the power 2^k (the usual QPE layout, and every gate matrix is correct). The test only accepts the Stack Overflow answer's order (control i gets 2^(2-i)), so it reports [2, 3, ..., 8] instead of [0, 3, ..., 8]. | CH15: AssertionError | CI15: AssertionError: Lists differ: [2, 3, 4, 5, 6, 7, 8] != [0, 3, 4, 5, 6, 7, 8] | CJ15: The LLM fixed the qubit count (one control plus the six target qubits) but kept the original code's control order, so control qubit k gets the power 2^k (the usual QPE layout, and every gate matrix is correct). The test only accepts the Stack Overflow answer's order (control i gets 2^(2-i)), so it reports [2, 3, ..., 8] instead of [0, 3, ..., 8]. | CK15: AssertionError | CL15: AssertionError: Lists differ: [2, 3, 4, 5, 6, 7, 8] != [0, 3, 4, 5, 6, 7, 8] | CM15: The LLM fixed the qubit count (one control plus the six target qubits) but kept the original code's control order, so control qubit k gets the power 2^k (the usual QPE layout, and every gate matrix is correct). The test only accepts the Stack Overflow answer's order (control i gets 2^(2-i)), so it reports [2, 3, ..., 8] instead of [0, 3, ..., 8]. | CN15: AssertionError | CO15: AssertionError: Lists differ: [2, 3, 4, 5, 6, 7, 8] != [0, 3, 4, 5, 6, 7, 8] | CP15: The LLM fixed the qubit count (one control plus the six target qubits) but kept the original code's control order, so control qubit k gets the power 2^k (the usual QPE layout, and every gate matrix is correct). The test only accepts the Stack Overflow answer's order (control i gets 2^(2-i)), so it reports [2, 3, ..., 8] instead of [0, 3, ..., 8]. | CQ15: AssertionError | CR15: AssertionError: Lists differ: [2, 3, 4, 5, 6, 7, 8] != [0, 3, 4, 5, 6, 7, 8] | CS15: The LLM fixed the qubit count (one control plus the six target qubits) but kept the original code's control order, so control qubit k gets the power 2^k (the usual QPE layout, and every gate matrix is correct). The test only accepts the Stack Overflow answer's order (control i gets 2^(2-i)), so it reports [2, 3, ..., 8] instead of [0, 3, ..., 8]. | CT15: AssertionError | CU15: AssertionError: Lists differ: [2, 3, 4, 5, 6, 7, 8] != [0, 3, 4, 5, 6, 7, 8] | CV15: The LLM fixed the qubit count (one control plus the six target qubits) but kept the original code's control order, so control qubit k gets the power 2^k (the usual QPE layout, and every gate matrix is correct). The test only accepts the Stack Overflow answer's order (control i gets 2^(2-i)), so it reports [2, 3, ..., 8] instead of [0, 3, ..., 8]. | CW15: AssertionError | CX15: AssertionError: Lists differ: [2, 3, 4, 5, 6, 7, 8] != [0, 3, 4, 5, 6, 7, 8] | CY15: The LLM fixed the qubit count (one control plus the six target qubits) but kept the original code's control order, so control qubit k gets the power 2^k (the usual QPE layout, and every gate matrix is correct). The test only accepts the Stack Overflow answer's order (control i gets 2^(2-i)), so it reports [2, 3, ..., 8] instead of [0, 3, ..., 8]. | CZ15: AssertionError | DA15: AssertionError: Lists differ: [2, 3, 4, 5, 6, 7, 8] != [0, 3, 4, 5, 6, 7, 8] | DB15: The LLM fixed the qubit count (one control plus the six target qubits) but kept the original code's control order, so control qubit k gets the power 2^k (the usual QPE layout, and every gate matrix is correct). The test only accepts the Stack Overflow answer's order (control i gets 2^(2-i)), so it reports [2, 3, ..., 8] instead of [0, 3, ..., 8]. | DC15: AssertionError | DD15: AssertionError: Lists differ: [2, 3, 4, 5, 6, 7, 8] != [0, 3, 4, 5, 6, 7, 8] | DE15: The LLM fixed the qubit count (one control plus the six target qubits) but kept the original code's control order, so control qubit k gets the power 2^k (the usual QPE layout, and every gate matrix is correct). The test only accepts the Stack Overflow answer's order (control i gets 2^(2-i)), so it reports [2, 3, ..., 8] instead of [0, 3, ..., 8].
A16: issue_225 | B16: NOT_TESTED | C16: NOT_TESTED | D16: NOT_TESTED | E16: NOT_TESTED | F16: Passed on test | G16: Passed on test | H16: Passed on test | I16: Passed on test | J16: Passed on test | K16: Passed on test | L16: Passed on test | M16: Passed on test | N16: NOT_TESTED | O16: NOT_TESTED | P16: NOT_TESTED | Q16: NOT_TESTED | R16: NOT_TESTED | S16: NOT_TESTED | T16: NOT_TESTED | U16: NOT_TESTED | V16: NOT_TESTED | W16: NOT_TESTED | X16: NOT_TESTED | Y16: NOT_TESTED | Z16: NOT_TESTED | AA16: NOT_TESTED | AB16: NOT_TESTED
